<?xml version="1.0" ?>
<!-- =================================================================================== -->
<!-- |    This document was autogenerated by xacro from ari.urdf.xacro                 | -->
<!-- |    EDITING THIS FILE BY HAND IS NOT RECOMMENDED                                 | -->
<!-- =================================================================================== -->
<robot name="ari" xmlns:controller="http://playerstage.sourceforge.net/gazebo/xmlschema/#controller" xmlns:interface="http://playerstage.sourceforge.net/gazebo/xmlschema/#interface" xmlns:sensor="http://playerstage.sourceforge.net/gazebo/xmlschema/#sensor" xmlns:xacro="http://ros.org/wiki/xacro">
  <!--
 Ari robot configuration for RoboEarth project
-->
  <!-- Included URDF Files -->
  <!-- Body of TurtleBot, with plates, standoffs and Create (including sim sensors) -->
  <link name="base_link">
    <inertial>
      <mass value="3.5"/>
      <origin xyz="-0.05 0 0"/>
      <inertia ixx="1" ixy="0" ixz="0" iyy="1" iyz="0" izz="1"/>
    </inertial>
    <visual name="base_visual">
      <origin rpy="0 0 0" xyz="-0.045 0 0.148"/>
      <geometry name="pioneer_geom">
        <mesh filename="package://ari_robot/meshes/chassis.stl"/>
      </geometry>
      <material name="ChassisRed">
        <color rgba="0.851 0.0 0.0 1.0"/>
      </material>
    </visual>
    <collision>
      <origin rpy="0 0 0" xyz="-0.045 0 0.145"/>
      <geometry>
        <box size="0.35 0.25 0.14"/>
      </geometry>
    </collision>
  </link>
  <gazebo reference="base_link">
    <material value="Gazebo/Pioneer2Body"/>
  </gazebo>
  <link name="top_plate">
    <inertial>
      <mass value="0.01"/>
      <origin xyz="0 0 0"/>
      <inertia ixx="1" ixy="0" ixz="0" iyy="1" iyz="0" izz="1"/>
    </inertial>
    <visual name="base_visual">
      <origin rpy="0 0 0" xyz="0 0 0"/>
      <geometry name="top_geom">
        <mesh filename="package://ari_robot/meshes/top.stl"/>
      </geometry>
      <material name="TopBlack">
        <color rgba="0.038 0.038 0.038 1.0"/>
      </material>
    </visual>
    <collision>
      <origin rpy="0 0 0" xyz="0.0 0 0"/>
      <geometry name="pioneer_geom">
        <box size="0.45 0.38 0.01"/>
      </geometry>
    </collision>
  </link>
  <gazebo reference="top_plate">
    <material value="Gazebo/FlatBlack"/>
  </gazebo>
  <joint name="base_top_joint" type="fixed">
    <origin rpy="0 0 0" xyz="-0.045 0 0.234"/>
    <parent link="base_link"/>
    <child link="top_plate"/>
  </joint>
  <link name="front_sonar">
    <inertial>
      <mass value="0.0001"/>
      <origin xyz="0 0 0"/>
      <inertia ixx="1" ixy="0" ixz="0" iyy="1" iyz="0" izz="1"/>
    </inertial>
    <visual name="base_visual">
      <origin rpy="0 0 0" xyz="0 0 0"/>
      <geometry name="pioneer_geom">
        <mesh filename="package://ari_robot/meshes/front_sonar.stl"/>
      </geometry>
      <material name="SonarYellow">
        <color rgba="0.715 0.583 0.210 1.0"/>
      </material>
    </visual>
    <collision>
      <origin rpy="0 0 0" xyz="0 0 0"/>
      <geometry>
        <box size="0 0 0"/>
      </geometry>
    </collision>
  </link>
  <gazebo reference="front_sonar">
    <material value="Gazebo/Yellow"/>
  </gazebo>
  <joint name="base_front_joint" type="fixed">
    <origin rpy="0 0 0" xyz="-0.198 0 0.208"/>
    <parent link="base_link"/>
    <child link="front_sonar"/>
  </joint>
  <link name="back_sonar">
    <inertial>
      <mass value="0.0001"/>
      <origin xyz="0 0 0"/>
      <inertia ixx="1" ixy="0" ixz="0" iyy="1" iyz="0" izz="1"/>
    </inertial>
    <visual name="back_sonar_vis">
      <origin rpy="0 0 0" xyz="0 0 0"/>
      <geometry name="pioneer_geom">
        <mesh filename="package://ari_robot/meshes/back_sonar.stl"/>
      </geometry>
      <material name="SonarYellow">
        <color rgba="0.715 0.583 0.210 1.0"/>
      </material>
    </visual>
    <collision>
      <origin rpy="0 0 0" xyz="0 0 0"/>
      <geometry>
        <box size="0 0 0"/>
      </geometry>
    </collision>
  </link>
  <gazebo reference="back_sonar">
    <material value="Gazebo/Yellow"/>
  </gazebo>
  <joint name="base_back_joint" type="fixed">
    <origin rpy="0 0 0" xyz="0.109 0 0.209"/>
    <parent link="base_link"/>
    <child link="back_sonar"/>
  </joint>
  <link name="swivel">
    <inertial>
      <mass value="0.1"/>
      <origin xyz="0 0 0"/>
      <inertia ixx="0.01" ixy="0" ixz="0" iyy="0.01" iyz="0" izz="0.01"/>
    </inertial>
    <visual name="base_visual">
      <origin rpy="0 0 0" xyz="0 0 0"/>
      <geometry name="pioneer_geom">
        <mesh filename="package://ari_robot/meshes/swivel.stl"/>
      </geometry>
      <material name="swivel">
        <color rgba="0.5 0.5 0.5 1"/>
      </material>
    </visual>
    <collision>
      <origin rpy="0 0 0" xyz="0 0 0"/>
      <geometry>
        <box size="0 0 0"/>
      </geometry>
    </collision>
  </link>
  <gazebo reference="swivel">
    <material value="Gazebo/Grey"/>
  </gazebo>
  <joint name="base_swivel_joint" type="continuous">
    <origin rpy="0 0 0" xyz="-0.185 0 0.055"/>
    <axis xyz="0 0 1"/>
    <anchor xyz="0 0 0"/>
    <limit effort="100" k_velocity="0" velocity="100"/>
    <joint_properties damping="0.0" friction="0.0"/>
    <parent link="base_link"/>
    <child link="swivel"/>
  </joint>
  <link name="center_hubcap">
    <inertial>
      <mass value="0.01"/>
      <origin xyz="0 0 0"/>
      <inertia ixx="0.012411765597" ixy="-0.000711733678" ixz="0.00050272983" iyy="0.015218160428" iyz="-0.000004273467" izz="0.011763977943"/>
    </inertial>
    <visual name="base_visual">
      <origin rpy="0 0 0" xyz="0 0 0"/>
      <geometry name="pioneer_geom">
        <mesh filename="package://ari_robot/meshes/center_hubcap.stl"/>
      </geometry>
      <material name="swivel">
        <color rgba="0.5 0.5 0.5 1"/>
      </material>
    </visual>
    <collision>
      <origin rpy="0 0 0" xyz="0 0 0"/>
      <geometry>
        <box size="0 0 0"/>
      </geometry>
    </collision>
  </link>
  <gazebo reference="center_hubcap">
    <material value="Gazebo/Grey"/>
  </gazebo>
  <joint name="swivel_hubcap_joint" type="continuous">
    <origin rpy="0 0 0" xyz="-0.026 0 -0.016"/>
    <axis xyz="0 1 0"/>
    <anchor xyz="0 0 0"/>
    <limit effort="100" k_velocity="0" velocity="100"/>
    <joint_properties damping="0.0" friction="0.0"/>
    <parent link="swivel"/>
    <child link="center_wheel"/>
  </joint>
  <link name="center_wheel">
    <inertial>
      <mass value="0.1"/>
      <origin xyz="0 0 0"/>
      <inertia ixx="0.012411765597" ixy="-0.000711733678" ixz="0.00050272983" iyy="0.015218160428" iyz="-0.000004273467" izz="0.011763977943"/>
    </inertial>
    <visual name="base_visual">
      <origin rpy="0 0 0" xyz="0 0 0"/>
      <geometry name="pioneer_geom">
        <mesh filename="package://ari_robot/meshes/center_wheel.stl"/>
      </geometry>
      <material name="WheelBlack">
        <color rgba="0.117 0.117 0.117 1"/>
      </material>
    </visual>
    <collision>
      <origin rpy="-1.57079635 0 0" xyz="0 0 0"/>
      <geometry>
        <cylinder length="0.01" radius="0.0375"/>
      </geometry>
    </collision>
  </link>
  <gazebo reference="center_wheel">
    <material value="Gazebo/FlatBlack"/>
    <elem key="mu1" value="10.0"/>
    <elem key="mu2" value="10.0"/>
    <elem key="kp" value="1000000.0"/>
    <elem key="kd" value="1.0"/>
  </gazebo>
  <joint name="center_wheel_joint" type="fixed">
    <origin rpy="0 0 0" xyz="-0.0035 0 -0.001"/>
    <parent link="center_wheel"/>
    <child link="center_hubcap"/>
  </joint>
  <link name="p3dx_left_wheel">
    <inertial>
      <mass value="0.5"/>
      <origin xyz="0 0 0"/>
      <inertia ixx="0.012411765597" ixy="0" ixz="0" iyy="0.015218160428" iyz="0" izz="0.011763977943"/>
    </inertial>
    <visual name="base_visual">
      <origin rpy="0 0 0" xyz="0 0 0"/>
      <geometry name="pioneer_geom">
        <mesh filename="package://ari_robot/meshes/left_wheel.stl"/>
      </geometry>
      <material name="WheelBlack">
        <color rgba="0.117 0.117 0.117 1"/>
      </material>
    </visual>
    <collision>
      <origin rpy="-1.57079635 0 0" xyz="0 0 0"/>
      <geometry>
        <cylinder length="0.01" radius="0.09"/>
      </geometry>
    </collision>
  </link>
  <joint name="base_left_hubcap_joint" type="fixed">
    <origin rpy="0 0 0" xyz="0 0 0"/>
    <parent link="p3dx_left_wheel"/>
    <child link="p3dx_left_hubcap"/>
  </joint>
  <link name="p3dx_left_hubcap">
    <inertial>
      <mass value="0.01"/>
      <origin xyz="0 0 0"/>
      <inertia ixx="0.012411765597" ixy="0" ixz="0" iyy="0.015218160428" iyz="0" izz="0.011763977943"/>
    </inertial>
    <visual name="base_visual">
      <origin rpy="0 0 0" xyz="0 0 0"/>
      <geometry name="pioneer_geom">
        <mesh filename="package://ari_robot/meshes/left_hubcap.stl"/>
      </geometry>
      <material name="HubcapYellow">
        <color rgba="1.0 0.811 0.151 1.0"/>
      </material>
    </visual>
    <collision>
      <origin rpy="0 0 0" xyz="0 0 0"/>
      <geometry>
        <box size="0 0 0"/>
      </geometry>
    </collision>
  </link>
  <transmission name="base_link_left_wheel_trans" type="pr2_mechanism_model/SimpleTransmission">
    <actuator name="base_left_wheel_motor"/>
    <joint name="base_left_wheel_joint"/>
    <mechanicalReduction>75.0676691729</mechanicalReduction>
  </transmission>
  <joint name="base_left_wheel_joint" type="continuous">
    <axis xyz="0 1 0"/>
    <anchor xyz="0 0 0"/>
    <limit effort="100" velocity="100"/>
    <joint_properties damping="0.0" friction="0.0"/>
    <origin rpy="0 0 0" xyz="0 0.158 0.091"/>
    <parent link="base_link"/>
    <child link="p3dx_left_wheel"/>
  </joint>
  <gazebo reference="p3dx_left_hubcap">
    <material value="Gazebo/Yellow"/>
  </gazebo>
  <gazebo reference="p3dx_left_wheel">
    <material value="Gazebo/FlatBlack"/>
    <elem key="mu1" value="0.5"/>
    <elem key="mu2" value="50.0"/>
    <elem key="kp" value="100000000.0"/>
    <elem key="kd" value="1.0"/>
  </gazebo>
  <link name="p3dx_right_wheel">
    <inertial>
      <mass value="0.5"/>
      <origin xyz="0 0 0"/>
      <inertia ixx="0.012411765597" ixy="0" ixz="0" iyy="0.015218160428" iyz="0" izz="0.011763977943"/>
    </inertial>
    <visual name="base_visual">
      <origin rpy="0 0 0" xyz="0 0 0"/>
      <geometry name="pioneer_geom">
        <mesh filename="package://ari_robot/meshes/right_wheel.stl"/>
      </geometry>
      <material name="WheelBlack">
        <color rgba="0.117 0.117 0.117 1"/>
      </material>
    </visual>
    <collision>
      <origin rpy="-1.57079635 0 0" xyz="0 0 0"/>
      <geometry>
        <cylinder length="0.01" radius="0.09"/>
      </geometry>
    </collision>
  </link>
  <joint name="base_right_hubcap_joint" type="fixed">
    <origin rpy="0 0 0" xyz="0 0 0"/>
    <parent link="p3dx_right_wheel"/>
    <child link="p3dx_right_hubcap"/>
  </joint>
  <link name="p3dx_right_hubcap">
    <inertial>
      <mass value="0.01"/>
      <origin xyz="0 0 0"/>
      <inertia ixx="0.012411765597" ixy="0" ixz="0" iyy="0.015218160428" iyz="0" izz="0.011763977943"/>
    </inertial>
    <visual name="base_visual">
      <origin rpy="0 0 0" xyz="0 0 0"/>
      <geometry name="pioneer_geom">
        <mesh filename="package://ari_robot/meshes/right_hubcap.stl"/>
      </geometry>
      <material name="HubcapYellow">
        <color rgba="1.0 0.811 0.151 1.0"/>
      </material>
    </visual>
    <collision>
      <origin rpy="0 0 0" xyz="0 0 0"/>
      <geometry>
        <box size="0 0 0"/>
      </geometry>
    </collision>
  </link>
  <transmission name="base_link_right_wheel_trans" type="pr2_mechanism_model/SimpleTransmission">
    <actuator name="base_right_wheel_motor"/>
    <joint name="base_right_wheel_joint"/>
    <mechanicalReduction>-75.0676691729</mechanicalReduction>
  </transmission>
  <joint name="base_right_wheel_joint" type="continuous">
    <axis xyz="0 1 0"/>
    <anchor xyz="0 0 0"/>
    <limit effort="100" velocity="100"/>
    <joint_properties damping="0.0" friction="0.0"/>
    <origin rpy="0 0 0" xyz="0 -0.158 0.091"/>
    <parent link="base_link"/>
    <child link="p3dx_right_wheel"/>
  </joint>
  <gazebo reference="p3dx_right_hubcap">
    <material value="Gazebo/Yellow"/>
  </gazebo>
  <gazebo reference="p3dx_right_wheel">
    <material value="Gazebo/FlatBlack"/>
    <elem key="mu1" value="0.5"/>
    <elem key="mu2" value="50.0"/>
    <elem key="kp" value="100000000.0"/>
    <elem key="kd" value="1.0"/>
  </gazebo>
  <link name="base_laser">
    <inertial>
      <mass value="0.01"/>
      <origin xyz="0 0 0"/>
      <inertia ixx="1" ixy="0" ixz="0" iyy="1" iyz="0" izz="1"/>
    </inertial>
    <visual name="laser_visual">
      <origin rpy="0 0 0" xyz="0 0 0"/>
      <geometry name="laser_geom">
        <mesh filename="package://ari_robot/meshes/sick_lms200.stl"/>
        <cylinder length="0.2" radius="0.07"/>
      </geometry>
      <material name="TopBlue">
        <color rgba="0.0 0.0 1.0 1.0"/>
      </material>
    </visual>
    <collision>
      <origin rpy="0 0 0" xyz="0.0 0 0"/>
      <geometry name="laser_geom">
        <box size="0.15 0.15 0.2"/>
      </geometry>
    </collision>
  </link>
  <gazebo reference="base_laser">
    <material value="Gazebo/Blue"/>
  </gazebo>
  <joint name="base_laser_joint" type="fixed">
    <origin rpy="0 0 0" xyz="0.135 0.0 0.075"/>
    <parent link="top_plate"/>
    <child link="base_laser"/>
  </joint>
  <link name="computer_plate">
    <inertial>
      <mass value="0.01"/>
      <origin xyz="0 0 0"/>
      <inertia ixx="1" ixy="0" ixz="0" iyy="1" iyz="0" izz="1"/>
    </inertial>
    <visual name="computer_plate_visual">
      <origin rpy="0 0 0" xyz="0 0 0"/>
      <geometry name="test_geom">
        <mesh filename="package://ari_robot/meshes/computer_plate.stl"/>
      </geometry>
      <material name="testGray">
        <color rgba="0.5 0.5 0.5 1.0"/>
      </material>
    </visual>
    <collision>
      <origin rpy="0 0 0" xyz="0.0 0 0"/>
      <geometry name="computer_plate_geom">
        <box size="0.45 0.38 0.01"/>
      </geometry>
    </collision>
  </link>
  <gazebo reference="computer_plate">
    <material value="Gazebo/Gray"/>
  </gazebo>
  <joint name="computer_plate_joint" type="fixed">
    <origin rpy="0 0 0" xyz="-0.05 -0.007 0.257"/>
    <parent link="top_plate"/>
    <child link="computer_plate"/>
  </joint>
  <link name="left_stick">
    <inertial>
      <mass value="0.01"/>
      <origin xyz="0 0 0"/>
      <inertia ixx="1" ixy="0" ixz="0" iyy="1" iyz="0" izz="1"/>
    </inertial>
    <visual name="left_stick">
      <origin rpy="0 0 0" xyz="0 0 0"/>
      <geometry name="stick_geom">
        <box size="0.265 0.030 0.030"/>
      </geometry>
      <material name="StickBlack">
        <color rgba="0.038 0.038 0.038 1.0"/>
      </material>
    </visual>
    <collision>
      <origin rpy="0 0 0" xyz="0.0 0 0"/>
      <geometry name="stick_geom">
        <box size="0.265 0.030 0.030"/>
      </geometry>
    </collision>
  </link>
  <gazebo reference="left_stick">
    <material value="Gazebo/FlatBlack"/>
  </gazebo>
  <link name="left_up_1_stick">
    <inertial>
      <mass value="0.01"/>
      <origin xyz="0 0 0"/>
      <inertia ixx="1" ixy="0" ixz="0" iyy="1" iyz="0" izz="1"/>
    </inertial>
    <visual name="left_up_1_stick">
      <origin rpy="0 0 0" xyz="0 0 0"/>
      <geometry name="stick_2_geom">
        <box size="0.030 0.030  0.22"/>
      </geometry>
      <material name="StickBlack">
        <color rgba="0.038 0.038 0.038 1.0"/>
      </material>
    </visual>
    <collision>
      <origin rpy="0 0 0" xyz="0.0 0 0"/>
      <geometry name="stick_2_geom">
        <box size="0.030 0.030 0.22"/>
      </geometry>
    </collision>
  </link>
  <gazebo reference="left_up_1_stick">
    <material value="Gazebo/FlatBlack"/>
  </gazebo>
  <link name="left_up_2_stick">
    <inertial>
      <mass value="0.01"/>
      <origin xyz="0 0 0"/>
      <inertia ixx="1" ixy="0" ixz="0" iyy="1" iyz="0" izz="1"/>
    </inertial>
    <visual name="left_up_2_stick">
      <origin rpy="0 0 0" xyz="0 0 0"/>
      <geometry name="stick_2_geom">
        <box size="0.030 0.030  0.22"/>
      </geometry>
      <material name="StickBlack">
        <color rgba="0.038 0.038 0.038 1.0"/>
      </material>
    </visual>
    <collision>
      <origin rpy="0 0 0" xyz="0.0 0 0"/>
      <geometry name="stick_2_geom">
        <box size="0.030 0.030 0.22"/>
      </geometry>
    </collision>
  </link>
  <gazebo reference="left_up_2_stick">
    <material value="Gazebo/FlatBlack"/>
  </gazebo>
  <link name="left_up_3_stick">
    <inertial>
      <mass value="0.01"/>
      <origin xyz="0 0 0"/>
      <inertia ixx="1" ixy="0" ixz="0" iyy="1" iyz="0" izz="1"/>
    </inertial>
    <visual name="left_up_3_stick">
      <origin rpy="0 0 0" xyz="0 0 0"/>
      <geometry name="stick_3_geom">
        <box size="0.030 0.030  0.84"/>
      </geometry>
      <material name="StickBlack">
        <color rgba="0.038 0.038 0.038 1.0"/>
      </material>
    </visual>
    <collision>
      <origin rpy="0 0 0" xyz="0.0 0 0"/>
      <geometry name="stick_3_geom">
        <box size="0.030 0.030 0.84"/>
      </geometry>
    </collision>
  </link>
  <gazebo reference="left_up_3_stick">
    <material value="Gazebo/FlatBlack"/>
  </gazebo>
  <link name="right_stick">
    <inertial>
      <mass value="0.01"/>
      <origin xyz="0 0 0"/>
      <inertia ixx="1" ixy="0" ixz="0" iyy="1" iyz="0" izz="1"/>
    </inertial>
    <visual name="right_stick">
      <origin rpy="0 0 0" xyz="0 0 0"/>
      <geometry name="stick_geom">
        <box size="0.265 0.030 0.030"/>
      </geometry>
      <material name="StickBlack">
        <color rgba="0.038 0.038 0.038 1.0"/>
      </material>
    </visual>
    <collision>
      <origin rpy="0 0 0" xyz="0.0 0 0"/>
      <geometry name="stick_geom">
        <box size="0.265 0.030 0.030"/>
      </geometry>
    </collision>
  </link>
  <gazebo reference="right_stick">
    <material value="Gazebo/FlatBlack"/>
  </gazebo>
  <link name="right_up_1_stick">
    <inertial>
      <mass value="0.01"/>
      <origin xyz="0 0 0"/>
      <inertia ixx="1" ixy="0" ixz="0" iyy="1" iyz="0" izz="1"/>
    </inertial>
    <visual name="right_up_1_stick">
      <origin rpy="0 0 0" xyz="0 0 0"/>
      <geometry name="stick_2_geom">
        <box size="0.030 0.030  0.22"/>
      </geometry>
      <material name="StickBlack">
        <color rgba="0.038 0.038 0.038 1.0"/>
      </material>
    </visual>
    <collision>
      <origin rpy="0 0 0" xyz="0.0 0 0"/>
      <geometry name="stick_2_geom">
        <box size="0.030 0.030 0.22"/>
      </geometry>
    </collision>
  </link>
  <gazebo reference="right_up_1_stick">
    <material value="Gazebo/FlatBlack"/>
  </gazebo>
  <link name="right_up_2_stick">
    <inertial>
      <mass value="0.01"/>
      <origin xyz="0 0 0"/>
      <inertia ixx="1" ixy="0" ixz="0" iyy="1" iyz="0" izz="1"/>
    </inertial>
    <visual name="right_up_2_stick">
      <origin rpy="0 0 0" xyz="0 0 0"/>
      <geometry name="stick_2_geom">
        <box size="0.030 0.030  0.22"/>
      </geometry>
      <material name="StickBlack">
        <color rgba="0.038 0.038 0.038 1.0"/>
      </material>
    </visual>
    <collision>
      <origin rpy="0 0 0" xyz="0.0 0 0"/>
      <geometry name="stick_2_geom">
        <box size="0.030 0.030 0.22"/>
      </geometry>
    </collision>
  </link>
  <gazebo reference="right_up_2_stick">
    <material value="Gazebo/FlatBlack"/>
  </gazebo>
  <link name="right_up_3_stick">
    <inertial>
      <mass value="0.01"/>
      <origin xyz="0 0 0"/>
      <inertia ixx="1" ixy="0" ixz="0" iyy="1" iyz="0" izz="1"/>
    </inertial>
    <visual name="right_up_3_stick">
      <origin rpy="0 0 0" xyz="0 0 0"/>
      <geometry name="stick_3_geom">
        <box size="0.030 0.030  0.84"/>
      </geometry>
      <material name="StickBlack">
        <color rgba="0.038 0.038 0.038 1.0"/>
      </material>
    </visual>
    <collision>
      <origin rpy="0 0 0" xyz="0.0 0 0"/>
      <geometry name="stick_3_geom">
        <box size="0.030 0.030 0.84"/>
      </geometry>
    </collision>
  </link>
  <gazebo reference="right_up_3_stick">
    <material value="Gazebo/FlatBlack"/>
  </gazebo>
  <link name="up_stick">
    <inertial>
      <mass value="0.01"/>
      <origin xyz="0 0 0"/>
      <inertia ixx="1" ixy="0" ixz="0" iyy="1" iyz="0" izz="1"/>
    </inertial>
    <visual name="up_stick">
      <origin rpy="0 0 0" xyz="0 0 0"/>
      <geometry name="stick_4_geom">
        <box size="0.030 0.46 0.030"/>
      </geometry>
      <material name="StickBlack">
        <color rgba="0.038 0.038 0.038 1.0"/>
      </material>
    </visual>
    <collision>
      <origin rpy="0 0 0" xyz="0.0 0 0"/>
      <geometry name="stick_4_geom">
        <box size="0.030 0.46 0.030"/>
      </geometry>
    </collision>
  </link>
  <gazebo reference="up_stick">
    <material value="Gazebo/FlatBlack"/>
  </gazebo>
  <joint name="left_stick_joint" type="fixed">
    <origin rpy="0 0 0" xyz="-0.010 0.15 0.018"/>
    <parent link="top_plate"/>
    <child link="left_stick"/>
  </joint>
  <joint name="left_up_1_stick_joint" type="fixed">
    <origin rpy="0 0 0" xyz="-0.08 0.0 0.125"/>
    <parent link="left_stick"/>
    <child link="left_up_1_stick"/>
  </joint>
  <joint name="left_up_2_stick_joint" type="fixed">
    <origin rpy="0 0 0" xyz="0.025 0.0 0.125"/>
    <parent link="left_stick"/>
    <child link="left_up_2_stick"/>
  </joint>
  <joint name="left_up_3_stick_joint" type="fixed">
    <origin rpy="0 0 0" xyz="0.0 0.03 0.28"/>
    <parent link="left_up_2_stick"/>
    <child link="left_up_3_stick"/>
  </joint>
  <joint name="right_stick_joint" type="fixed">
    <origin rpy="0 0 0" xyz="-0.010 -0.15 0.018"/>
    <parent link="top_plate"/>
    <child link="right_stick"/>
  </joint>
  <joint name="right_up_1_stick_joint" type="fixed">
    <origin rpy="0 0 0" xyz="-0.08 0.0 0.125"/>
    <parent link="right_stick"/>
    <child link="right_up_1_stick"/>
  </joint>
  <joint name="right_up_2_stick_joint" type="fixed">
    <origin rpy="0 0 0" xyz="0.025 0.0 0.125"/>
    <parent link="right_stick"/>
    <child link="right_up_2_stick"/>
  </joint>
  <joint name="right_up_3_stick_joint" type="fixed">
    <origin rpy="0 0 0" xyz="0.0 -0.03 0.28"/>
    <parent link="right_up_2_stick"/>
    <child link="right_up_3_stick"/>
  </joint>
  <joint name="up_stick_joint" type="fixed">
    <origin rpy="0 0 0" xyz="0.0 -0.18 0.435"/>
    <parent link="left_up_3_stick"/>
    <child link="up_stick"/>
  </joint>
  <link name="camera_mount">
    <inertial>
      <mass value="0.01"/>
      <origin xyz="0 0 0"/>
      <inertia ixx="1" ixy="0" ixz="0" iyy="1" iyz="0" izz="1"/>
    </inertial>
    <visual name="camera_mount">
      <origin rpy="0 0 0" xyz="0 0 0"/>
      <geometry>
        <box size="0.09 0.069 0.045 "/>
      </geometry>
      <material name="StickBlack">
        <color rgba="0.038 0.038 0.038 1.0"/>
      </material>
    </visual>
    <collision>
      <origin rpy="0 0 0" xyz="0.0 0 0"/>
      <geometry name="box_1_geom">
        <box size="0.09 0.069 0.045 "/>
      </geometry>
    </collision>
  </link>
  <gazebo reference="camera_mount">
    <material value="Gazebo/FlatBlack"/>
  </gazebo>
  <link name="camera_pan">
    <inertial>
      <mass value="0.01"/>
      <origin xyz="0 0 0"/>
      <inertia ixx="1" ixy="0" ixz="0" iyy="1" iyz="0" izz="1"/>
    </inertial>
    <visual name="camera_pan">
      <origin rpy="0 0 0" xyz="0 0 0"/>
      <geometry>
        <box size="0.043 0.042 0.067 "/>
      </geometry>
      <material name="StickBlack">
        <color rgba="0.038 0.038 0.038 1.0"/>
      </material>
    </visual>
    <collision>
      <origin rpy="0 0 0" xyz="0.0 0 0"/>
      <geometry name="box_2_geom">
        <box size="0.043 0.042 0.067 "/>
      </geometry>
    </collision>
  </link>
  <gazebo reference="camera_pan">
    <material value="Gazebo/FlatBlack"/>
  </gazebo>
  <link name="camera_tilt">
    <inertial>
      <mass value="0.01"/>
      <origin xyz="0 0 0"/>
      <inertia ixx="1" ixy="0" ixz="0" iyy="1" iyz="0" izz="1"/>
    </inertial>
    <visual name="camera_tilt">
      <origin rpy="0 0 0" xyz="0 0 0"/>
      <geometry>
        <box size="0.025 0.064 0.05 "/>
      </geometry>
      <material name="StickBlack">
        <color rgba="0.038 0.038 0.038 1.0"/>
      </material>
    </visual>
    <collision>
      <origin rpy="0 0 0" xyz="0.0 0 0"/>
      <geometry name="box_3_geom">
        <box size="0.025 0.064 0.05 "/>
      </geometry>
    </collision>
  </link>
  <gazebo reference="camera_tilt">
    <material value="Gazebo/FlatBlack"/>
  </gazebo>
  <joint name="camera_mount_joint" type="fixed">
    <origin rpy="0.0 0 -1.570796327" xyz="0.0 0 0.0375"/>
    <parent link="up_stick"/>
    <child link="camera_mount"/>
  </joint>
  <joint name="camera_pan_joint" type="revolute">
    <parent link="camera_mount"/>
    <child link="camera_pan"/>
    <dynamics damping="0.1" friction="0"/>
    <limit effort="1000.0" lower="-3.1416" upper="3.1416" velocity="0.5"/>
    <axis xyz="0 0 1"/>
    <origin rpy="0.0 0 0.0" xyz="0.0235 -0.0105 0.056"/>
  </joint>
  <joint name="camera_tilt_joint" type="revolute">
    <parent link="camera_pan"/>
    <child link="camera_tilt"/>
    <dynamics damping="0.1" friction="0"/>
    <limit effort="1000.0" lower="-0.541052068" upper="1.3962634" velocity="0.5"/>
    <axis xyz="0 1 0"/>
    <origin rpy="0.0 0 0.0" xyz="0.0 0.0 0.0255"/>
  </joint>
  <link name="camera_link">
    <inertial>
      <mass value="0.01"/>
      <origin xyz="0 0 0"/>
      <inertia ixx="0.001" ixy="0.0" ixz="0.0" iyy="0.001" iyz="0.0" izz="0.001"/>
    </inertial>
    <visual>
      <origin rpy="0 0 0" xyz=" 0 0 0 "/>
      <geometry>
        <mesh filename="package://ari_robot/meshes/kinect.dae"/>
      </geometry>
    </visual>
    <collision>
      <origin rpy="0 0 0" xyz="0.0 0.0 0.0"/>
      <geometry>
        <box size="0.0730 .2760 0.0720"/>
      </geometry>
    </collision>
  </link>
  <link name="camera_depth_frame">
    <inertial>
      <mass value="0.01"/>
      <origin xyz="0 0 0"/>
      <inertia ixx="0.001" ixy="0.0" ixz="0.0" iyy="0.001" iyz="0.0" izz="0.001"/>
    </inertial>
  </link>
  <link name="camera_depth_optical_frame">
    <inertial>
      <mass value="0.001"/>
      <origin xyz="0 0 0"/>
      <inertia ixx="0.0001" ixy="0.0" ixz="0.0" iyy="0.0001" iyz="0.0" izz="0.0001"/>
    </inertial>
  </link>
  <link name="camera_rgb_frame">
    <inertial>
      <mass value="0.001"/>
      <origin xyz="0 0 0"/>
      <inertia ixx="0.0001" ixy="0.0" ixz="0.0" iyy="0.0001" iyz="0.0" izz="0.0001"/>
    </inertial>
  </link>
  <link name="camera_rgb_optical_frame">
    <inertial>
      <mass value="0.001"/>
      <origin xyz="0 0 0"/>
      <inertia ixx="0.0001" ixy="0.0" ixz="0.0" iyy="0.0001" iyz="0.0" izz="0.0001"/>
    </inertial>
  </link>
  <joint name="base_camera_joint" type="fixed">
    <origin rpy="0 0 0" xyz="0.03 0.0 0.078"/>
    <parent link="camera_tilt"/>
    <child link="camera_link"/>
  </joint>
  <joint name="camera_depth_joint" type="fixed">
    <origin rpy="0 0 0" xyz="0 0.049 0"/>
    <parent link="camera_link"/>
    <child link="camera_depth_frame"/>
  </joint>
  <joint name="camera_depth_optical_joint" type="fixed">
    <origin rpy="-1.570795 0 -1.570795" xyz="0 0 0"/>
    <parent link="camera_depth_frame"/>
    <child link="camera_depth_optical_frame"/>
  </joint>
  <joint name="camera_rgb_joint" type="fixed">
    <origin rpy="0 0 0" xyz="0 0.022 0"/>
    <parent link="camera_link"/>
    <child link="camera_rgb_frame"/>
  </joint>
  <joint name="camera_rgb_optical_joint" type="fixed">
    <origin rpy="-1.570795 0 -1.570795" xyz="0 0 0"/>
    <parent link="camera_rgb_frame"/>
    <child link="camera_rgb_optical_frame"/>
  </joint>
  <transmission name="pan_trans" type="pr2_mechanism_model/SimpleTransmission">
    <actuator name="pan_motor"/>
    <joint name="camera_pan_joint"/>
    <mechanicalReduction>1</mechanicalReduction>
    <motorTorqueConstant>1</motorTorqueConstant>
  </transmission>
  <transmission name="tilt_trans" type="pr2_mechanism_model/SimpleTransmission">
    <actuator name="tilt_motor"/>
    <joint name="camera_tilt_joint"/>
    <mechanicalReduction>1</mechanicalReduction>
    <motorTorqueConstant>1</motorTorqueConstant>
  </transmission>
  <gazebo>
    <controller:differential_position2d name="controller1">
      <update>100</update>
      <leftJoint>base_right_wheel_joint</leftJoint>
      <rightJoint>base_left_wheel_joint</rightJoint>
      <wheelSeparation>0.39</wheelSeparation>
      <wheelDiameter>0.15</wheelDiameter>
      <torque>5</torque>
      <interface:position name="position_iface_0"/>
    </controller:differential_position2d>
    <controller:gazebo_ros_p3d name="p3d_base_controller" plugin="libgazebo_ros_p3d.so">
      <alwaysOn>true</alwaysOn>
      <updateRate>100.0</updateRate>
      <bodyName>base_link</bodyName>
      <topicName>base_pose_ground_truth</topicName>
      <gaussianNoise>0.01</gaussianNoise>
      <frameName>map</frameName>
      <xyzOffsets>0 0 0</xyzOffsets>
      <!-- initialize odometry for fake localization-->
      <rpyOffsets>0 0 0</rpyOffsets>
      <interface:position name="p3d_base_position"/>
    </controller:gazebo_ros_p3d>
    <!-- this publishes empty joint_states due to no transmission, but
        	 	triggering robot_state_puublisher to publish tf between fixed joints in erratic,
	         	(e.g. base_laser_link for the base_scan frame)  -->
    <controller:gazebo_ros_controller_manager name="gazebo_ros_controller_manager" plugin="libgazebo_ros_controller_manager.so">
      <alwaysOn>true</alwaysOn>
      <updateRate>1000.0</updateRate>
      <interface:audio name="gazebo_ros_controller_manager_dummy_iface"/>
    </controller:gazebo_ros_controller_manager>
  </gazebo>
  <gazebo reference="camera_link">
    <sensor:camera name="camera">
      <imageSize>640 480</imageSize>
      <imageFormat>R8G8B8</imageFormat>
      <hfov>62.8</hfov>
      <nearClip>0.1</nearClip>
      <farClip>10</farClip>
      <updateRate>2.0</updateRate>
      <controller:gazebo_ros_wge100 name="kinect_camera_controller" plugin="libgazebo_ros_wge100.so">
        <alwaysOn>true</alwaysOn>
        <updateRate>5000.0</updateRate>
        <cameraName>camera/rgb</cameraName>
        <frameName>camera_rgb_optical_frame</frameName>
        <hackBaseline>0.0</hackBaseline>
        <CxPrime>320.5</CxPrime>
        <Cx>320.5</Cx>
        <Cy>240.5</Cy>
        <baseline>0.09</baseline>
        <!-- image_width / (2*tan(hfov_radian /2)) -->
        <!-- 320 for wide and 772.55 for narrow stereo camera -->
        <focal_length>525</focal_length>
        <cameraNamespace>camera/rgb</cameraNamespace>
        <depthData>true</depthData>
        <interface:camera name="camera_iface"/>
      </controller:gazebo_ros_wge100>
    </sensor:camera>
  </gazebo>
  <gazebo reference="base_laser">
    <sensor:ray name="laser">
      <rayCount>361</rayCount>
      <rangeCount>361</rangeCount>
      <laserCount>1</laserCount>
      <origin>0.0 0.0 0.0</origin>
      <displayRays>true</displayRays>
      <minAngle>-90</minAngle>
      <maxAngle>90</maxAngle>
      <minRange>0.05</minRange>
      <maxRange>7.9</maxRange>
      <resRange>0.01</resRange>
      <updateRate>4.0</updateRate>
      <controller:gazebo_ros_laser name="gazebo_ros_laser_controller" plugin="libgazebo_ros_laser.so">
        <gaussianNoise>0.005</gaussianNoise>
        <alwaysOn>true</alwaysOn>
        <updateRate>4.0</updateRate>
        <topicName>scan</topicName>
        <frameName>base_laser</frameName>
        <interface:laser name="gazebo_ros_laser_iface"/>
      </controller:gazebo_ros_laser>
    </sensor:ray>
  </gazebo>
</robot>

