<?xml version="1.0" ?>
<!-- =================================================================================== -->
<!-- |    This document was autogenerated by xacro from /home/alex/ros/pkgs/tue-ros-pkg/trunk/tue_robot_models/amigo_robot_model/robot.urdf.xacro | -->
<!-- |    EDITING THIS FILE BY HAND IS NOT RECOMMENDED                                 | -->
<!-- =================================================================================== -->
<robot name="amigo" xmlns:controller="http://playerstage.sourceforge.net/gazebo/xmlschema/#controller" xmlns:interface="http://playerstage.sourceforge.net/gazebo/xmlschema/#interface" xmlns:sensor="http://playerstage.sourceforge.net/gazebo/xmlschema/#sensor" xmlns:xacro="http://ros.org/wiki/xacro">
  <!--get plugins -->
  <gazebo>
    <controller:gazebo_ros_time name="gazebo_ros_time" plugin="libgazebo_ros_time.so">
      <alwaysOn>true</alwaysOn>
      <updateRate>1000.0</updateRate>
      <interface:audio name="dummy_gazebo_ros_time_iface_should_not_be_here"/>
    </controller:gazebo_ros_time>
    <controller:gazebo_ros_controller_manager name="gazebo_ros_controller_manager" plugin="libgazebo_ros_controller_manager.so">
      <alwaysOn>true</alwaysOn>
      <updateRate>1000.0</updateRate>
      <interface:audio name="gazebo_ros_controller_manager_dummy_iface"/>
    </controller:gazebo_ros_controller_manager>
    <controller:gazebo_ros_imu name="imu_controller" plugin="libgazebo_ros_imu.so">
      <alwaysOn>true</alwaysOn>
      <updateRate>1000.0</updateRate>
      <bodyName>base_link</bodyName>
      <topicName>body_pose_ground_truth</topicName>
      <xyzOffsets>0.0 0.0 0</xyzOffsets>
      <rpyOffsets>0 0 0</rpyOffsets>
      <interface:position name="imu_position_iface"/>
    </controller:gazebo_ros_imu>
    <controller:gazebo_ros_p3d name="base_controller" plugin="libgazebo_ros_p3d.so">
      <alwaysOn>true</alwaysOn>
      <updateRate>100.0</updateRate>
      <bodyName>base_link</bodyName>
      <topicName>base_pose_ground_truth</topicName>
      <gaussianNoise>0.01</gaussianNoise>
      <frameName>map</frameName>
      <xyzOffsets>25.7 25.7 0</xyzOffsets>
      <!-- initialize odometry for fake localization-->
      <rpyOffsets>0 0 0</rpyOffsets>
      <interface:position name="p3d_base_position"/>
    </controller:gazebo_ros_p3d>
  </gazebo>
  <gazebo reference="base_laser">
    <sensor:ray name="base_ray_sensor">
      <origin>0.0 0.0 0.0</origin>
      <rayCount>683</rayCount>
      <rangeCount>683</rangeCount>
      <laserCount>1</laserCount>
      <displayRays>false</displayRays>
      <minAngle>-135</minAngle>
      <maxAngle> 135</maxAngle>
      <minRange>0.05</minRange>
      <maxRange>10.0</maxRange>
      <resRange>0.01</resRange>
      <updateRate>100.0</updateRate>
      <controller:gazebo_ros_laser name="base_ros_ray_sensor_controller" plugin="libgazebo_ros_laser.so">
        <gaussianNoise>0.005</gaussianNoise>
        <alwaysOn>true</alwaysOn>
        <updateRate>15.0</updateRate>
        <topicName>base_scan</topicName>
        <frameName>/base_laser</frameName>
        <interface:laser name="base_ros_ray_sensor_iface"/>
      </controller:gazebo_ros_laser>
    </sensor:ray>
  </gazebo>
  <gazebo reference="top_laser">
    <sensor:ray name="top_ray_sensor">
      <origin>0.0 0.0 0.0</origin>
      <rayCount>683</rayCount>
      <rangeCount>683</rangeCount>
      <laserCount>1</laserCount>
      <displayRays>false</displayRays>
      <minAngle>-135</minAngle>
      <maxAngle> 135</maxAngle>
      <minRange>0.05</minRange>
      <maxRange>10.0</maxRange>
      <resRange>0.01</resRange>
      <updateRate>100.0</updateRate>
      <controller:gazebo_ros_laser name="top_ros_ray_sensor_controller" plugin="libgazebo_ros_laser.so">
        <gaussianNoise>0.005</gaussianNoise>
        <alwaysOn>true</alwaysOn>
        <updateRate>15.0</updateRate>
        <topicName>top_scan</topicName>
        <frameName>/top_laser</frameName>
        <interface:laser name="top_ros_ray_sensor_iface"/>
      </controller:gazebo_ros_laser>
    </sensor:ray>
  </gazebo>
  <gazebo reference="openni_camera">
    <sensor:camera name="openni_camera">
      <imageFormat>R8G8B8</imageFormat>
      <imageSize>640 480</imageSize>
      <hfov>60</hfov>
      <nearClip>0.05</nearClip>
      <farClip>3</farClip>
      <updateRate>20</updateRate>
      <baseline>0.1</baseline>
      <controller:gazebo_ros_openni_kinect name="kinect_camera_controller" plugin="libgazebo_ros_openni_kinect.so">
        <alwaysOn>true</alwaysOn>
        <updateRate>20</updateRate>
        <imageTopicName>/camera/rgb/image_raw</imageTopicName>
        <pointCloudTopicName>/camera/rgb/points</pointCloudTopicName>
        <cameraInfoTopicName>/camera/rgb/camera_info</cameraInfoTopicName>
        <frameName>/openni_depth_optical_frame</frameName>
        <!--<distortion_k1>0.00000001</distortion_k1>
        <distortion_k2>0.00000001</distortion_k2>
        <distortion_k3>0.00000001</distortion_k3>
        <distortion_t1>0.00000001</distortion_t1>
        <distortion_t2>0.00000001</distortion_t2>-->
      </controller:gazebo_ros_openni_kinect>
    </sensor:camera>
  </gazebo>
  <!--get link & joint definitions -->
  <!--get custom materials -->
  <material name="Blue">
    <color rgba="0.0 0.0 0.8 1.0"/>
  </material>
  <material name="Green">
    <color rgba="0.0 0.8 0.0 1.0"/>
  </material>
  <material name="Grey">
    <color rgba="0.7 0.7 0.7 1.0"/>
  </material>
  <material name="Grey2">
    <color rgba="0.9 0.9 0.9 1.0"/>
  </material>
  <material name="Red">
    <color rgba="0.8 0.0 0.0 1.0"/>
  </material>
  <material name="White">
    <color rgba="1.0 1.0 1.0 1.0"/>
  </material>
  <material name="Black">
    <color rgba="0.1 0.1 0.1 1.0"/>
  </material>
  <material name="LightGrey">
    <color rgba="0.6 0.6 0.6 1.0"/>
  </material>
  <material name="bottomcovers">
    <texture filename="package://amigo_robot_model/Media/materials/textures/bottomcovers/finalreduced.jpg"/>
  </material>
  <material name="white">
    <texture filename="package://amigo_robot_model/Media/materials/textures/white/white.jpg"/>
  </material>
  <material name="logo">
    <texture filename="package://amigo_robot_model/Media/materials/textures/logo/tue.jpg"/>
  </material>
  <material name="aluminum">
    <texture filename="package://amigo_robot_model/Media/materials/textures/aluminum/aluminium_0001_c.jpg"/>
  </material>
  <material name="orange">
    <texture filename="package://amigo_robot_model/Media/materials/textures/orange/orange.jpg"/>
  </material>
  <!--========BUILD BODY======-->
  <link name="base">
    <inertial>
      <origin rpy="0 0 0" xyz="0.0 0.0 0.3275"/>
      <mass value="20"/>
      <inertia ixx="2.63" ixy="0" ixz="0" iyy="2.63" iyz="0" izz="2.4"/>
    </inertial>
    <visual>
      <origin rpy="0 0 -1.5708" xyz="0.0 0.0 0.23"/>
      <geometry>
        <mesh filename="package://amigo_robot_model/body/bottomcovers.dae" scale="0.001 0.001 0.001"/>
      </geometry>
      <material name="bottomcovers"/>
    </visual>
    <collision>
      <origin rpy="0 0 -1.5708" xyz="0.0 0.0 0.33"/>
      <geometry>
        <box size="0.275 0.275 0.6"/>
      </geometry>
    </collision>
  </link>
  <gazebo reference="base">
    <material>amigo_robot_model/bottomcovers</material>
    <turnGravityOff>false</turnGravityOff>
  </gazebo>
  <link name="torso_slider">
    <inertial>
      <origin rpy="0 0 0" xyz="0 0 0"/>
      <mass value="0.1"/>
      <inertia ixx="0.01" ixy="0" ixz="0" iyy="0.01" iyz="0" izz="0.01"/>
    </inertial>
    <visual>
      <origin rpy="0 1.5708 0" xyz="-0.35 0.0 0.0"/>
      <geometry>
        <mesh filename="package://amigo_robot_model/body/torsoslidertextured.dae" scale="0.01 0.01 0.01"/>
      </geometry>
      <material name="aluminum"/>
    </visual>
    <collision>
      <origin rpy="0 1.5708 0" xyz="-0.35 0.0 0.0"/>
      <geometry>
        <mesh filename="package://amigo_robot_model/body/torsoslidertextured.dae" scale="0.01 0.01 0.01"/>
      </geometry>
    </collision>
  </link>
  <gazebo reference="torso_slider">
    <material>amigo_robot_model/aluminum</material>
    <turnGravityOff>false</turnGravityOff>
  </gazebo>
  <link name="base_link">
    <inertial>
      <origin rpy="0 0 0" xyz="0.0 0.0 0.0"/>
      <mass value="0"/>
      <inertia ixx="0" ixy="0" ixz="0" iyy="0" iyz="0" izz="0"/>
    </inertial>
    <visual>
      <origin rpy="0 0 0" xyz="0.0 0.0 0.0"/>
      <geometry>
        <cylinder length="0.00" radius="0.0"/>
      </geometry>
      <material name="Red">
     </material>
    </visual>
    <collision>
      <origin rpy="0 0 0" xyz="0.0 0.0 0.0"/>
      <geometry>
        <cylinder length="0.00" radius="0.0"/>
      </geometry>
    </collision>
  </link>
  <gazebo reference="base_link">
    <material>Gazebo/Red</material>
    <turnGravityOff>false</turnGravityOff>
  </gazebo>
  <link name="batterycovercollision_left">
    <inertial>
      <origin xyz="0.0 0.0 0.0"/>
      <mass value="0.001"/>
      <inertia ixx="0.01" ixy="0" ixz="0" iyy="0.01" iyz="0" izz="0.01"/>
    </inertial>
    <visual>
      <origin xyz="0.0 0.0 0.0"/>
      <geometry>
        <box size="0.0 0.0 0.0"/>
      </geometry>
    </visual>
    <collision>
      <origin xyz="0.0 0.0 0.0"/>
      <geometry>
        <box size="0.25 0.15 0.125"/>
      </geometry>
    </collision>
  </link>
  <joint name="batterycovercollision_left_joint" type="fixed">
    <parent link="base"/>
    <child link="batterycovercollision_left"/>
    <axis xyz="1 0 0"/>
    <origin rpy="0 0 0" xyz="0.0 0.25 0.1"/>
  </joint>
  <link name="batterycovercollision_right">
    <inertial>
      <origin xyz="0.0 0.0 0.0"/>
      <mass value="0.001"/>
      <inertia ixx="0.01" ixy="0" ixz="0" iyy="0.01" iyz="0" izz="0.01"/>
    </inertial>
    <visual>
      <origin xyz="0.0 0.0 0.0"/>
      <geometry>
        <box size="0.0 0.0 0.0"/>
      </geometry>
    </visual>
    <collision>
      <origin xyz="0.0 0.0 0.0"/>
      <geometry>
        <box size="0.25 0.15 0.125"/>
      </geometry>
    </collision>
  </link>
  <joint name="batterycovercollision_right_joint" type="fixed">
    <parent link="base"/>
    <child link="batterycovercollision_right"/>
    <axis xyz="1 0 0"/>
    <origin rpy="0 0 0" xyz="0.0 -0.25 0.1"/>
  </joint>
  <link name="batterycovercollision_back">
    <inertial>
      <origin xyz="0.0 0.0 0.0"/>
      <mass value="0.001"/>
      <inertia ixx="0.01" ixy="0" ixz="0" iyy="0.01" iyz="0" izz="0.01"/>
    </inertial>
    <visual>
      <origin xyz="0.0 0.0 0.0"/>
      <geometry>
        <box size="0.0 0.0 0.0"/>
      </geometry>
    </visual>
    <collision>
      <origin xyz="0.0 0.0 0.0"/>
      <geometry>
        <box size="0.25 0.15 0.175"/>
      </geometry>
    </collision>
  </link>
  <joint name="batterycovercollision_back_joint" type="fixed">
    <parent link="base"/>
    <child link="batterycovercollision_back"/>
    <axis xyz="1 0 0"/>
    <origin rpy="0 0 1.5708" xyz="-0.25 0.0 0.125"/>
  </joint>
  <link name="torso">
    <inertial>
      <origin rpy="0 0 0" xyz="0.0 0.0 0.0"/>
      <mass value="16"/>
      <inertia ixx="0.01" ixy="0" ixz="0" iyy="0.01" iyz="0" izz="0.01"/>
    </inertial>
    <visual>
      <origin rpy="-1.5708 0 -1.5708" xyz="0.045 0.0 0.06"/>
      <geometry>
        <mesh filename="package://amigo_robot_model/body/torsocovers.dae" scale="0.001 0.001 0.001"/>
      </geometry>
      <material name="white"/>
    </visual>
    <collision>
      <origin rpy="-1.5708 0 -1.5708" xyz="0.045 0.0 0.06"/>
      <geometry>
        <mesh filename="package://amigo_robot_model/body/torsocovers.dae" scale="0.001 0.001 0.001"/>
      </geometry>
    </collision>
  </link>
  <gazebo reference="torso">
    <material>amigo_robot_model/white</material>
    <turnGravityOff>false</turnGravityOff>
  </gazebo>
  <joint name="spindle_joint" type="prismatic">
    <parent link="base"/>
    <child link="torso_slider"/>
    <axis xyz="1 0 0"/>
    <origin rpy="3.14159265 -1.5708 0" xyz="0.0 0.0 0.58"/>
    <dynamics damping="3" friction="0.0"/>
    <!--*-->
    <limit effort="30" lower="0.0" upper="0.41" velocity="1.0"/>
    <!--*-->
  </joint>
  <joint name="base_link_joint" type="fixed">
    <parent link="base_link"/>
    <child link="base"/>
    <axis xyz="1 0 0"/>
    <origin rpy="0 0 0" xyz="0.0 0.0 0.055"/>
  </joint>
  <joint name="torso_slider_joint" type="fixed">
    <parent link="torso_slider"/>
    <child link="torso"/>
    <axis xyz="1 0 0"/>
    <origin rpy="0 0 0" xyz="0.135 0.0 0.0"/>
  </joint>
  <!--extra body visuals-->
  <link name="base_plate">
    <inertial>
      <origin rpy="0 0 0" xyz="0.0 0.0 0.0"/>
      <mass value="0.1"/>
      <inertia ixx="0.01" ixy="0" ixz="0" iyy="0.01" iyz="0" izz="0.01"/>
    </inertial>
    <visual>
      <origin rpy="0 0 0" xyz="0.0 0.0 0.0"/>
      <geometry>
        <cylinder length="0.02" radius="0.333"/>
      </geometry>
      <material name="aluminum">
     </material>
    </visual>
    <collision>
      <origin rpy="0 0 0" xyz="0.0 0.0 0.0"/>
      <geometry>
        <cylinder length="0.02" radius="0.333"/>
      </geometry>
    </collision>
  </link>
  <gazebo reference="base_plate">
    <material>amigo_robot_model/aluminum</material>
    <turnGravityOff>false</turnGravityOff>
  </gazebo>
  <joint name="base_plate_joint" type="fixed">
    <parent link="base_link"/>
    <child link="base_plate"/>
    <axis xyz="1 0 0"/>
    <origin rpy="0 0 0" xyz="0.0 0.0 0.05"/>
  </joint>
  <link name="torso_assist_slider_right">
    <inertial>
      <origin rpy="0 0 0" xyz="0 0 0"/>
      <mass value="0.01"/>
      <inertia ixx="0.01" ixy="0" ixz="0" iyy="0.01" iyz="0" izz="0.01"/>
    </inertial>
    <visual>
      <origin rpy="0 1.5708 0" xyz="-0.4  0.0 0.0"/>
      <geometry>
        <mesh filename="package://amigo_robot_model/body_extra_visuals/torsoassistslidertextured.dae" scale="0.01 0.01 0.0125"/>
      </geometry>
      <material name="aluminum"/>
    </visual>
    <collision>
      <origin rpy="0 1.5708 0" xyz="-0.4  0.0 0.0"/>
      <geometry>
        <mesh filename="package://amigo_robot_model/body_extra_visuals/torsoassistslidertextured.dae" scale="0.01 0.01 0.0125"/>
      </geometry>
    </collision>
  </link>
  <gazebo reference="torso_assist_slider_right">
    <material>amigo_robot_model/aluminum</material>
    <turnGravityOff>false</turnGravityOff>
  </gazebo>
  <link name="torso_assist_slider_left">
    <inertial>
      <origin rpy="0 0 0" xyz="0 0 0"/>
      <mass value="0.01"/>
      <inertia ixx="0.01" ixy="0" ixz="0" iyy="0.01" iyz="0" izz="0.01"/>
    </inertial>
    <visual>
      <origin rpy="0 1.5708 0" xyz="-0.4  0.0 0.0"/>
      <geometry>
        <mesh filename="package://amigo_robot_model/body_extra_visuals/torsoassistslidertextured.dae" scale="0.01 0.01 0.0125"/>
      </geometry>
      <material name="aluminum"/>
    </visual>
    <collision>
      <origin rpy="0 1.5708 0" xyz="-0.4  0.0 0.0"/>
      <geometry>
        <mesh filename="package://amigo_robot_model/body_extra_visuals/torsoassistslidertextured.dae" scale="0.01 0.01 0.0125"/>
      </geometry>
    </collision>
  </link>
  <gazebo reference="torso_assist_slider_left">
    <material>amigo_robot_model/aluminum</material>
    <turnGravityOff>false</turnGravityOff>
  </gazebo>
  <link name="torso_assist_slider_back">
    <inertial>
      <origin rpy="0 0 0" xyz="0 0 0"/>
      <mass value="0.01"/>
      <inertia ixx="0.01" ixy="0" ixz="0" iyy="0.01" iyz="0" izz="0.01"/>
    </inertial>
    <visual>
      <origin rpy="0 1.5708 0" xyz="-0.4 0.0 0.0"/>
      <geometry>
        <mesh filename="package://amigo_robot_model/body_extra_visuals/torsoassistslidertextured.dae" scale="0.01 0.01 0.0125"/>
      </geometry>
      <material name="aluminum"/>
    </visual>
    <collision>
      <origin rpy="0 1.5708 0" xyz="-0.4 0.0 0.0"/>
      <geometry>
        <mesh filename="package://amigo_robot_model/body_extra_visuals/torsoassistslidertextured.dae" scale="0.01 0.01 0.0125"/>
      </geometry>
    </collision>
  </link>
  <gazebo reference="torso_assist_slider_back">
    <material>amigo_robot_model/aluminum</material>
    <turnGravityOff>false</turnGravityOff>
  </gazebo>
  <joint name="torso_slider_assist_joint_right" type="fixed">
    <parent link="torso"/>
    <child link="torso_assist_slider_right"/>
    <origin rpy="0 0 0" xyz="-0.3 0.1 0.0"/>
  </joint>
  <joint name="torso_slider_assist_joint_left" type="fixed">
    <parent link="torso"/>
    <child link="torso_assist_slider_left"/>
    <origin rpy="0 0 0" xyz="-0.3 -0.1 0.0"/>
  </joint>
  <joint name="torso_slider_assist_joint_back" type="fixed">
    <parent link="torso"/>
    <child link="torso_assist_slider_back"/>
    <origin rpy="1.5708 0 0" xyz="-0.3 0.0 -0.1"/>
  </joint>
  <link name="clavicles">
    <inertial>
      <origin rpy="0 0 0" xyz="0 0 0"/>
      <mass value="0.01"/>
      <inertia ixx="0.01" ixy="0" ixz="0" iyy="0.01" iyz="0" izz="0.01"/>
    </inertial>
    <visual>
      <origin rpy="0 0 0" xyz="0.0 0.0 0.0"/>
      <geometry>
        <box size="0.1 0.436 0.11"/>
      </geometry>
      <material name="Black">
     </material>
    </visual>
    <collision>
      <origin rpy="0 0 0" xyz="0.0 0.0 0.0"/>
      <geometry>
        <box size="0.1 0.436 0.11"/>
      </geometry>
    </collision>
  </link>
  <gazebo reference="clavicles">
    <material>Gazebo/Black</material>
    <turnGravityOff>false</turnGravityOff>
  </gazebo>
  <joint name="clavicle_joint" type="fixed">
    <parent link="torso"/>
    <child link="clavicles"/>
    <origin rpy="0 0 0" xyz="0.05 0.0 0.0"/>
  </joint>
  <link name="closure_right">
    <inertial>
      <origin rpy="0 0 0" xyz="0 0 0"/>
      <mass value="0.01"/>
      <inertia ixx="0.01" ixy="0" ixz="0" iyy="0.01" iyz="0" izz="0.01"/>
    </inertial>
    <visual>
      <origin rpy="0 0 0" xyz="0.0 0.0 0.0"/>
      <geometry>
        <box size="0.12 0.004 0.155"/>
      </geometry>
      <material name="White">
     </material>
    </visual>
    <collision>
      <origin rpy="0 0 0" xyz="0.0 0.0 0.0"/>
      <geometry>
        <box size="0.12 0.004 0.155"/>
      </geometry>
    </collision>
  </link>
  <gazebo reference="closure_right">
    <material>Gazebo/White</material>
    <turnGravityOff>false</turnGravityOff>
  </gazebo>
  <joint name="closure_right_joint" type="fixed">
    <parent link="torso"/>
    <child link="closure_right"/>
    <origin rpy="0 0 0" xyz="0.045 0.12 0.0"/>
  </joint>
  <link name="closure_left">
    <inertial>
      <origin rpy="0 0 0" xyz="0 0 0"/>
      <mass value="0.01"/>
      <inertia ixx="0.01" ixy="0" ixz="0" iyy="0.01" iyz="0" izz="0.01"/>
    </inertial>
    <visual>
      <origin rpy="0 0 0" xyz="0.0 0.0 0.0"/>
      <geometry>
        <box size="0.12 0.004 0.155"/>
      </geometry>
      <material name="White">
     </material>
    </visual>
    <collision>
      <origin rpy="0 0 0" xyz="0.0 0.0 0.0"/>
      <geometry>
        <box size="0.12 0.004 0.155"/>
      </geometry>
    </collision>
  </link>
  <gazebo reference="closure_left">
    <material>Gazebo/White</material>
    <turnGravityOff>false</turnGravityOff>
  </gazebo>
  <joint name="closure_left_joint" type="fixed">
    <parent link="torso"/>
    <child link="closure_left"/>
    <origin rpy="0 0 0" xyz="0.045 -0.12 0.0"/>
  </joint>
  <link name="closure_bottom">
    <inertial>
      <origin rpy="0 0 0" xyz="0 0 0"/>
      <mass value="0.01"/>
      <inertia ixx="0.01" ixy="0" ixz="0" iyy="0.01" iyz="0" izz="0.01"/>
    </inertial>
    <visual>
      <origin rpy="0 0 0" xyz="0.0 0.0 0.0"/>
      <geometry>
        <cylinder length="0.004" radius="0.1"/>
      </geometry>
      <material name="White">
     </material>
    </visual>
    <collision>
      <origin rpy="0 0 0" xyz="0.0 0.0 0.0"/>
      <geometry>
        <cylinder length="0.004" radius="0.1"/>
      </geometry>
    </collision>
  </link>
  <gazebo reference="closure_bottom">
    <material>Gazebo/White</material>
    <turnGravityOff>false</turnGravityOff>
  </gazebo>
  <joint name="closure_bottom_joint" type="fixed">
    <parent link="torso"/>
    <child link="closure_bottom"/>
    <origin rpy="0 1.5708 0" xyz="-0.05 0.0 0.0"/>
  </joint>
  <!--========BUILD LASER======-->
  <link name="base_laser">
    <inertial>
      <origin rpy="0 0 0" xyz="0.0 0.0 0.0"/>
      <mass value="0.5"/>
      <inertia ixx="0.0001" ixy="0" ixz="0" iyy="0.0001" iyz="0" izz="0.0001"/>
    </inertial>
    <visual>
      <origin rpy="0 0 0" xyz="-0.005 0.0 -0.065"/>
      <geometry>
        <box size="0.05 0.065 0.12"/>
      </geometry>
      <material name="Black">
     </material>
    </visual>
    <collision>
      <origin rpy="0 0 0" xyz="-0.005 0.0 -0.065"/>
      <geometry>
        <box size="0.05 0.065 0.12"/>
      </geometry>
    </collision>
  </link>
  <gazebo reference="base_laser">
    <material>Gazebo/Black</material>
    <turnGravityOff>false</turnGravityOff>
  </gazebo>
  <joint name="base_laser_joint" type="fixed">
    <parent link="base"/>
    <child link="base_laser"/>
    <origin rpy="0 0 0" xyz="0.31 0.0 0.185"/>
    <axis xyz="0 1 0"/>
    <dynamics damping="0.1" friction="0"/>
    <limit effort="13.4" lower="-0.7809" upper="1.5708" velocity="1.0"/>
  </joint>
  <link name="lasertop">
    <inertial>
      <origin rpy="0 0 0" xyz="0.0 0.0 0.0"/>
      <mass value="0.01"/>
      <inertia ixx="0.0001" ixy="0" ixz="0" iyy="0.0001" iyz="0" izz="0.0001"/>
    </inertial>
    <visual>
      <origin rpy="0 0 0" xyz="-0.005 0.0 0.0"/>
      <geometry>
        <box size="0.05 0.065 0.01"/>
      </geometry>
      <material name="orange">
     </material>
    </visual>
    <collision>
      <origin rpy="0 0 0" xyz="-0.005 0.0 0.0"/>
      <geometry>
        <box size="0.05 0.065 0.01"/>
      </geometry>
    </collision>
  </link>
  <gazebo reference="lasertop">
    <material>amigo_robot_model/orange</material>
    <turnGravityOff>false</turnGravityOff>
  </gazebo>
  <joint name="lasertop_joint" type="fixed">
    <parent link="base_laser"/>
    <child link="lasertop"/>
  </joint>
  <link name="logo">
    <inertial>
      <origin rpy="0 0 0" xyz="0.0 0.0 0.0"/>
      <mass value="0.01"/>
      <inertia ixx="0.0001" ixy="0" ixz="0" iyy="0.0001" iyz="0" izz="0.0001"/>
    </inertial>
    <visual>
      <origin rpy="0 0 3.1415" xyz="0.025 0.0 -0.165"/>
      <geometry>
        <mesh filename="package://amigo_robot_model/laser/logo.dae" scale="0.004 0.004 0.004"/>
      </geometry>
      <material name="logo"/>
    </visual>
    <collision>
      <origin rpy="0 0 3.1415" xyz="0.025 0.0 -0.165"/>
      <geometry>
        <mesh filename="package://amigo_robot_model/laser/logo.dae" scale="0.004 0.004 0.004"/>
      </geometry>
    </collision>
  </link>
  <gazebo reference="logo">
    <material>amigo_robot_model/logo</material>
    <turnGravityOff>false</turnGravityOff>
  </gazebo>
  <joint name="logo_joint" type="fixed">
    <parent link="base_laser"/>
    <child link="logo"/>
  </joint>
  <!--========BUILD HEAD======-->
  <link name="head_mount">
    <inertial>
      <origin rpy="0 0 0" xyz="0.0 0.0 0.0"/>
      <mass value="0.05"/>
      <inertia ixx="0.0001" ixy="0" ixz="0" iyy="0.0001" iyz="0" izz="0.0001"/>
    </inertial>
    <visual>
      <origin rpy="0 0 0" xyz="0.0 0.0 0.0"/>
      <geometry>
        <box size="0.01 0.01  0.01 "/>
      </geometry>
      <material name="Blue">
     </material>
    </visual>
    <collision>
      <origin rpy="0 0 0" xyz="0.0 0.0 0.0"/>
      <geometry>
        <box size="0.01 0.01  0.01 "/>
      </geometry>
    </collision>
  </link>
  <gazebo reference="head_mount">
    <material>Gazebo/Blue</material>
    <turnGravityOff>false</turnGravityOff>
  </gazebo>
  <link name="neck_pan">
    <inertial>
      <origin rpy="0 0 0" xyz="0.0 0.0 0.0335"/>
      <mass value="0.05"/>
      <inertia ixx="0.0001" ixy="0" ixz="0" iyy="0.0001" iyz="0" izz="0.0001"/>
    </inertial>
    <visual>
      <origin rpy="0 0 0" xyz="0.0 0.0 0.0335"/>
      <geometry>
        <cylinder length="0.0525" radius="0.015"/>
      </geometry>
      <material name="Black">
     </material>
    </visual>
    <collision>
      <origin rpy="0 0 0" xyz="0.0 0.0 0.0335"/>
      <geometry>
        <cylinder length="0.0525" radius="0.015"/>
      </geometry>
    </collision>
  </link>
  <gazebo reference="neck_pan">
    <material>Gazebo/Black</material>
    <turnGravityOff>false</turnGravityOff>
  </gazebo>
  <link name="neck_tilt">
    <inertial>
      <origin rpy="0 0 0" xyz="0.0 -0.0 0.0285"/>
      <mass value="0.05"/>
      <inertia ixx="0.001" ixy="0" ixz="0" iyy="0.001" iyz="0" izz="0.001"/>
    </inertial>
    <visual>
      <origin rpy="0 0 0" xyz="0.0 -0.0 0.015"/>
      <geometry>
        <mesh filename="package://amigo_robot_model/head/necktilttextured.dae" scale="0.01 0.01 0.01"/>
      </geometry>
      <material name="aluminum"/>
    </visual>
    <collision>
      <origin rpy="0 0 0" xyz="0.0 -0.0 0.015"/>
      <geometry>
        <mesh filename="package://amigo_robot_model/head/necktilttextured.dae" scale="0.01 0.01 0.01"/>
      </geometry>
    </collision>
  </link>
  <gazebo reference="neck_tilt">
    <material>amigo_robot_model/aluminum</material>
    <turnGravityOff>false</turnGravityOff>
  </gazebo>
  <link name="head">
    <inertial>
      <origin rpy="0 0 0" xyz="0 0 0"/>
      <mass value="0"/>
      <inertia ixx="0" ixy="0" ixz="0" iyy="0" iyz="0" izz="0"/>
    </inertial>
    <visual>
      <origin rpy="0 0 -1.5708" xyz="0.0 0.0 0.1"/>
      <geometry>
        <mesh filename="package://amigo_robot_model/head/headtextured.dae" scale="0.001 0.001 0.001"/>
      </geometry>
      <material name="white"/>
    </visual>
    <collision>
      <origin rpy="0 0 -1.5708" xyz="0.0 0.0 0.1"/>
      <geometry>
        <mesh filename="package://amigo_robot_model/head/headtextured.dae" scale="0.001 0.001 0.001"/>
      </geometry>
    </collision>
  </link>
  <gazebo reference="head">
    <material>amigo_robot_model/white</material>
    <turnGravityOff>false</turnGravityOff>
  </gazebo>
  <joint name="head_mount_joint" type="fixed">
    <parent link="torso"/>
    <child link="head_mount"/>
    <axis xyz="0 0 1"/>
    <origin rpy="  0.0 0.0 0.0" xyz="0.097 0.0 0.0"/>
  </joint>
  <joint name="head_joint" type="fixed">
    <parent link="neck_tilt"/>
    <child link="head"/>
  </joint>
  <joint name="neck_pan_joint" type="revolute">
    <parent link="head_mount"/>
    <child link="neck_pan"/>
    <origin rpy="3.14 -1.5708 0.0" xyz="0.0 0.0 0.0"/>
    <axis xyz="0 0 1"/>
    <dynamics damping="0.1" friction="0"/>
    <limit effort="13.4" lower="-1.5708" upper="1.5708" velocity="1.0"/>
  </joint>
  <joint name="neck_tilt_joint" type="revolute">
    <parent link="neck_pan"/>
    <child link="neck_tilt"/>
    <origin rpy="0.0 0.0 0.0" xyz="0.0 0.0 0.0445"/>
    <axis xyz="0 1 0"/>
    <dynamics damping="0.1" friction="0.0"/>
    <limit effort="13.4" lower="-2.0" upper="2.0" velocity="1.0"/>
  </joint>
  <!--========BUILD KINECT======-->
  <joint name="base_kinect_joint" type="fixed">
    <origin rpy="0 0 0" xyz="0.025 0 0.05"/>
    <!-- THESE VALUES ARE ROUGH ESTIMATES!! -->
    <parent link="head"/>
    <child link="openni_camera"/>
  </joint>
  <link name="openni_camera">
    <inertial>
      <mass value="0.01"/>
      <origin xyz="0 0 0"/>
      <inertia ixx="0.001" ixy="0.0" ixz="0.0" iyy="0.001" iyz="0.0" izz="0.001"/>
    </inertial>
    <visual>
      <origin rpy="0 0 0" xyz=" 0 0 0 "/>
      <geometry>
        <box size="0 0 0"/>
        <!--mesh filename="package://amigo_robot_model/kinect/meshes/kinect.dae" scale="0.001 0.001 0.001"/-->
        <!--<mesh filename="package://amigo_robot_model/kinect/meshes/kinect_without_base.dae"/>-->
      </geometry>
    </visual>
    <!--<collision>
      <origin xyz="-0.0365 0.0 0.0" rpy="0 0 0" />
      <geometry>
        <box size="0.0730 .2760 0.0720"/>
      </geometry>
    </collision>-->
  </link>
  <joint name="kinect_depth_joint" type="fixed">
    <origin rpy="0 0 0" xyz="0 0.018 0"/>
    <parent link="openni_camera"/>
    <child link="openni_depth_frame"/>
  </joint>
  <link name="openni_depth_frame">
    <inertial>
      <mass value="0.01"/>
      <origin xyz="0 0 0"/>
      <inertia ixx="0.001" ixy="0.0" ixz="0.0" iyy="0.001" iyz="0.0" izz="0.001"/>
    </inertial>
  </link>
  <joint name="kinect_depth_optical_joint" type="fixed">
    <origin rpy="-1.570795 0 -1.570795" xyz="0 0 0"/>
    <parent link="openni_depth_frame"/>
    <child link="openni_depth_optical_frame"/>
  </joint>
  <link name="openni_depth_optical_frame">
    <inertial>
      <mass value="0.001"/>
      <origin xyz="0 0 0"/>
      <inertia ixx="0.0001" ixy="0.0" ixz="0.0" iyy="0.0001" iyz="0.0" izz="0.0001"/>
    </inertial>
  </link>
  <joint name="kinect_rgb_joint" type="fixed">
    <origin rpy="0 0 0" xyz="0 -0.005 0"/>
    <parent link="openni_camera"/>
    <child link="openni_rgb_frame"/>
  </joint>
  <link name="openni_rgb_frame">
    <inertial>
      <mass value="0.001"/>
      <origin xyz="0 0 0"/>
      <inertia ixx="0.0001" ixy="0.0" ixz="0.0" iyy="0.0001" iyz="0.0" izz="0.0001"/>
    </inertial>
  </link>
  <joint name="kinect_rgb_optical_joint" type="fixed">
    <origin rpy="-1.570795 0 -1.570795" xyz="0 0 0"/>
    <parent link="openni_rgb_frame"/>
    <child link="openni_rgb_optical_frame"/>
  </joint>
  <link name="openni_rgb_optical_frame">
    <inertial>
      <mass value="0.001"/>
      <origin xyz="0 0 0"/>
      <inertia ixx="0.0001" ixy="0.0" ixz="0.0" iyy="0.0001" iyz="0.0" izz="0.0001"/>
    </inertial>
  </link>
  <!--========BUILD ARMS======-->
  <link name="shoulder_mount_right">
    <inertial>
      <origin rpy="0 0 0" xyz="0.0 0.0 0.0"/>
      <mass value="0.1"/>
      <inertia ixx="0.01" ixy="0" ixz="0" iyy="0.01" iyz="0" izz="0.01"/>
    </inertial>
    <visual>
      <origin rpy="0 0 0 " xyz="0.0 0.0 0.0"/>
      <geometry>
        <cylinder length="0.11" radius="0.05"/>
      </geometry>
      <material name="Black">
     </material>
    </visual>
    <collision>
      <origin rpy="0 0 0 " xyz="0.0 0.0 0.0"/>
      <geometry>
        <cylinder length="0.11" radius="0.05"/>
      </geometry>
    </collision>
  </link>
  <gazebo reference="shoulder_mount_right">
    <material>Gazebo/Black</material>
    <turnGravityOff>false</turnGravityOff>
  </gazebo>
  <link name="shoulder_link1_right">
    <inertial>
      <origin rpy="0 0 0" xyz="0.0 0.0 0.0"/>
      <mass value="0.1"/>
      <inertia ixx="0.01" ixy="0" ixz="0" iyy="0.01" iyz="0" izz="0.01"/>
    </inertial>
    <visual>
      <origin rpy="0 0 0 " xyz="0.0 0.0 0.0525"/>
      <geometry>
        <cylinder length="0.015" radius="0.045"/>
      </geometry>
      <material name="Black">
     </material>
    </visual>
    <collision>
      <origin rpy="0 0 0 " xyz="0.0 0.0 0.0525"/>
      <geometry>
        <cylinder length="0.015" radius="0.045"/>
      </geometry>
    </collision>
  </link>
  <gazebo reference="shoulder_link1_right">
    <material>Gazebo/Black</material>
    <turnGravityOff>false</turnGravityOff>
  </gazebo>
  <link name="shoulder_link2_right">
    <inertial>
      <origin rpy="0 0 0" xyz="0.0 0.0 0.0"/>
      <mass value="0.1"/>
      <inertia ixx="0.001" ixy="0" ixz="0" iyy="0.001" iyz="0" izz="0.001"/>
    </inertial>
    <visual>
      <origin rpy="0 0 0" xyz="0.0 -0.06 -0.05"/>
      <geometry>
        <box size="0.035 0.01 0.1"/>
      </geometry>
      <material name="Black">
     </material>
    </visual>
    <collision>
      <origin rpy="0 0 0" xyz="0.0 -0.06 -0.05"/>
      <geometry>
        <box size="0.035 0.01 0.1"/>
      </geometry>
    </collision>
  </link>
  <gazebo reference="shoulder_link2_right">
    <material>Gazebo/Black</material>
    <turnGravityOff>false</turnGravityOff>
  </gazebo>
  <link name="upper_arm_right">
    <inertial>
      <origin rpy="0 0 0" xyz="0.0 -0.2 0.0"/>
      <mass value="2.9"/>
      <inertia ixx="0.027" ixy="0" ixz="0" iyy="0.027" iyz="0" izz="0.004"/>
    </inertial>
    <visual>
      <origin rpy="0 0 3.1415" xyz="-0.00959 -0.19131 -0.00001"/>
      <geometry>
        <mesh filename="package://amigo_robot_model/arms_DH/upperarmtextured.dae" scale="0.001 0.001 0.001"/>
      </geometry>
      <material name="white"/>
    </visual>
    <collision>
      <origin rpy="0 0 3.1415" xyz="-0.00959 -0.19131 -0.00001"/>
      <geometry>
        <mesh filename="package://amigo_robot_model/arms_DH/upperarmtextured.dae" scale="0.001 0.001 0.001"/>
      </geometry>
    </collision>
  </link>
  <gazebo reference="upper_arm_right">
    <material>amigo_robot_model/white</material>
    <turnGravityOff>false</turnGravityOff>
  </gazebo>
  <link name="elbow_link4_right">
    <inertial>
      <origin rpy="0 0 0" xyz="0.0 0.0 0.0"/>
      <mass value="0.1"/>
      <inertia ixx="0.001" ixy="0" ixz="0" iyy="0.001" iyz="0" izz="0.001"/>
    </inertial>
    <visual>
      <origin rpy="0 0 0" xyz="0.0 0.0 0.0"/>
      <geometry>
        <cylinder length="0.0" radius="0.0"/>
      </geometry>
      <material name="Grey">
     </material>
    </visual>
    <collision>
      <origin rpy="0 0 0" xyz="0.0 0.0 0.0"/>
      <geometry>
        <cylinder length="0.0" radius="0.0"/>
      </geometry>
    </collision>
  </link>
  <gazebo reference="elbow_link4_right">
    <material>Gazebo/Grey</material>
    <turnGravityOff>false</turnGravityOff>
  </gazebo>
  <link name="fore_arm_right">
    <inertial>
      <origin rpy="0.0 0 0" xyz="0.0 -0.14 0.0"/>
      <mass value="0.1"/>
      <inertia ixx="0.0054" ixy="0" ixz="0" iyy="0.0054" iyz="0" izz="0.0004"/>
    </inertial>
    <visual>
      <origin rpy="0 -1.5708 0" xyz="0.00425 -0.14868 0.00547"/>
      <geometry>
        <mesh filename="package://amigo_robot_model/arms_DH/forearmtextured.dae" scale="0.001 0.001 0.001"/>
      </geometry>
      <material name="white"/>
    </visual>
    <collision>
      <origin rpy="0 -1.5708 0" xyz="0.00425 -0.14868 0.00547"/>
      <geometry>
        <mesh filename="package://amigo_robot_model/arms_DH/forearmtextured.dae" scale="0.001 0.001 0.001"/>
      </geometry>
    </collision>
  </link>
  <gazebo reference="fore_arm_right">
    <material>amigo_robot_model/white</material>
    <turnGravityOff>false</turnGravityOff>
  </gazebo>
  <link name="wrist_link6_right">
    <inertial>
      <origin rpy="0 0 0" xyz="0.0 0.0 0.0"/>
      <mass value="0.01"/>
      <inertia ixx="0.001" ixy="0" ixz="0" iyy="0.001" iyz="0" izz="0.001"/>
    </inertial>
    <visual>
      <origin rpy="1.5708 0 0" xyz="0.0 0.0 0.0"/>
      <geometry>
        <cylinder length="0.0" radius="0.0"/>
      </geometry>
      <material name="Black">
     </material>
    </visual>
    <collision>
      <origin rpy="1.5708 0 0" xyz="0.0 0.0 0.0"/>
      <geometry>
        <cylinder length="0.0" radius="0.0"/>
      </geometry>
    </collision>
  </link>
  <gazebo reference="wrist_link6_right">
    <material>Gazebo/Black</material>
    <turnGravityOff>false</turnGravityOff>
  </gazebo>
  <link name="hand_right">
    <inertial>
      <origin rpy="0 0 0" xyz="0.048 0.0 0.0"/>
      <mass value="0.2"/>
      <inertia ixx="0.01" ixy="0" ixz="0" iyy="0.01" iyz="0" izz="0.01"/>
    </inertial>
    <visual>
      <origin rpy="0 0 0" xyz="0.048 0.0 0.0"/>
      <geometry>
        <box size="0.080 0.085 0.038"/>
      </geometry>
      <material name="Grey">
     </material>
    </visual>
    <collision>
      <origin rpy="0 0 0" xyz="0.048 0.0 0.0"/>
      <geometry>
        <box size="0.080 0.085 0.038"/>
      </geometry>
    </collision>
  </link>
  <gazebo reference="hand_right">
    <material>Gazebo/Grey</material>
    <turnGravityOff>false</turnGravityOff>
  </gazebo>
  <link name="finger1_right">
    <inertial>
      <origin rpy="0 0 0" xyz="0.0 0.0 -0.055"/>
      <mass value="0.05"/>
      <inertia ixx="0.00037" ixy="0" ixz="0" iyy="0.00052" iyz="0" izz="0.00052"/>
    </inertial>
    <visual>
      <origin rpy="0 0 0" xyz="0.0 0.0 -0.055"/>
      <geometry>
        <box size="0.02 0.022 0.11"/>
      </geometry>
      <material name="Black">
     </material>
    </visual>
    <collision>
      <origin rpy="0 0 0" xyz="0.0 0.0 -0.055"/>
      <geometry>
        <box size="0.02 0.022 0.11"/>
      </geometry>
    </collision>
  </link>
  <gazebo reference="finger1_right">
    <material>Gazebo/Black</material>
    <turnGravityOff>false</turnGravityOff>
  </gazebo>
  <link name="finger2_right">
    <inertial>
      <origin rpy="0 0 0" xyz="0.0 0.0 -0.055"/>
      <mass value="0.05"/>
      <inertia ixx="0.00037" ixy="0" ixz="0" iyy="0.00052" iyz="0" izz="0.00052"/>
    </inertial>
    <visual>
      <origin rpy="0 0 0" xyz="0.0 0.0 -0.055"/>
      <geometry>
        <box size="0.02 0.022 0.11"/>
      </geometry>
      <material name="Black">
     </material>
    </visual>
    <collision>
      <origin rpy="0 0 0" xyz="0.0 0.0 -0.055"/>
      <geometry>
        <box size="0.02 0.022 0.11"/>
      </geometry>
    </collision>
  </link>
  <gazebo reference="finger2_right">
    <material>Gazebo/Black</material>
    <turnGravityOff>false</turnGravityOff>
  </gazebo>
  <link name="grippoint_right">
    <inertial>
      <origin rpy="0 0 0" xyz="-0.1 0.0 0.0"/>
      <mass value="0.01"/>
      <inertia ixx="0.0001" ixy="0" ixz="0" iyy="0.0001" iyz="0" izz="0.0001"/>
    </inertial>
    <visual>
      <origin rpy="0 0 0 " xyz="-0.1 0.0 0.0"/>
      <geometry>
        <box size="0.0 0.0 0.0"/>
      </geometry>
      <material name="Blue">
     </material>
    </visual>
    <collision>
      <origin rpy="0 0 0 " xyz="-0.1 0.0 0.0"/>
      <geometry>
        <box size="0.0 0.0 0.0"/>
      </geometry>
    </collision>
  </link>
  <gazebo reference="grippoint_right">
    <material>Gazebo/Blue</material>
    <turnGravityOff>false</turnGravityOff>
  </gazebo>
  <joint name="shoulder_mount_joint_right" type="fixed">
    <parent link="torso"/>
    <child link="shoulder_mount_right"/>
    <origin rpy="0 0 0.0" xyz="0.05 0.22 0.0"/>
  </joint>
  <joint name="shoulder_yaw_joint_right" type="revolute">
    <parent link="shoulder_mount_right"/>
    <child link="shoulder_link1_right"/>
    <origin rpy="-1.5708 -1.5708 0" xyz="0 0 0"/>
    <axis xyz="+1 0 0"/>
    <dynamics damping="6.0" friction="4.87"/>
    <limit effort="13.4" lower="-1.58" upper="0.01" velocity="1.0"/>
  </joint>
  <joint name="shoulder_pitch_joint_right" type="revolute">
    <parent link="shoulder_link1_right"/>
    <child link="shoulder_link2_right"/>
    <origin rpy="-1.5708  0 0" xyz="0.0 0.0 0.0"/>
    <axis xyz="0 -1 0"/>
    <dynamics damping="6.0" friction="6.06"/>
    <limit effort="13.4" lower="-1.58" upper="1.58" velocity="1.0"/>
  </joint>
  <joint name="shoulder_roll_joint_right" type="revolute">
    <parent link="shoulder_link2_right"/>
    <child link="upper_arm_right"/>
    <origin rpy="1.5708 0 0.0" xyz="0.0 0.0 0.0"/>
    <axis xyz="0 1.0 0"/>
    <dynamics damping="6.0" friction="2.16"/>
    <limit effort="9.8" lower="-1.58" upper="1.58" velocity="1.0"/>
  </joint>
  <joint name="elbow_pitch_joint_right" type="revolute">
    <parent link="upper_arm_right"/>
    <child link="elbow_link4_right"/>
    <origin rpy="-1.5708 0 0" xyz="0.01 -0.32 0.0"/>
    <axis xyz="0 -1 0"/>
    <dynamics damping="2.5" friction="1.18"/>
    <limit effort="4.5" lower="-0.01" upper="2.24" velocity="1.0"/>
  </joint>
  <joint name="elbow_roll_joint_right" type="revolute">
    <parent link="elbow_link4_right"/>
    <child link="fore_arm_right"/>
    <origin rpy="1.5708 0 0" xyz="0.0 0.0 0.0"/>
    <axis xyz="0 1.0 0"/>
    <dynamics damping="2.5" friction="1.35"/>
    <limit effort="4.5" lower="-1.84" upper="1.84" velocity="1.0"/>
  </joint>
  <joint name="wrist_pitch_joint_right" type="revolute">
    <parent link="fore_arm_right"/>
    <child link="wrist_link6_right"/>
    <origin rpy="-1.5708 0 -1.5708" xyz="0.01 -0.28 0.0"/>
    <axis xyz="0 -1 0"/>
    <dynamics damping="0.5" friction="0.63"/>
    <limit effort="1" lower="-0.96" upper="0.96" velocity="1.0"/>
  </joint>
  <joint name="wrist_yaw_joint_right" type="revolute">
    <parent link="wrist_link6_right"/>
    <child link="hand_right"/>
    <origin rpy="0 0 0" xyz="0.0 0.0 0.0"/>
    <axis xyz="0 0 1.01"/>
    <dynamics damping="0.5" friction="0.68"/>
    <limit effort="1" lower="-0.8" upper="0.8" velocity="1.0"/>
  </joint>
  <joint name="finger1_joint_right" type="revolute">
    <parent link="hand_right"/>
    <child link="finger1_right"/>
    <origin rpy="0 -1.57 0" xyz=" 0.075 0.04 0"/>
    <axis xyz="1 0 0"/>
    <dynamics damping="0.1" friction="0.63"/>
    <limit effort="3" lower="-0.7854" upper="0.7854" velocity="1.0"/>
  </joint>
  <joint name="finger2_joint_right" type="revolute">
    <parent link="hand_right"/>
    <child link="finger2_right"/>
    <origin rpy="0 -1.57 0" xyz="0.075 -0.04 0"/>
    <axis xyz="1 0 0"/>
    <dynamics damping="0.1" friction="0.0"/>
    <limit effort="3" lower="-0.7854" upper="0.7854" velocity="1.0"/>
  </joint>
  <joint name="grippoint_joint_right" type="fixed">
    <parent link="hand_right"/>
    <child link="grippoint_right"/>
    <origin rpy="0 0 0" xyz="0.14 0.0 0.0"/>
  </joint>
  <link name="shoulder_mount_left">
    <inertial>
      <origin rpy="0 0 0" xyz="0.0 0.0 0.0"/>
      <mass value="0.1"/>
      <inertia ixx="0.01" ixy="0" ixz="0" iyy="0.01" iyz="0" izz="0.01"/>
    </inertial>
    <visual>
      <origin rpy="0 0 0 " xyz="0.0 0.0 0.0"/>
      <geometry>
        <cylinder length="0.11" radius="0.05"/>
      </geometry>
      <material name="Black">
     </material>
    </visual>
    <collision>
      <origin rpy="0 0 0 " xyz="0.0 0.0 0.0"/>
      <geometry>
        <cylinder length="0.11" radius="0.05"/>
      </geometry>
    </collision>
  </link>
  <gazebo reference="shoulder_mount_left">
    <material>Gazebo/Black</material>
    <turnGravityOff>false</turnGravityOff>
  </gazebo>
  <link name="shoulder_link1_left">
    <inertial>
      <origin rpy="0 0 0" xyz="0.0 0.0 0.0"/>
      <mass value="0.1"/>
      <inertia ixx="0.01" ixy="0" ixz="0" iyy="0.01" iyz="0" izz="0.01"/>
    </inertial>
    <visual>
      <origin rpy="0 0 0 " xyz="0.0 0.0 -0.0525"/>
      <geometry>
        <cylinder length="0.015" radius="0.045"/>
      </geometry>
      <material name="Black">
     </material>
    </visual>
    <collision>
      <origin rpy="0 0 0 " xyz="0.0 0.0 -0.0525"/>
      <geometry>
        <cylinder length="0.015" radius="0.045"/>
      </geometry>
    </collision>
  </link>
  <gazebo reference="shoulder_link1_left">
    <material>Gazebo/Black</material>
    <turnGravityOff>false</turnGravityOff>
  </gazebo>
  <link name="shoulder_link2_left">
    <inertial>
      <origin rpy="0 0 0" xyz="0.0 0.0 0.0"/>
      <mass value="0.1"/>
      <inertia ixx="0.001" ixy="0" ixz="0" iyy="0.001" iyz="0" izz="0.001"/>
    </inertial>
    <visual>
      <origin rpy="0 0 0" xyz="0.0 0.06 -0.05"/>
      <geometry>
        <box size="0.035 0.01 0.1"/>
      </geometry>
      <material name="Black">
     </material>
    </visual>
    <collision>
      <origin rpy="0 0 0" xyz="0.0 0.06 -0.05"/>
      <geometry>
        <box size="0.035 0.01 0.1"/>
      </geometry>
    </collision>
  </link>
  <gazebo reference="shoulder_link2_left">
    <material>Gazebo/Black</material>
    <turnGravityOff>false</turnGravityOff>
  </gazebo>
  <link name="upper_arm_left">
    <inertial>
      <origin rpy="0 0 0" xyz="0.0 -0.2 0.0"/>
      <mass value="2.9"/>
      <inertia ixx="0.027" ixy="0" ixz="0" iyy="0.027" iyz="0" izz="0.004"/>
    </inertial>
    <visual>
      <origin rpy="0 0 3.1415" xyz="-0.00959 -0.19131 -0.00001"/>
      <geometry>
        <mesh filename="package://amigo_robot_model/arms_DH/upperarmtextured.dae" scale="0.001 0.001 0.001"/>
      </geometry>
      <material name="white"/>
    </visual>
    <collision>
      <origin rpy="0 0 3.1415" xyz="-0.00959 -0.19131 -0.00001"/>
      <geometry>
        <mesh filename="package://amigo_robot_model/arms_DH/upperarmtextured.dae" scale="0.001 0.001 0.001"/>
      </geometry>
    </collision>
  </link>
  <gazebo reference="upper_arm_left">
    <material>amigo_robot_model/white</material>
    <turnGravityOff>false</turnGravityOff>
  </gazebo>
  <link name="elbow_link4_left">
    <inertial>
      <origin rpy="0 0 0" xyz="0.0 0.0 0.0"/>
      <mass value="0.1"/>
      <inertia ixx="0.001" ixy="0" ixz="0" iyy="0.001" iyz="0" izz="0.001"/>
    </inertial>
    <visual>
      <origin rpy="0 0 0" xyz="0.0 0.0 0.0"/>
      <geometry>
        <cylinder length="0.0" radius="0.0"/>
      </geometry>
      <material name="Grey">
     </material>
    </visual>
    <collision>
      <origin rpy="0 0 0" xyz="0.0 0.0 0.0"/>
      <geometry>
        <cylinder length="0.0" radius="0.0"/>
      </geometry>
    </collision>
  </link>
  <gazebo reference="elbow_link4_left">
    <material>Gazebo/Grey</material>
    <turnGravityOff>false</turnGravityOff>
  </gazebo>
  <link name="fore_arm_left">
    <inertial>
      <origin rpy="0.0 0 0" xyz="0.0 -0.14 0.0"/>
      <mass value="0.1"/>
      <inertia ixx="0.0054" ixy="0" ixz="0" iyy="0.0054" iyz="0" izz="0.0004"/>
    </inertial>
    <visual>
      <origin rpy="0 -1.5708 0" xyz="0.00425 -0.14868 0.00547"/>
      <geometry>
        <mesh filename="package://amigo_robot_model/arms_DH/forearmtextured.dae" scale="0.001 0.001 0.001"/>
      </geometry>
      <material name="white"/>
    </visual>
    <collision>
      <origin rpy="0 -1.5708 0" xyz="0.00425 -0.14868 0.00547"/>
      <geometry>
        <mesh filename="package://amigo_robot_model/arms_DH/forearmtextured.dae" scale="0.001 0.001 0.001"/>
      </geometry>
    </collision>
  </link>
  <gazebo reference="fore_arm_left">
    <material>amigo_robot_model/white</material>
    <turnGravityOff>false</turnGravityOff>
  </gazebo>
  <link name="wrist_link6_left">
    <inertial>
      <origin rpy="0 0 0" xyz="0.0 0.0 0.0"/>
      <mass value="0.01"/>
      <inertia ixx="0.001" ixy="0" ixz="0" iyy="0.001" iyz="0" izz="0.001"/>
    </inertial>
    <visual>
      <origin rpy="1.5708 0 0" xyz="0.0 0.0 0.0"/>
      <geometry>
        <cylinder length="0.0" radius="0.0"/>
      </geometry>
      <material name="Black">
     </material>
    </visual>
    <collision>
      <origin rpy="1.5708 0 0" xyz="0.0 0.0 0.0"/>
      <geometry>
        <cylinder length="0.0" radius="0.0"/>
      </geometry>
    </collision>
  </link>
  <gazebo reference="wrist_link6_left">
    <material>Gazebo/Black</material>
    <turnGravityOff>false</turnGravityOff>
  </gazebo>
  <link name="hand_left">
    <inertial>
      <origin rpy="0 0 0" xyz="0.048 0.0 0.0"/>
      <mass value="0.2"/>
      <inertia ixx="0.01" ixy="0" ixz="0" iyy="0.01" iyz="0" izz="0.01"/>
    </inertial>
    <visual>
      <origin rpy="0 0 0" xyz="0.048 0.0 0.0"/>
      <geometry>
        <box size="0.080 0.085 0.038"/>
      </geometry>
      <material name="Grey">
     </material>
    </visual>
    <collision>
      <origin rpy="0 0 0" xyz="0.048 0.0 0.0"/>
      <geometry>
        <box size="0.080 0.085 0.038"/>
      </geometry>
    </collision>
  </link>
  <gazebo reference="hand_left">
    <material>Gazebo/Grey</material>
    <turnGravityOff>false</turnGravityOff>
  </gazebo>
  <link name="finger1_left">
    <inertial>
      <origin rpy="0 0 0" xyz="0.0 0.0 -0.055"/>
      <mass value="0.05"/>
      <inertia ixx="0.00037" ixy="0" ixz="0" iyy="0.00052" iyz="0" izz="0.00052"/>
    </inertial>
    <visual>
      <origin rpy="0 0 0" xyz="0.0 0.0 -0.055"/>
      <geometry>
        <box size="0.02 0.022 0.11"/>
      </geometry>
      <material name="Black">
     </material>
    </visual>
    <collision>
      <origin rpy="0 0 0" xyz="0.0 0.0 -0.055"/>
      <geometry>
        <box size="0.02 0.022 0.11"/>
      </geometry>
    </collision>
  </link>
  <gazebo reference="finger1_left">
    <material>Gazebo/Black</material>
    <turnGravityOff>false</turnGravityOff>
  </gazebo>
  <link name="finger2_left">
    <inertial>
      <origin rpy="0 0 0" xyz="0.0 0.0 -0.055"/>
      <mass value="0.05"/>
      <inertia ixx="0.00037" ixy="0" ixz="0" iyy="0.00052" iyz="0" izz="0.00052"/>
    </inertial>
    <visual>
      <origin rpy="0 0 0" xyz="0.0 0.0 -0.055"/>
      <geometry>
        <box size="0.02 0.022 0.11"/>
      </geometry>
      <material name="Black">
     </material>
    </visual>
    <collision>
      <origin rpy="0 0 0" xyz="0.0 0.0 -0.055"/>
      <geometry>
        <box size="0.02 0.022 0.11"/>
      </geometry>
    </collision>
  </link>
  <gazebo reference="finger2_left">
    <material>Gazebo/Black</material>
    <turnGravityOff>false</turnGravityOff>
  </gazebo>
  <link name="grippoint_left">
    <inertial>
      <origin rpy="0 0 0" xyz="-0.1 0.0 0.0"/>
      <mass value="0.01"/>
      <inertia ixx="0.0001" ixy="0" ixz="0" iyy="0.0001" iyz="0" izz="0.0001"/>
    </inertial>
    <visual>
      <origin rpy="0 0 0 " xyz="-0.1 0.0 0.0"/>
      <geometry>
        <box size="0.0 0.0 0.0"/>
      </geometry>
      <material name="Blue">
     </material>
    </visual>
    <collision>
      <origin rpy="0 0 0 " xyz="-0.1 0.0 0.0"/>
      <geometry>
        <box size="0.0 0.0 0.0"/>
      </geometry>
    </collision>
  </link>
  <gazebo reference="grippoint_left">
    <material>Gazebo/Blue</material>
    <turnGravityOff>false</turnGravityOff>
  </gazebo>
  <joint name="shoulder_mount_joint_left" type="fixed">
    <parent link="torso"/>
    <child link="shoulder_mount_left"/>
    <origin rpy="0 0 0.0" xyz="0.05 -0.22 0.0"/>
  </joint>
  <joint name="shoulder_yaw_joint_left" type="revolute">
    <parent link="shoulder_mount_left"/>
    <child link="shoulder_link1_left"/>
    <origin rpy="-1.5708 -1.5708 0" xyz="0 0 0"/>
    <axis xyz="-1 0 0"/>
    <dynamics damping="6.0" friction="4.87"/>
    <limit effort="13.4" lower="-1.58" upper="0.01" velocity="1.0"/>
  </joint>
  <joint name="shoulder_pitch_joint_left" type="revolute">
    <parent link="shoulder_link1_left"/>
    <child link="shoulder_link2_left"/>
    <origin rpy="-1.5708  0 0" xyz="0.0 0.0 0.0"/>
    <axis xyz="0 -1 0"/>
    <dynamics damping="6.0" friction="6.06"/>
    <limit effort="13.4" lower="-1.58" upper="1.58" velocity="1.0"/>
  </joint>
  <joint name="shoulder_roll_joint_left" type="revolute">
    <parent link="shoulder_link2_left"/>
    <child link="upper_arm_left"/>
    <origin rpy="1.5708 0 0.0" xyz="0.0 0.0 0.0"/>
    <axis xyz="0 -1.0 0"/>
    <dynamics damping="6.0" friction="2.16"/>
    <limit effort="9.8" lower="-1.58" upper="1.58" velocity="1.0"/>
  </joint>
  <joint name="elbow_pitch_joint_left" type="revolute">
    <parent link="upper_arm_left"/>
    <child link="elbow_link4_left"/>
    <origin rpy="-1.5708 0 0" xyz="0.01 -0.32 0.0"/>
    <axis xyz="0 -1 0"/>
    <dynamics damping="2.5" friction="1.18"/>
    <limit effort="4.5" lower="-0.01" upper="2.24" velocity="1.0"/>
  </joint>
  <joint name="elbow_roll_joint_left" type="revolute">
    <parent link="elbow_link4_left"/>
    <child link="fore_arm_left"/>
    <origin rpy="1.5708 0 0" xyz="0.0 0.0 0.0"/>
    <axis xyz="0 -1.0 0"/>
    <dynamics damping="2.5" friction="1.35"/>
    <limit effort="4.5" lower="-1.84" upper="1.84" velocity="1.0"/>
  </joint>
  <joint name="wrist_pitch_joint_left" type="revolute">
    <parent link="fore_arm_left"/>
    <child link="wrist_link6_left"/>
    <origin rpy="-1.5708 0 -1.5708" xyz="0.01 -0.28 0.0"/>
    <axis xyz="0 -1 0"/>
    <dynamics damping="0.5" friction="0.63"/>
    <limit effort="1" lower="-0.96" upper="0.96" velocity="1.0"/>
  </joint>
  <joint name="wrist_yaw_joint_left" type="revolute">
    <parent link="wrist_link6_left"/>
    <child link="hand_left"/>
    <origin rpy="0 0 0" xyz="0.0 0.0 0.0"/>
    <axis xyz="0 0 -1.01"/>
    <dynamics damping="0.5" friction="0.68"/>
    <limit effort="1" lower="-0.8" upper="0.8" velocity="1.0"/>
  </joint>
  <joint name="finger1_joint_left" type="revolute">
    <parent link="hand_left"/>
    <child link="finger1_left"/>
    <origin rpy="0 -1.57 0" xyz=" 0.075 0.04 0"/>
    <axis xyz="1 0 0"/>
    <dynamics damping="0.1" friction="0.63"/>
    <limit effort="3" lower="-0.7854" upper="0.7854" velocity="1.0"/>
  </joint>
  <joint name="finger2_joint_left" type="revolute">
    <parent link="hand_left"/>
    <child link="finger2_left"/>
    <origin rpy="0 -1.57 0" xyz="0.075 -0.04 0"/>
    <axis xyz="1 0 0"/>
    <dynamics damping="0.1" friction="0.0"/>
    <limit effort="3" lower="-0.7854" upper="0.7854" velocity="1.0"/>
  </joint>
  <joint name="grippoint_joint_left" type="fixed">
    <parent link="hand_left"/>
    <child link="grippoint_left"/>
    <origin rpy="0 0 0" xyz="0.14 0.0 0.0"/>
  </joint>
  <!--extra arm visuals-->
  <link name="upper_arm_top_right">
    <inertial>
      <origin rpy="0 0 0" xyz="0.0 0.0 0.0"/>
      <mass value="0.01"/>
      <inertia ixx="0.027" ixy="0" ixz="0" iyy="0.027" iyz="0" izz="0.004"/>
    </inertial>
    <visual>
      <origin rpy="0 0 0" xyz="0.0 0.0 0.0"/>
      <geometry>
        <cylinder length="0.02" radius="0.0561"/>
      </geometry>
      <material name="Black">
     </material>
    </visual>
    <collision>
      <origin rpy="0 0 0" xyz="0.0 0.0 0.0"/>
      <geometry>
        <cylinder length="0.02" radius="0.0561"/>
      </geometry>
    </collision>
  </link>
  <gazebo reference="upper_arm_top_right">
    <material>Gazebo/Black</material>
    <turnGravityOff>false</turnGravityOff>
  </gazebo>
  <link name="elbow_extra_block_right">
    <inertial>
      <origin rpy="0 0 0" xyz="0.0 0.0 0.0"/>
      <mass value="0.01"/>
      <inertia ixx="0.001" ixy="0" ixz="0" iyy="0.001" iyz="0" izz="0.001"/>
    </inertial>
    <visual>
      <origin rpy="0 0 0" xyz="-0.036 0.0 0.02"/>
      <geometry>
        <box size="0.015 0.08 0.06"/>
      </geometry>
      <material name="Black">
     </material>
    </visual>
    <collision>
      <origin rpy="0 0 0" xyz="-0.036 0.0 0.02"/>
      <geometry>
        <box size="0.015 0.08 0.06"/>
      </geometry>
    </collision>
  </link>
  <gazebo reference="elbow_extra_block_right">
    <material>Gazebo/Black</material>
    <turnGravityOff>false</turnGravityOff>
  </gazebo>
  <link name="elbow_extra_block2_right">
    <inertial>
      <origin rpy="0 0 0" xyz="0.0 0.0 0.0"/>
      <mass value="0.01"/>
      <inertia ixx="0.001" ixy="0" ixz="0" iyy="0.001" iyz="0" izz="0.001"/>
    </inertial>
    <visual>
      <origin rpy="1.5708 0 0" xyz="0.0 0.0 0.0"/>
      <geometry>
        <cylinder length="0.08" radius="0.03"/>
      </geometry>
      <material name="Grey">
     </material>
    </visual>
    <collision>
      <origin rpy="1.5708 0 0" xyz="0.0 0.0 0.0"/>
      <geometry>
        <cylinder length="0.08" radius="0.03"/>
      </geometry>
    </collision>
  </link>
  <gazebo reference="elbow_extra_block2_right">
    <material>Gazebo/Grey</material>
    <turnGravityOff>false</turnGravityOff>
  </gazebo>
  <link name="fore_arm_top_right">
    <inertial>
      <origin rpy="0 0 0" xyz="0.0 0.0 0.0"/>
      <mass value="0.01"/>
      <inertia ixx="0.0054" ixy="0" ixz="0" iyy="0.0054" iyz="0" izz="0.0004"/>
    </inertial>
    <visual>
      <origin rpy="0 0 0" xyz="0.0 0.0 0.01"/>
      <geometry>
        <cylinder length="0.01" radius="0.037"/>
      </geometry>
      <material name="Black">
     </material>
    </visual>
    <collision>
      <origin rpy="0 0 0" xyz="0.0 0.0 0.01"/>
      <geometry>
        <cylinder length="0.01" radius="0.037"/>
      </geometry>
    </collision>
  </link>
  <gazebo reference="fore_arm_top_right">
    <material>Gazebo/Black</material>
    <turnGravityOff>false</turnGravityOff>
  </gazebo>
  <link name="wrist_visual_right">
    <inertial>
      <origin rpy="0 0 0" xyz="0.0 0.0 0.0"/>
      <mass value="0.01"/>
      <inertia ixx="0.001" ixy="0" ixz="0" iyy="0.001" iyz="0" izz="0.001"/>
    </inertial>
    <visual>
      <origin rpy="0 0 0" xyz="0.0 0.0 0.0"/>
      <geometry>
        <cylinder length="0.06" radius="0.018"/>
      </geometry>
      <material name="Grey">
     </material>
    </visual>
    <collision>
      <origin rpy="0 0 0" xyz="0.0 0.0 0.0"/>
      <geometry>
        <cylinder length="0.06" radius="0.018"/>
      </geometry>
    </collision>
  </link>
  <gazebo reference="wrist_visual_right">
    <material>Gazebo/Grey</material>
    <turnGravityOff>false</turnGravityOff>
  </gazebo>
  <link name="wrist_to_hand_block_right">
    <inertial>
      <origin rpy="0 0 0" xyz="0.0 0.0 0.0"/>
      <mass value="0.01"/>
      <inertia ixx="0.001" ixy="0" ixz="0" iyy="0.001" iyz="0" izz="0.001"/>
    </inertial>
    <visual>
      <origin rpy="0 0 0" xyz="0.0 0.0 0.0"/>
      <geometry>
        <box size="0.03 0.02 0.038"/>
      </geometry>
      <material name="Grey">
     </material>
    </visual>
    <collision>
      <origin rpy="0 0 0" xyz="0.0 0.0 0.0"/>
      <geometry>
        <box size="0.03 0.02 0.038"/>
      </geometry>
    </collision>
  </link>
  <gazebo reference="wrist_to_hand_block_right">
    <material>Gazebo/Grey</material>
    <turnGravityOff>false</turnGravityOff>
  </gazebo>
  <joint name="upper_arm_top_joint_right" type="fixed">
    <parent link="upper_arm_right"/>
    <child link="upper_arm_top_right"/>
    <origin rpy="1.5708 0 0.0" xyz="-0.01 -0.1 0.0"/>
  </joint>
  <joint name="elbow_extra_block_joint_right" type="fixed">
    <parent link="upper_arm_right"/>
    <child link="elbow_extra_block_right"/>
    <origin rpy="-1.5708 0 0" xyz="0.0 -0.31 0.0"/>
  </joint>
  <joint name="elbow_extra_block2_joint_right" type="fixed">
    <parent link="upper_arm_right"/>
    <child link="elbow_extra_block2_right"/>
    <origin rpy="-1.5708 0 0" xyz="0.0 -0.31 0.0"/>
  </joint>
  <joint name="fore_arm_top_joint_right" type="fixed">
    <parent link="fore_arm_right"/>
    <child link="fore_arm_top_right"/>
    <origin rpy="1.5708 0 0" xyz="0.002 -0.011 0.0"/>
  </joint>
  <joint name="wrist_visual_joint_right" type="fixed">
    <parent link="wrist_link6_right"/>
    <child link="wrist_visual_right"/>
    <origin rpy="1.5708 0 0" xyz="-0.02 0.0 0.0"/>
  </joint>
  <joint name="wrist_to_hand_block_joint_right" type="fixed">
    <parent link="wrist_link6_right"/>
    <child link="wrist_to_hand_block_right"/>
    <origin rpy="0 0 0" xyz="0.0 0.0 0.0"/>
  </joint>
  <link name="upper_arm_top_left">
    <inertial>
      <origin rpy="0 0 0" xyz="0.0 0.0 0.0"/>
      <mass value="0.01"/>
      <inertia ixx="0.027" ixy="0" ixz="0" iyy="0.027" iyz="0" izz="0.004"/>
    </inertial>
    <visual>
      <origin rpy="0 0 0" xyz="0.0 0.0 0.0"/>
      <geometry>
        <cylinder length="0.02" radius="0.0561"/>
      </geometry>
      <material name="Black">
     </material>
    </visual>
    <collision>
      <origin rpy="0 0 0" xyz="0.0 0.0 0.0"/>
      <geometry>
        <cylinder length="0.02" radius="0.0561"/>
      </geometry>
    </collision>
  </link>
  <gazebo reference="upper_arm_top_left">
    <material>Gazebo/Black</material>
    <turnGravityOff>false</turnGravityOff>
  </gazebo>
  <link name="elbow_extra_block_left">
    <inertial>
      <origin rpy="0 0 0" xyz="0.0 0.0 0.0"/>
      <mass value="0.01"/>
      <inertia ixx="0.001" ixy="0" ixz="0" iyy="0.001" iyz="0" izz="0.001"/>
    </inertial>
    <visual>
      <origin rpy="0 0 0" xyz="-0.036 0.0 0.02"/>
      <geometry>
        <box size="0.015 0.08 0.06"/>
      </geometry>
      <material name="Black">
     </material>
    </visual>
    <collision>
      <origin rpy="0 0 0" xyz="-0.036 0.0 0.02"/>
      <geometry>
        <box size="0.015 0.08 0.06"/>
      </geometry>
    </collision>
  </link>
  <gazebo reference="elbow_extra_block_left">
    <material>Gazebo/Black</material>
    <turnGravityOff>false</turnGravityOff>
  </gazebo>
  <link name="elbow_extra_block2_left">
    <inertial>
      <origin rpy="0 0 0" xyz="0.0 0.0 0.0"/>
      <mass value="0.01"/>
      <inertia ixx="0.001" ixy="0" ixz="0" iyy="0.001" iyz="0" izz="0.001"/>
    </inertial>
    <visual>
      <origin rpy="1.5708 0 0" xyz="0.0 0.0 0.0"/>
      <geometry>
        <cylinder length="0.08" radius="0.03"/>
      </geometry>
      <material name="Grey">
     </material>
    </visual>
    <collision>
      <origin rpy="1.5708 0 0" xyz="0.0 0.0 0.0"/>
      <geometry>
        <cylinder length="0.08" radius="0.03"/>
      </geometry>
    </collision>
  </link>
  <gazebo reference="elbow_extra_block2_left">
    <material>Gazebo/Grey</material>
    <turnGravityOff>false</turnGravityOff>
  </gazebo>
  <link name="fore_arm_top_left">
    <inertial>
      <origin rpy="0 0 0" xyz="0.0 0.0 0.0"/>
      <mass value="0.01"/>
      <inertia ixx="0.0054" ixy="0" ixz="0" iyy="0.0054" iyz="0" izz="0.0004"/>
    </inertial>
    <visual>
      <origin rpy="0 0 0" xyz="0.0 0.0 0.01"/>
      <geometry>
        <cylinder length="0.01" radius="0.037"/>
      </geometry>
      <material name="Black">
     </material>
    </visual>
    <collision>
      <origin rpy="0 0 0" xyz="0.0 0.0 0.01"/>
      <geometry>
        <cylinder length="0.01" radius="0.037"/>
      </geometry>
    </collision>
  </link>
  <gazebo reference="fore_arm_top_left">
    <material>Gazebo/Black</material>
    <turnGravityOff>false</turnGravityOff>
  </gazebo>
  <link name="wrist_visual_left">
    <inertial>
      <origin rpy="0 0 0" xyz="0.0 0.0 0.0"/>
      <mass value="0.01"/>
      <inertia ixx="0.001" ixy="0" ixz="0" iyy="0.001" iyz="0" izz="0.001"/>
    </inertial>
    <visual>
      <origin rpy="0 0 0" xyz="0.0 0.0 0.0"/>
      <geometry>
        <cylinder length="0.06" radius="0.018"/>
      </geometry>
      <material name="Grey">
     </material>
    </visual>
    <collision>
      <origin rpy="0 0 0" xyz="0.0 0.0 0.0"/>
      <geometry>
        <cylinder length="0.06" radius="0.018"/>
      </geometry>
    </collision>
  </link>
  <gazebo reference="wrist_visual_left">
    <material>Gazebo/Grey</material>
    <turnGravityOff>false</turnGravityOff>
  </gazebo>
  <link name="wrist_to_hand_block_left">
    <inertial>
      <origin rpy="0 0 0" xyz="0.0 0.0 0.0"/>
      <mass value="0.01"/>
      <inertia ixx="0.001" ixy="0" ixz="0" iyy="0.001" iyz="0" izz="0.001"/>
    </inertial>
    <visual>
      <origin rpy="0 0 0" xyz="0.0 0.0 0.0"/>
      <geometry>
        <box size="0.03 0.02 0.038"/>
      </geometry>
      <material name="Grey">
     </material>
    </visual>
    <collision>
      <origin rpy="0 0 0" xyz="0.0 0.0 0.0"/>
      <geometry>
        <box size="0.03 0.02 0.038"/>
      </geometry>
    </collision>
  </link>
  <gazebo reference="wrist_to_hand_block_left">
    <material>Gazebo/Grey</material>
    <turnGravityOff>false</turnGravityOff>
  </gazebo>
  <joint name="upper_arm_top_joint_left" type="fixed">
    <parent link="upper_arm_left"/>
    <child link="upper_arm_top_left"/>
    <origin rpy="1.5708 0 0.0" xyz="-0.01 -0.1 0.0"/>
  </joint>
  <joint name="elbow_extra_block_joint_left" type="fixed">
    <parent link="upper_arm_left"/>
    <child link="elbow_extra_block_left"/>
    <origin rpy="-1.5708 0 0" xyz="0.0 -0.31 0.0"/>
  </joint>
  <joint name="elbow_extra_block2_joint_left" type="fixed">
    <parent link="upper_arm_left"/>
    <child link="elbow_extra_block2_left"/>
    <origin rpy="-1.5708 0 0" xyz="0.0 -0.31 0.0"/>
  </joint>
  <joint name="fore_arm_top_joint_left" type="fixed">
    <parent link="fore_arm_left"/>
    <child link="fore_arm_top_left"/>
    <origin rpy="1.5708 0 0" xyz="0.002 -0.011 0.0"/>
  </joint>
  <joint name="wrist_visual_joint_left" type="fixed">
    <parent link="wrist_link6_left"/>
    <child link="wrist_visual_left"/>
    <origin rpy="1.5708 0 0" xyz="-0.02 0.0 0.0"/>
  </joint>
  <joint name="wrist_to_hand_block_joint_left" type="fixed">
    <parent link="wrist_link6_left"/>
    <child link="wrist_to_hand_block_left"/>
    <origin rpy="0 0 0" xyz="0.0 0.0 0.0"/>
  </joint>
  <!--====BUILD STUFF THAT NEEDS TO RUN IN EITHER SIMULATION OR ON THE REAL ROBOT ====-->
  <joint name="omni_sphere1_joint_left_front" type="continuous">
    <parent link="wheel_left_front"/>
    <child link="omni_sphere1_left_front"/>
    <axis xyz="0 1 0"/>
    <origin rpy="0.0 0 0" xyz="0.0 0.03 0.0"/>
    <dynamics damping="0.01" friction="0.0"/>
    <limit effort="0.5" velocity="0.05"/>
  </joint>
  <link name="omni_sphere1_left_front">
    <inertial>
      <origin rpy="0 0 0" xyz="0.0 0.0 0.0"/>
      <mass value="0.05"/>
      <inertia ixx="0.000018" ixy="0" ixz="0" iyy="0.000018" iyz="0" izz="0.000018"/>
    </inertial>
    <visual>
      <origin rpy="0 0 0" xyz="0.0 0.0 0.0"/>
      <geometry>
        <sphere radius="0.03"/>
      </geometry>
      <material name="Grey">
     </material>
    </visual>
    <collision>
      <origin rpy="0 0 0" xyz="0.0 0.0 0.0"/>
      <geometry>
        <sphere radius="0.03"/>
      </geometry>
    </collision>
  </link>
  <gazebo reference="omni_sphere1_left_front">
    <material>Gazebo/Grey</material>
    <turnGravityOff>false</turnGravityOff>
  </gazebo>
  <joint name="omni_sphere1_joint_right_front" type="continuous">
    <parent link="wheel_right_front"/>
    <child link="omni_sphere1_right_front"/>
    <axis xyz="0 1 0"/>
    <origin rpy="0.0 0 0" xyz="0.0 0.03 0.0"/>
    <dynamics damping="0.01" friction="0.0"/>
    <limit effort="0.5" velocity="0.05"/>
  </joint>
  <link name="omni_sphere1_right_front">
    <inertial>
      <origin rpy="0 0 0" xyz="0.0 0.0 0.0"/>
      <mass value="0.05"/>
      <inertia ixx="0.000018" ixy="0" ixz="0" iyy="0.000018" iyz="0" izz="0.000018"/>
    </inertial>
    <visual>
      <origin rpy="0 0 0" xyz="0.0 0.0 0.0"/>
      <geometry>
        <sphere radius="0.03"/>
      </geometry>
      <material name="Grey">
     </material>
    </visual>
    <collision>
      <origin rpy="0 0 0" xyz="0.0 0.0 0.0"/>
      <geometry>
        <sphere radius="0.03"/>
      </geometry>
    </collision>
  </link>
  <gazebo reference="omni_sphere1_right_front">
    <material>Gazebo/Grey</material>
    <turnGravityOff>false</turnGravityOff>
  </gazebo>
  <joint name="omni_sphere1_joint_left_rear" type="continuous">
    <parent link="wheel_left_rear"/>
    <child link="omni_sphere1_left_rear"/>
    <axis xyz="0 1 0"/>
    <origin rpy="0.0 0 0" xyz="0.0 0.03 0.0"/>
    <dynamics damping="0.01" friction="0.0"/>
    <limit effort="0.5" velocity="0.05"/>
  </joint>
  <link name="omni_sphere1_left_rear">
    <inertial>
      <origin rpy="0 0 0" xyz="0.0 0.0 0.0"/>
      <mass value="0.05"/>
      <inertia ixx="0.000018" ixy="0" ixz="0" iyy="0.000018" iyz="0" izz="0.000018"/>
    </inertial>
    <visual>
      <origin rpy="0 0 0" xyz="0.0 0.0 0.0"/>
      <geometry>
        <sphere radius="0.03"/>
      </geometry>
      <material name="Grey">
     </material>
    </visual>
    <collision>
      <origin rpy="0 0 0" xyz="0.0 0.0 0.0"/>
      <geometry>
        <sphere radius="0.03"/>
      </geometry>
    </collision>
  </link>
  <gazebo reference="omni_sphere1_left_rear">
    <material>Gazebo/Grey</material>
    <turnGravityOff>false</turnGravityOff>
  </gazebo>
  <joint name="omni_sphere1_joint_right_rear" type="continuous">
    <parent link="wheel_right_rear"/>
    <child link="omni_sphere1_right_rear"/>
    <axis xyz="0 1 0"/>
    <origin rpy="0.0 0 0" xyz="0.0 0.03 0.0"/>
    <dynamics damping="0.01" friction="0.0"/>
    <limit effort="0.5" velocity="0.05"/>
  </joint>
  <link name="omni_sphere1_right_rear">
    <inertial>
      <origin rpy="0 0 0" xyz="0.0 0.0 0.0"/>
      <mass value="0.05"/>
      <inertia ixx="0.000018" ixy="0" ixz="0" iyy="0.000018" iyz="0" izz="0.000018"/>
    </inertial>
    <visual>
      <origin rpy="0 0 0" xyz="0.0 0.0 0.0"/>
      <geometry>
        <sphere radius="0.03"/>
      </geometry>
      <material name="Grey">
     </material>
    </visual>
    <collision>
      <origin rpy="0 0 0" xyz="0.0 0.0 0.0"/>
      <geometry>
        <sphere radius="0.03"/>
      </geometry>
    </collision>
  </link>
  <gazebo reference="omni_sphere1_right_rear">
    <material>Gazebo/Grey</material>
    <turnGravityOff>false</turnGravityOff>
  </gazebo>
  <joint name="omni_sphere2_joint_left_front" type="continuous">
    <parent link="wheel_left_front"/>
    <child link="omni_sphere2_left_front"/>
    <axis xyz="0 1 0"/>
    <origin rpy="0.5236 0 0" xyz="0.0 0.026 0.015"/>
    <dynamics damping="0.01" friction="0.0"/>
    <limit effort="0.5" velocity="0.05"/>
  </joint>
  <link name="omni_sphere2_left_front">
    <inertial>
      <origin rpy="0 0 0" xyz="0.0 0.0 0.0"/>
      <mass value="0.05"/>
      <inertia ixx="0.000018" ixy="0" ixz="0" iyy="0.000018" iyz="0" izz="0.000018"/>
    </inertial>
    <visual>
      <origin rpy="0 0 0" xyz="0.0 0.0 0.0"/>
      <geometry>
        <sphere radius="0.03"/>
      </geometry>
      <material name="Grey">
     </material>
    </visual>
    <collision>
      <origin rpy="0 0 0" xyz="0.0 0.0 0.0"/>
      <geometry>
        <sphere radius="0.03"/>
      </geometry>
    </collision>
  </link>
  <gazebo reference="omni_sphere2_left_front">
    <material>Gazebo/Grey</material>
    <turnGravityOff>false</turnGravityOff>
  </gazebo>
  <joint name="omni_sphere2_joint_right_front" type="continuous">
    <parent link="wheel_right_front"/>
    <child link="omni_sphere2_right_front"/>
    <axis xyz="0 1 0"/>
    <origin rpy="0.5236 0 0" xyz="0.0 0.026 0.015"/>
    <dynamics damping="0.01" friction="0.0"/>
    <limit effort="0.5" velocity="0.05"/>
  </joint>
  <link name="omni_sphere2_right_front">
    <inertial>
      <origin rpy="0 0 0" xyz="0.0 0.0 0.0"/>
      <mass value="0.05"/>
      <inertia ixx="0.000018" ixy="0" ixz="0" iyy="0.000018" iyz="0" izz="0.000018"/>
    </inertial>
    <visual>
      <origin rpy="0 0 0" xyz="0.0 0.0 0.0"/>
      <geometry>
        <sphere radius="0.03"/>
      </geometry>
      <material name="Grey">
     </material>
    </visual>
    <collision>
      <origin rpy="0 0 0" xyz="0.0 0.0 0.0"/>
      <geometry>
        <sphere radius="0.03"/>
      </geometry>
    </collision>
  </link>
  <gazebo reference="omni_sphere2_right_front">
    <material>Gazebo/Grey</material>
    <turnGravityOff>false</turnGravityOff>
  </gazebo>
  <joint name="omni_sphere2_joint_left_rear" type="continuous">
    <parent link="wheel_left_rear"/>
    <child link="omni_sphere2_left_rear"/>
    <axis xyz="0 1 0"/>
    <origin rpy="0.5236 0 0" xyz="0.0 0.026 0.015"/>
    <dynamics damping="0.01" friction="0.0"/>
    <limit effort="0.5" velocity="0.05"/>
  </joint>
  <link name="omni_sphere2_left_rear">
    <inertial>
      <origin rpy="0 0 0" xyz="0.0 0.0 0.0"/>
      <mass value="0.05"/>
      <inertia ixx="0.000018" ixy="0" ixz="0" iyy="0.000018" iyz="0" izz="0.000018"/>
    </inertial>
    <visual>
      <origin rpy="0 0 0" xyz="0.0 0.0 0.0"/>
      <geometry>
        <sphere radius="0.03"/>
      </geometry>
      <material name="Grey">
     </material>
    </visual>
    <collision>
      <origin rpy="0 0 0" xyz="0.0 0.0 0.0"/>
      <geometry>
        <sphere radius="0.03"/>
      </geometry>
    </collision>
  </link>
  <gazebo reference="omni_sphere2_left_rear">
    <material>Gazebo/Grey</material>
    <turnGravityOff>false</turnGravityOff>
  </gazebo>
  <joint name="omni_sphere2_joint_right_rear" type="continuous">
    <parent link="wheel_right_rear"/>
    <child link="omni_sphere2_right_rear"/>
    <axis xyz="0 1 0"/>
    <origin rpy="0.5236 0 0" xyz="0.0 0.026 0.015"/>
    <dynamics damping="0.01" friction="0.0"/>
    <limit effort="0.5" velocity="0.05"/>
  </joint>
  <link name="omni_sphere2_right_rear">
    <inertial>
      <origin rpy="0 0 0" xyz="0.0 0.0 0.0"/>
      <mass value="0.05"/>
      <inertia ixx="0.000018" ixy="0" ixz="0" iyy="0.000018" iyz="0" izz="0.000018"/>
    </inertial>
    <visual>
      <origin rpy="0 0 0" xyz="0.0 0.0 0.0"/>
      <geometry>
        <sphere radius="0.03"/>
      </geometry>
      <material name="Grey">
     </material>
    </visual>
    <collision>
      <origin rpy="0 0 0" xyz="0.0 0.0 0.0"/>
      <geometry>
        <sphere radius="0.03"/>
      </geometry>
    </collision>
  </link>
  <gazebo reference="omni_sphere2_right_rear">
    <material>Gazebo/Grey</material>
    <turnGravityOff>false</turnGravityOff>
  </gazebo>
  <joint name="omni_sphere3_joint_left_front" type="continuous">
    <parent link="wheel_left_front"/>
    <child link="omni_sphere3_left_front"/>
    <axis xyz="0 1 0"/>
    <origin rpy="1.0472 0 0" xyz="0.0 0.015 0.026"/>
    <dynamics damping="0.01" friction="0.0"/>
    <limit effort="0.5" velocity="0.05"/>
  </joint>
  <link name="omni_sphere3_left_front">
    <inertial>
      <origin rpy="0 0 0" xyz="0.0 0.0 0.0"/>
      <mass value="0.05"/>
      <inertia ixx="0.000018" ixy="0" ixz="0" iyy="0.000018" iyz="0" izz="0.000018"/>
    </inertial>
    <visual>
      <origin rpy="0 0 0" xyz="0.0 0.0 0.0"/>
      <geometry>
        <sphere radius="0.03"/>
      </geometry>
      <material name="Grey">
     </material>
    </visual>
    <collision>
      <origin rpy="0 0 0" xyz="0.0 0.0 0.0"/>
      <geometry>
        <sphere radius="0.03"/>
      </geometry>
    </collision>
  </link>
  <gazebo reference="omni_sphere3_left_front">
    <material>Gazebo/Grey</material>
    <turnGravityOff>false</turnGravityOff>
  </gazebo>
  <joint name="omni_sphere3_joint_right_front" type="continuous">
    <parent link="wheel_right_front"/>
    <child link="omni_sphere3_right_front"/>
    <axis xyz="0 1 0"/>
    <origin rpy="1.0472 0 0" xyz="0.0 0.015 0.026"/>
    <dynamics damping="0.01" friction="0.0"/>
    <limit effort="0.5" velocity="0.05"/>
  </joint>
  <link name="omni_sphere3_right_front">
    <inertial>
      <origin rpy="0 0 0" xyz="0.0 0.0 0.0"/>
      <mass value="0.05"/>
      <inertia ixx="0.000018" ixy="0" ixz="0" iyy="0.000018" iyz="0" izz="0.000018"/>
    </inertial>
    <visual>
      <origin rpy="0 0 0" xyz="0.0 0.0 0.0"/>
      <geometry>
        <sphere radius="0.03"/>
      </geometry>
      <material name="Grey">
     </material>
    </visual>
    <collision>
      <origin rpy="0 0 0" xyz="0.0 0.0 0.0"/>
      <geometry>
        <sphere radius="0.03"/>
      </geometry>
    </collision>
  </link>
  <gazebo reference="omni_sphere3_right_front">
    <material>Gazebo/Grey</material>
    <turnGravityOff>false</turnGravityOff>
  </gazebo>
  <joint name="omni_sphere3_joint_left_rear" type="continuous">
    <parent link="wheel_left_rear"/>
    <child link="omni_sphere3_left_rear"/>
    <axis xyz="0 1 0"/>
    <origin rpy="1.0472 0 0" xyz="0.0 0.015 0.026"/>
    <dynamics damping="0.01" friction="0.0"/>
    <limit effort="0.5" velocity="0.05"/>
  </joint>
  <link name="omni_sphere3_left_rear">
    <inertial>
      <origin rpy="0 0 0" xyz="0.0 0.0 0.0"/>
      <mass value="0.05"/>
      <inertia ixx="0.000018" ixy="0" ixz="0" iyy="0.000018" iyz="0" izz="0.000018"/>
    </inertial>
    <visual>
      <origin rpy="0 0 0" xyz="0.0 0.0 0.0"/>
      <geometry>
        <sphere radius="0.03"/>
      </geometry>
      <material name="Grey">
     </material>
    </visual>
    <collision>
      <origin rpy="0 0 0" xyz="0.0 0.0 0.0"/>
      <geometry>
        <sphere radius="0.03"/>
      </geometry>
    </collision>
  </link>
  <gazebo reference="omni_sphere3_left_rear">
    <material>Gazebo/Grey</material>
    <turnGravityOff>false</turnGravityOff>
  </gazebo>
  <joint name="omni_sphere3_joint_right_rear" type="continuous">
    <parent link="wheel_right_rear"/>
    <child link="omni_sphere3_right_rear"/>
    <axis xyz="0 1 0"/>
    <origin rpy="1.0472 0 0" xyz="0.0 0.015 0.026"/>
    <dynamics damping="0.01" friction="0.0"/>
    <limit effort="0.5" velocity="0.05"/>
  </joint>
  <link name="omni_sphere3_right_rear">
    <inertial>
      <origin rpy="0 0 0" xyz="0.0 0.0 0.0"/>
      <mass value="0.05"/>
      <inertia ixx="0.000018" ixy="0" ixz="0" iyy="0.000018" iyz="0" izz="0.000018"/>
    </inertial>
    <visual>
      <origin rpy="0 0 0" xyz="0.0 0.0 0.0"/>
      <geometry>
        <sphere radius="0.03"/>
      </geometry>
      <material name="Grey">
     </material>
    </visual>
    <collision>
      <origin rpy="0 0 0" xyz="0.0 0.0 0.0"/>
      <geometry>
        <sphere radius="0.03"/>
      </geometry>
    </collision>
  </link>
  <gazebo reference="omni_sphere3_right_rear">
    <material>Gazebo/Grey</material>
    <turnGravityOff>false</turnGravityOff>
  </gazebo>
  <joint name="omni_sphere4_joint_left_front" type="continuous">
    <parent link="wheel_left_front"/>
    <child link="omni_sphere4_left_front"/>
    <axis xyz="0 1 0"/>
    <origin rpy="1.5708 0 0" xyz="0.0 0 0.03"/>
    <dynamics damping="0.01" friction="0.0"/>
    <limit effort="0.5" velocity="0.05"/>
  </joint>
  <link name="omni_sphere4_left_front">
    <inertial>
      <origin rpy="0 0 0" xyz="0.0 0.0 0.0"/>
      <mass value="0.05"/>
      <inertia ixx="0.000018" ixy="0" ixz="0" iyy="0.000018" iyz="0" izz="0.000018"/>
    </inertial>
    <visual>
      <origin rpy="0 0 0" xyz="0.0 0.0 0.0"/>
      <geometry>
        <sphere radius="0.03"/>
      </geometry>
      <material name="Grey">
     </material>
    </visual>
    <collision>
      <origin rpy="0 0 0" xyz="0.0 0.0 0.0"/>
      <geometry>
        <sphere radius="0.03"/>
      </geometry>
    </collision>
  </link>
  <gazebo reference="omni_sphere4_left_front">
    <material>Gazebo/Grey</material>
    <turnGravityOff>false</turnGravityOff>
  </gazebo>
  <joint name="omni_sphere4_joint_right_front" type="continuous">
    <parent link="wheel_right_front"/>
    <child link="omni_sphere4_right_front"/>
    <axis xyz="0 1 0"/>
    <origin rpy="1.5708 0 0" xyz="0.0 0 0.03"/>
    <dynamics damping="0.01" friction="0.0"/>
    <limit effort="0.5" velocity="0.05"/>
  </joint>
  <link name="omni_sphere4_right_front">
    <inertial>
      <origin rpy="0 0 0" xyz="0.0 0.0 0.0"/>
      <mass value="0.05"/>
      <inertia ixx="0.000018" ixy="0" ixz="0" iyy="0.000018" iyz="0" izz="0.000018"/>
    </inertial>
    <visual>
      <origin rpy="0 0 0" xyz="0.0 0.0 0.0"/>
      <geometry>
        <sphere radius="0.03"/>
      </geometry>
      <material name="Grey">
     </material>
    </visual>
    <collision>
      <origin rpy="0 0 0" xyz="0.0 0.0 0.0"/>
      <geometry>
        <sphere radius="0.03"/>
      </geometry>
    </collision>
  </link>
  <gazebo reference="omni_sphere4_right_front">
    <material>Gazebo/Grey</material>
    <turnGravityOff>false</turnGravityOff>
  </gazebo>
  <joint name="omni_sphere4_joint_left_rear" type="continuous">
    <parent link="wheel_left_rear"/>
    <child link="omni_sphere4_left_rear"/>
    <axis xyz="0 1 0"/>
    <origin rpy="1.5708 0 0" xyz="0.0 0 0.03"/>
    <dynamics damping="0.01" friction="0.0"/>
    <limit effort="0.5" velocity="0.05"/>
  </joint>
  <link name="omni_sphere4_left_rear">
    <inertial>
      <origin rpy="0 0 0" xyz="0.0 0.0 0.0"/>
      <mass value="0.05"/>
      <inertia ixx="0.000018" ixy="0" ixz="0" iyy="0.000018" iyz="0" izz="0.000018"/>
    </inertial>
    <visual>
      <origin rpy="0 0 0" xyz="0.0 0.0 0.0"/>
      <geometry>
        <sphere radius="0.03"/>
      </geometry>
      <material name="Grey">
     </material>
    </visual>
    <collision>
      <origin rpy="0 0 0" xyz="0.0 0.0 0.0"/>
      <geometry>
        <sphere radius="0.03"/>
      </geometry>
    </collision>
  </link>
  <gazebo reference="omni_sphere4_left_rear">
    <material>Gazebo/Grey</material>
    <turnGravityOff>false</turnGravityOff>
  </gazebo>
  <joint name="omni_sphere4_joint_right_rear" type="continuous">
    <parent link="wheel_right_rear"/>
    <child link="omni_sphere4_right_rear"/>
    <axis xyz="0 1 0"/>
    <origin rpy="1.5708 0 0" xyz="0.0 0 0.03"/>
    <dynamics damping="0.01" friction="0.0"/>
    <limit effort="0.5" velocity="0.05"/>
  </joint>
  <link name="omni_sphere4_right_rear">
    <inertial>
      <origin rpy="0 0 0" xyz="0.0 0.0 0.0"/>
      <mass value="0.05"/>
      <inertia ixx="0.000018" ixy="0" ixz="0" iyy="0.000018" iyz="0" izz="0.000018"/>
    </inertial>
    <visual>
      <origin rpy="0 0 0" xyz="0.0 0.0 0.0"/>
      <geometry>
        <sphere radius="0.03"/>
      </geometry>
      <material name="Grey">
     </material>
    </visual>
    <collision>
      <origin rpy="0 0 0" xyz="0.0 0.0 0.0"/>
      <geometry>
        <sphere radius="0.03"/>
      </geometry>
    </collision>
  </link>
  <gazebo reference="omni_sphere4_right_rear">
    <material>Gazebo/Grey</material>
    <turnGravityOff>false</turnGravityOff>
  </gazebo>
  <joint name="omni_sphere5_joint_left_front" type="continuous">
    <parent link="wheel_left_front"/>
    <child link="omni_sphere5_left_front"/>
    <axis xyz="0 1 0"/>
    <origin rpy="2.0944 0 0" xyz="0.0 -0.015 0.026"/>
    <dynamics damping="0.01" friction="0.0"/>
    <limit effort="0.5" velocity="0.05"/>
  </joint>
  <link name="omni_sphere5_left_front">
    <inertial>
      <origin rpy="0 0 0" xyz="0.0 0.0 0.0"/>
      <mass value="0.05"/>
      <inertia ixx="0.000018" ixy="0" ixz="0" iyy="0.000018" iyz="0" izz="0.000018"/>
    </inertial>
    <visual>
      <origin rpy="0 0 0" xyz="0.0 0.0 0.0"/>
      <geometry>
        <sphere radius="0.03"/>
      </geometry>
      <material name="Grey">
     </material>
    </visual>
    <collision>
      <origin rpy="0 0 0" xyz="0.0 0.0 0.0"/>
      <geometry>
        <sphere radius="0.03"/>
      </geometry>
    </collision>
  </link>
  <gazebo reference="omni_sphere5_left_front">
    <material>Gazebo/Grey</material>
    <turnGravityOff>false</turnGravityOff>
  </gazebo>
  <joint name="omni_sphere5_joint_right_front" type="continuous">
    <parent link="wheel_right_front"/>
    <child link="omni_sphere5_right_front"/>
    <axis xyz="0 1 0"/>
    <origin rpy="2.0944 0 0" xyz="0.0 -0.015 0.026"/>
    <dynamics damping="0.01" friction="0.0"/>
    <limit effort="0.5" velocity="0.05"/>
  </joint>
  <link name="omni_sphere5_right_front">
    <inertial>
      <origin rpy="0 0 0" xyz="0.0 0.0 0.0"/>
      <mass value="0.05"/>
      <inertia ixx="0.000018" ixy="0" ixz="0" iyy="0.000018" iyz="0" izz="0.000018"/>
    </inertial>
    <visual>
      <origin rpy="0 0 0" xyz="0.0 0.0 0.0"/>
      <geometry>
        <sphere radius="0.03"/>
      </geometry>
      <material name="Grey">
     </material>
    </visual>
    <collision>
      <origin rpy="0 0 0" xyz="0.0 0.0 0.0"/>
      <geometry>
        <sphere radius="0.03"/>
      </geometry>
    </collision>
  </link>
  <gazebo reference="omni_sphere5_right_front">
    <material>Gazebo/Grey</material>
    <turnGravityOff>false</turnGravityOff>
  </gazebo>
  <joint name="omni_sphere5_joint_left_rear" type="continuous">
    <parent link="wheel_left_rear"/>
    <child link="omni_sphere5_left_rear"/>
    <axis xyz="0 1 0"/>
    <origin rpy="2.0944 0 0" xyz="0.0 -0.015 0.026"/>
    <dynamics damping="0.01" friction="0.0"/>
    <limit effort="0.5" velocity="0.05"/>
  </joint>
  <link name="omni_sphere5_left_rear">
    <inertial>
      <origin rpy="0 0 0" xyz="0.0 0.0 0.0"/>
      <mass value="0.05"/>
      <inertia ixx="0.000018" ixy="0" ixz="0" iyy="0.000018" iyz="0" izz="0.000018"/>
    </inertial>
    <visual>
      <origin rpy="0 0 0" xyz="0.0 0.0 0.0"/>
      <geometry>
        <sphere radius="0.03"/>
      </geometry>
      <material name="Grey">
     </material>
    </visual>
    <collision>
      <origin rpy="0 0 0" xyz="0.0 0.0 0.0"/>
      <geometry>
        <sphere radius="0.03"/>
      </geometry>
    </collision>
  </link>
  <gazebo reference="omni_sphere5_left_rear">
    <material>Gazebo/Grey</material>
    <turnGravityOff>false</turnGravityOff>
  </gazebo>
  <joint name="omni_sphere5_joint_right_rear" type="continuous">
    <parent link="wheel_right_rear"/>
    <child link="omni_sphere5_right_rear"/>
    <axis xyz="0 1 0"/>
    <origin rpy="2.0944 0 0" xyz="0.0 -0.015 0.026"/>
    <dynamics damping="0.01" friction="0.0"/>
    <limit effort="0.5" velocity="0.05"/>
  </joint>
  <link name="omni_sphere5_right_rear">
    <inertial>
      <origin rpy="0 0 0" xyz="0.0 0.0 0.0"/>
      <mass value="0.05"/>
      <inertia ixx="0.000018" ixy="0" ixz="0" iyy="0.000018" iyz="0" izz="0.000018"/>
    </inertial>
    <visual>
      <origin rpy="0 0 0" xyz="0.0 0.0 0.0"/>
      <geometry>
        <sphere radius="0.03"/>
      </geometry>
      <material name="Grey">
     </material>
    </visual>
    <collision>
      <origin rpy="0 0 0" xyz="0.0 0.0 0.0"/>
      <geometry>
        <sphere radius="0.03"/>
      </geometry>
    </collision>
  </link>
  <gazebo reference="omni_sphere5_right_rear">
    <material>Gazebo/Grey</material>
    <turnGravityOff>false</turnGravityOff>
  </gazebo>
  <joint name="omni_sphere6_joint_left_front" type="continuous">
    <parent link="wheel_left_front"/>
    <child link="omni_sphere6_left_front"/>
    <axis xyz="0 1 0"/>
    <origin rpy="2.618 0 0" xyz="0.0 -0.026 0.015"/>
    <dynamics damping="0.01" friction="0.0"/>
    <limit effort="0.5" velocity="0.05"/>
  </joint>
  <link name="omni_sphere6_left_front">
    <inertial>
      <origin rpy="0 0 0" xyz="0.0 0.0 0.0"/>
      <mass value="0.05"/>
      <inertia ixx="0.000018" ixy="0" ixz="0" iyy="0.000018" iyz="0" izz="0.000018"/>
    </inertial>
    <visual>
      <origin rpy="0 0 0" xyz="0.0 0.0 0.0"/>
      <geometry>
        <sphere radius="0.03"/>
      </geometry>
      <material name="Grey">
     </material>
    </visual>
    <collision>
      <origin rpy="0 0 0" xyz="0.0 0.0 0.0"/>
      <geometry>
        <sphere radius="0.03"/>
      </geometry>
    </collision>
  </link>
  <gazebo reference="omni_sphere6_left_front">
    <material>Gazebo/Grey</material>
    <turnGravityOff>false</turnGravityOff>
  </gazebo>
  <joint name="omni_sphere6_joint_right_front" type="continuous">
    <parent link="wheel_right_front"/>
    <child link="omni_sphere6_right_front"/>
    <axis xyz="0 1 0"/>
    <origin rpy="2.618 0 0" xyz="0.0 -0.026 0.015"/>
    <dynamics damping="0.01" friction="0.0"/>
    <limit effort="0.5" velocity="0.05"/>
  </joint>
  <link name="omni_sphere6_right_front">
    <inertial>
      <origin rpy="0 0 0" xyz="0.0 0.0 0.0"/>
      <mass value="0.05"/>
      <inertia ixx="0.000018" ixy="0" ixz="0" iyy="0.000018" iyz="0" izz="0.000018"/>
    </inertial>
    <visual>
      <origin rpy="0 0 0" xyz="0.0 0.0 0.0"/>
      <geometry>
        <sphere radius="0.03"/>
      </geometry>
      <material name="Grey">
     </material>
    </visual>
    <collision>
      <origin rpy="0 0 0" xyz="0.0 0.0 0.0"/>
      <geometry>
        <sphere radius="0.03"/>
      </geometry>
    </collision>
  </link>
  <gazebo reference="omni_sphere6_right_front">
    <material>Gazebo/Grey</material>
    <turnGravityOff>false</turnGravityOff>
  </gazebo>
  <joint name="omni_sphere6_joint_left_rear" type="continuous">
    <parent link="wheel_left_rear"/>
    <child link="omni_sphere6_left_rear"/>
    <axis xyz="0 1 0"/>
    <origin rpy="2.618 0 0" xyz="0.0 -0.026 0.015"/>
    <dynamics damping="0.01" friction="0.0"/>
    <limit effort="0.5" velocity="0.05"/>
  </joint>
  <link name="omni_sphere6_left_rear">
    <inertial>
      <origin rpy="0 0 0" xyz="0.0 0.0 0.0"/>
      <mass value="0.05"/>
      <inertia ixx="0.000018" ixy="0" ixz="0" iyy="0.000018" iyz="0" izz="0.000018"/>
    </inertial>
    <visual>
      <origin rpy="0 0 0" xyz="0.0 0.0 0.0"/>
      <geometry>
        <sphere radius="0.03"/>
      </geometry>
      <material name="Grey">
     </material>
    </visual>
    <collision>
      <origin rpy="0 0 0" xyz="0.0 0.0 0.0"/>
      <geometry>
        <sphere radius="0.03"/>
      </geometry>
    </collision>
  </link>
  <gazebo reference="omni_sphere6_left_rear">
    <material>Gazebo/Grey</material>
    <turnGravityOff>false</turnGravityOff>
  </gazebo>
  <joint name="omni_sphere6_joint_right_rear" type="continuous">
    <parent link="wheel_right_rear"/>
    <child link="omni_sphere6_right_rear"/>
    <axis xyz="0 1 0"/>
    <origin rpy="2.618 0 0" xyz="0.0 -0.026 0.015"/>
    <dynamics damping="0.01" friction="0.0"/>
    <limit effort="0.5" velocity="0.05"/>
  </joint>
  <link name="omni_sphere6_right_rear">
    <inertial>
      <origin rpy="0 0 0" xyz="0.0 0.0 0.0"/>
      <mass value="0.05"/>
      <inertia ixx="0.000018" ixy="0" ixz="0" iyy="0.000018" iyz="0" izz="0.000018"/>
    </inertial>
    <visual>
      <origin rpy="0 0 0" xyz="0.0 0.0 0.0"/>
      <geometry>
        <sphere radius="0.03"/>
      </geometry>
      <material name="Grey">
     </material>
    </visual>
    <collision>
      <origin rpy="0 0 0" xyz="0.0 0.0 0.0"/>
      <geometry>
        <sphere radius="0.03"/>
      </geometry>
    </collision>
  </link>
  <gazebo reference="omni_sphere6_right_rear">
    <material>Gazebo/Grey</material>
    <turnGravityOff>false</turnGravityOff>
  </gazebo>
  <joint name="omni_sphere7_joint_left_front" type="continuous">
    <parent link="wheel_left_front"/>
    <child link="omni_sphere7_left_front"/>
    <axis xyz="0 1 0"/>
    <origin rpy="3.1416 0 0" xyz="0.0 -0.03 0.0"/>
    <dynamics damping="0.01" friction="0.0"/>
    <limit effort="0.5" velocity="0.05"/>
  </joint>
  <link name="omni_sphere7_left_front">
    <inertial>
      <origin rpy="0 0 0" xyz="0.0 0.0 0.0"/>
      <mass value="0.05"/>
      <inertia ixx="0.000018" ixy="0" ixz="0" iyy="0.000018" iyz="0" izz="0.000018"/>
    </inertial>
    <visual>
      <origin rpy="0 0 0" xyz="0.0 0.0 0.0"/>
      <geometry>
        <sphere radius="0.03"/>
      </geometry>
      <material name="Grey">
     </material>
    </visual>
    <collision>
      <origin rpy="0 0 0" xyz="0.0 0.0 0.0"/>
      <geometry>
        <sphere radius="0.03"/>
      </geometry>
    </collision>
  </link>
  <gazebo reference="omni_sphere7_left_front">
    <material>Gazebo/Grey</material>
    <turnGravityOff>false</turnGravityOff>
  </gazebo>
  <joint name="omni_sphere7_joint_right_front" type="continuous">
    <parent link="wheel_right_front"/>
    <child link="omni_sphere7_right_front"/>
    <axis xyz="0 1 0"/>
    <origin rpy="3.1416 0 0" xyz="0.0 -0.03 0.0"/>
    <dynamics damping="0.01" friction="0.0"/>
    <limit effort="0.5" velocity="0.05"/>
  </joint>
  <link name="omni_sphere7_right_front">
    <inertial>
      <origin rpy="0 0 0" xyz="0.0 0.0 0.0"/>
      <mass value="0.05"/>
      <inertia ixx="0.000018" ixy="0" ixz="0" iyy="0.000018" iyz="0" izz="0.000018"/>
    </inertial>
    <visual>
      <origin rpy="0 0 0" xyz="0.0 0.0 0.0"/>
      <geometry>
        <sphere radius="0.03"/>
      </geometry>
      <material name="Grey">
     </material>
    </visual>
    <collision>
      <origin rpy="0 0 0" xyz="0.0 0.0 0.0"/>
      <geometry>
        <sphere radius="0.03"/>
      </geometry>
    </collision>
  </link>
  <gazebo reference="omni_sphere7_right_front">
    <material>Gazebo/Grey</material>
    <turnGravityOff>false</turnGravityOff>
  </gazebo>
  <joint name="omni_sphere7_joint_left_rear" type="continuous">
    <parent link="wheel_left_rear"/>
    <child link="omni_sphere7_left_rear"/>
    <axis xyz="0 1 0"/>
    <origin rpy="3.1416 0 0" xyz="0.0 -0.03 0.0"/>
    <dynamics damping="0.01" friction="0.0"/>
    <limit effort="0.5" velocity="0.05"/>
  </joint>
  <link name="omni_sphere7_left_rear">
    <inertial>
      <origin rpy="0 0 0" xyz="0.0 0.0 0.0"/>
      <mass value="0.05"/>
      <inertia ixx="0.000018" ixy="0" ixz="0" iyy="0.000018" iyz="0" izz="0.000018"/>
    </inertial>
    <visual>
      <origin rpy="0 0 0" xyz="0.0 0.0 0.0"/>
      <geometry>
        <sphere radius="0.03"/>
      </geometry>
      <material name="Grey">
     </material>
    </visual>
    <collision>
      <origin rpy="0 0 0" xyz="0.0 0.0 0.0"/>
      <geometry>
        <sphere radius="0.03"/>
      </geometry>
    </collision>
  </link>
  <gazebo reference="omni_sphere7_left_rear">
    <material>Gazebo/Grey</material>
    <turnGravityOff>false</turnGravityOff>
  </gazebo>
  <joint name="omni_sphere7_joint_right_rear" type="continuous">
    <parent link="wheel_right_rear"/>
    <child link="omni_sphere7_right_rear"/>
    <axis xyz="0 1 0"/>
    <origin rpy="3.1416 0 0" xyz="0.0 -0.03 0.0"/>
    <dynamics damping="0.01" friction="0.0"/>
    <limit effort="0.5" velocity="0.05"/>
  </joint>
  <link name="omni_sphere7_right_rear">
    <inertial>
      <origin rpy="0 0 0" xyz="0.0 0.0 0.0"/>
      <mass value="0.05"/>
      <inertia ixx="0.000018" ixy="0" ixz="0" iyy="0.000018" iyz="0" izz="0.000018"/>
    </inertial>
    <visual>
      <origin rpy="0 0 0" xyz="0.0 0.0 0.0"/>
      <geometry>
        <sphere radius="0.03"/>
      </geometry>
      <material name="Grey">
     </material>
    </visual>
    <collision>
      <origin rpy="0 0 0" xyz="0.0 0.0 0.0"/>
      <geometry>
        <sphere radius="0.03"/>
      </geometry>
    </collision>
  </link>
  <gazebo reference="omni_sphere7_right_rear">
    <material>Gazebo/Grey</material>
    <turnGravityOff>false</turnGravityOff>
  </gazebo>
  <joint name="omni_sphere8_joint_left_front" type="continuous">
    <parent link="wheel_left_front"/>
    <child link="omni_sphere8_left_front"/>
    <axis xyz="0 1 0"/>
    <origin rpy="3.6652 0 0" xyz="0.0 -0.026 -0.015"/>
    <dynamics damping="0.01" friction="0.0"/>
    <limit effort="0.5" velocity="0.05"/>
  </joint>
  <link name="omni_sphere8_left_front">
    <inertial>
      <origin rpy="0 0 0" xyz="0.0 0.0 0.0"/>
      <mass value="0.05"/>
      <inertia ixx="0.000018" ixy="0" ixz="0" iyy="0.000018" iyz="0" izz="0.000018"/>
    </inertial>
    <visual>
      <origin rpy="0 0 0" xyz="0.0 0.0 0.0"/>
      <geometry>
        <sphere radius="0.03"/>
      </geometry>
      <material name="Grey">
     </material>
    </visual>
    <collision>
      <origin rpy="0 0 0" xyz="0.0 0.0 0.0"/>
      <geometry>
        <sphere radius="0.03"/>
      </geometry>
    </collision>
  </link>
  <gazebo reference="omni_sphere8_left_front">
    <material>Gazebo/Grey</material>
    <turnGravityOff>false</turnGravityOff>
  </gazebo>
  <joint name="omni_sphere8_joint_right_front" type="continuous">
    <parent link="wheel_right_front"/>
    <child link="omni_sphere8_right_front"/>
    <axis xyz="0 1 0"/>
    <origin rpy="3.6652 0 0" xyz="0.0 -0.026 -0.015"/>
    <dynamics damping="0.01" friction="0.0"/>
    <limit effort="0.5" velocity="0.05"/>
  </joint>
  <link name="omni_sphere8_right_front">
    <inertial>
      <origin rpy="0 0 0" xyz="0.0 0.0 0.0"/>
      <mass value="0.05"/>
      <inertia ixx="0.000018" ixy="0" ixz="0" iyy="0.000018" iyz="0" izz="0.000018"/>
    </inertial>
    <visual>
      <origin rpy="0 0 0" xyz="0.0 0.0 0.0"/>
      <geometry>
        <sphere radius="0.03"/>
      </geometry>
      <material name="Grey">
     </material>
    </visual>
    <collision>
      <origin rpy="0 0 0" xyz="0.0 0.0 0.0"/>
      <geometry>
        <sphere radius="0.03"/>
      </geometry>
    </collision>
  </link>
  <gazebo reference="omni_sphere8_right_front">
    <material>Gazebo/Grey</material>
    <turnGravityOff>false</turnGravityOff>
  </gazebo>
  <joint name="omni_sphere8_joint_left_rear" type="continuous">
    <parent link="wheel_left_rear"/>
    <child link="omni_sphere8_left_rear"/>
    <axis xyz="0 1 0"/>
    <origin rpy="3.6652 0 0" xyz="0.0 -0.026 -0.015"/>
    <dynamics damping="0.01" friction="0.0"/>
    <limit effort="0.5" velocity="0.05"/>
  </joint>
  <link name="omni_sphere8_left_rear">
    <inertial>
      <origin rpy="0 0 0" xyz="0.0 0.0 0.0"/>
      <mass value="0.05"/>
      <inertia ixx="0.000018" ixy="0" ixz="0" iyy="0.000018" iyz="0" izz="0.000018"/>
    </inertial>
    <visual>
      <origin rpy="0 0 0" xyz="0.0 0.0 0.0"/>
      <geometry>
        <sphere radius="0.03"/>
      </geometry>
      <material name="Grey">
     </material>
    </visual>
    <collision>
      <origin rpy="0 0 0" xyz="0.0 0.0 0.0"/>
      <geometry>
        <sphere radius="0.03"/>
      </geometry>
    </collision>
  </link>
  <gazebo reference="omni_sphere8_left_rear">
    <material>Gazebo/Grey</material>
    <turnGravityOff>false</turnGravityOff>
  </gazebo>
  <joint name="omni_sphere8_joint_right_rear" type="continuous">
    <parent link="wheel_right_rear"/>
    <child link="omni_sphere8_right_rear"/>
    <axis xyz="0 1 0"/>
    <origin rpy="3.6652 0 0" xyz="0.0 -0.026 -0.015"/>
    <dynamics damping="0.01" friction="0.0"/>
    <limit effort="0.5" velocity="0.05"/>
  </joint>
  <link name="omni_sphere8_right_rear">
    <inertial>
      <origin rpy="0 0 0" xyz="0.0 0.0 0.0"/>
      <mass value="0.05"/>
      <inertia ixx="0.000018" ixy="0" ixz="0" iyy="0.000018" iyz="0" izz="0.000018"/>
    </inertial>
    <visual>
      <origin rpy="0 0 0" xyz="0.0 0.0 0.0"/>
      <geometry>
        <sphere radius="0.03"/>
      </geometry>
      <material name="Grey">
     </material>
    </visual>
    <collision>
      <origin rpy="0 0 0" xyz="0.0 0.0 0.0"/>
      <geometry>
        <sphere radius="0.03"/>
      </geometry>
    </collision>
  </link>
  <gazebo reference="omni_sphere8_right_rear">
    <material>Gazebo/Grey</material>
    <turnGravityOff>false</turnGravityOff>
  </gazebo>
  <joint name="omni_sphere9_joint_left_front" type="continuous">
    <parent link="wheel_left_front"/>
    <child link="omni_sphere9_left_front"/>
    <axis xyz="0 1 0"/>
    <origin rpy="4.1888 0 0" xyz="0.0 -0.015 -0.026"/>
    <dynamics damping="0.01" friction="0.0"/>
    <limit effort="0.5" velocity="0.05"/>
  </joint>
  <link name="omni_sphere9_left_front">
    <inertial>
      <origin rpy="0 0 0" xyz="0.0 0.0 0.0"/>
      <mass value="0.05"/>
      <inertia ixx="0.000018" ixy="0" ixz="0" iyy="0.000018" iyz="0" izz="0.000018"/>
    </inertial>
    <visual>
      <origin rpy="0 0 0" xyz="0.0 0.0 0.0"/>
      <geometry>
        <sphere radius="0.03"/>
      </geometry>
      <material name="Grey">
     </material>
    </visual>
    <collision>
      <origin rpy="0 0 0" xyz="0.0 0.0 0.0"/>
      <geometry>
        <sphere radius="0.03"/>
      </geometry>
    </collision>
  </link>
  <gazebo reference="omni_sphere9_left_front">
    <material>Gazebo/Grey</material>
    <turnGravityOff>false</turnGravityOff>
  </gazebo>
  <joint name="omni_sphere9_joint_right_front" type="continuous">
    <parent link="wheel_right_front"/>
    <child link="omni_sphere9_right_front"/>
    <axis xyz="0 1 0"/>
    <origin rpy="4.1888 0 0" xyz="0.0 -0.015 -0.026"/>
    <dynamics damping="0.01" friction="0.0"/>
    <limit effort="0.5" velocity="0.05"/>
  </joint>
  <link name="omni_sphere9_right_front">
    <inertial>
      <origin rpy="0 0 0" xyz="0.0 0.0 0.0"/>
      <mass value="0.05"/>
      <inertia ixx="0.000018" ixy="0" ixz="0" iyy="0.000018" iyz="0" izz="0.000018"/>
    </inertial>
    <visual>
      <origin rpy="0 0 0" xyz="0.0 0.0 0.0"/>
      <geometry>
        <sphere radius="0.03"/>
      </geometry>
      <material name="Grey">
     </material>
    </visual>
    <collision>
      <origin rpy="0 0 0" xyz="0.0 0.0 0.0"/>
      <geometry>
        <sphere radius="0.03"/>
      </geometry>
    </collision>
  </link>
  <gazebo reference="omni_sphere9_right_front">
    <material>Gazebo/Grey</material>
    <turnGravityOff>false</turnGravityOff>
  </gazebo>
  <joint name="omni_sphere9_joint_left_rear" type="continuous">
    <parent link="wheel_left_rear"/>
    <child link="omni_sphere9_left_rear"/>
    <axis xyz="0 1 0"/>
    <origin rpy="4.1888 0 0" xyz="0.0 -0.015 -0.026"/>
    <dynamics damping="0.01" friction="0.0"/>
    <limit effort="0.5" velocity="0.05"/>
  </joint>
  <link name="omni_sphere9_left_rear">
    <inertial>
      <origin rpy="0 0 0" xyz="0.0 0.0 0.0"/>
      <mass value="0.05"/>
      <inertia ixx="0.000018" ixy="0" ixz="0" iyy="0.000018" iyz="0" izz="0.000018"/>
    </inertial>
    <visual>
      <origin rpy="0 0 0" xyz="0.0 0.0 0.0"/>
      <geometry>
        <sphere radius="0.03"/>
      </geometry>
      <material name="Grey">
     </material>
    </visual>
    <collision>
      <origin rpy="0 0 0" xyz="0.0 0.0 0.0"/>
      <geometry>
        <sphere radius="0.03"/>
      </geometry>
    </collision>
  </link>
  <gazebo reference="omni_sphere9_left_rear">
    <material>Gazebo/Grey</material>
    <turnGravityOff>false</turnGravityOff>
  </gazebo>
  <joint name="omni_sphere9_joint_right_rear" type="continuous">
    <parent link="wheel_right_rear"/>
    <child link="omni_sphere9_right_rear"/>
    <axis xyz="0 1 0"/>
    <origin rpy="4.1888 0 0" xyz="0.0 -0.015 -0.026"/>
    <dynamics damping="0.01" friction="0.0"/>
    <limit effort="0.5" velocity="0.05"/>
  </joint>
  <link name="omni_sphere9_right_rear">
    <inertial>
      <origin rpy="0 0 0" xyz="0.0 0.0 0.0"/>
      <mass value="0.05"/>
      <inertia ixx="0.000018" ixy="0" ixz="0" iyy="0.000018" iyz="0" izz="0.000018"/>
    </inertial>
    <visual>
      <origin rpy="0 0 0" xyz="0.0 0.0 0.0"/>
      <geometry>
        <sphere radius="0.03"/>
      </geometry>
      <material name="Grey">
     </material>
    </visual>
    <collision>
      <origin rpy="0 0 0" xyz="0.0 0.0 0.0"/>
      <geometry>
        <sphere radius="0.03"/>
      </geometry>
    </collision>
  </link>
  <gazebo reference="omni_sphere9_right_rear">
    <material>Gazebo/Grey</material>
    <turnGravityOff>false</turnGravityOff>
  </gazebo>
  <joint name="omni_sphere10_joint_left_front" type="continuous">
    <parent link="wheel_left_front"/>
    <child link="omni_sphere10_left_front"/>
    <axis xyz="0 1 0"/>
    <origin rpy="4.7124 0 0" xyz="0.0 0.0 -0.03"/>
    <dynamics damping="0.01" friction="0.0"/>
    <limit effort="0.5" velocity="0.05"/>
  </joint>
  <link name="omni_sphere10_left_front">
    <inertial>
      <origin rpy="0 0 0" xyz="0.0 0.0 0.0"/>
      <mass value="0.05"/>
      <inertia ixx="0.000018" ixy="0" ixz="0" iyy="0.000018" iyz="0" izz="0.000018"/>
    </inertial>
    <visual>
      <origin rpy="0 0 0" xyz="0.0 0.0 0.0"/>
      <geometry>
        <sphere radius="0.03"/>
      </geometry>
      <material name="Grey">
     </material>
    </visual>
    <collision>
      <origin rpy="0 0 0" xyz="0.0 0.0 0.0"/>
      <geometry>
        <sphere radius="0.03"/>
      </geometry>
    </collision>
  </link>
  <gazebo reference="omni_sphere10_left_front">
    <material>Gazebo/Grey</material>
    <turnGravityOff>false</turnGravityOff>
  </gazebo>
  <joint name="omni_sphere10_joint_right_front" type="continuous">
    <parent link="wheel_right_front"/>
    <child link="omni_sphere10_right_front"/>
    <axis xyz="0 1 0"/>
    <origin rpy="4.7124 0 0" xyz="0.0 0.0 -0.03"/>
    <dynamics damping="0.01" friction="0.0"/>
    <limit effort="0.5" velocity="0.05"/>
  </joint>
  <link name="omni_sphere10_right_front">
    <inertial>
      <origin rpy="0 0 0" xyz="0.0 0.0 0.0"/>
      <mass value="0.05"/>
      <inertia ixx="0.000018" ixy="0" ixz="0" iyy="0.000018" iyz="0" izz="0.000018"/>
    </inertial>
    <visual>
      <origin rpy="0 0 0" xyz="0.0 0.0 0.0"/>
      <geometry>
        <sphere radius="0.03"/>
      </geometry>
      <material name="Grey">
     </material>
    </visual>
    <collision>
      <origin rpy="0 0 0" xyz="0.0 0.0 0.0"/>
      <geometry>
        <sphere radius="0.03"/>
      </geometry>
    </collision>
  </link>
  <gazebo reference="omni_sphere10_right_front">
    <material>Gazebo/Grey</material>
    <turnGravityOff>false</turnGravityOff>
  </gazebo>
  <joint name="omni_sphere10_joint_left_rear" type="continuous">
    <parent link="wheel_left_rear"/>
    <child link="omni_sphere10_left_rear"/>
    <axis xyz="0 1 0"/>
    <origin rpy="4.7124 0 0" xyz="0.0 0.0 -0.03"/>
    <dynamics damping="0.01" friction="0.0"/>
    <limit effort="0.5" velocity="0.05"/>
  </joint>
  <link name="omni_sphere10_left_rear">
    <inertial>
      <origin rpy="0 0 0" xyz="0.0 0.0 0.0"/>
      <mass value="0.05"/>
      <inertia ixx="0.000018" ixy="0" ixz="0" iyy="0.000018" iyz="0" izz="0.000018"/>
    </inertial>
    <visual>
      <origin rpy="0 0 0" xyz="0.0 0.0 0.0"/>
      <geometry>
        <sphere radius="0.03"/>
      </geometry>
      <material name="Grey">
     </material>
    </visual>
    <collision>
      <origin rpy="0 0 0" xyz="0.0 0.0 0.0"/>
      <geometry>
        <sphere radius="0.03"/>
      </geometry>
    </collision>
  </link>
  <gazebo reference="omni_sphere10_left_rear">
    <material>Gazebo/Grey</material>
    <turnGravityOff>false</turnGravityOff>
  </gazebo>
  <joint name="omni_sphere10_joint_right_rear" type="continuous">
    <parent link="wheel_right_rear"/>
    <child link="omni_sphere10_right_rear"/>
    <axis xyz="0 1 0"/>
    <origin rpy="4.7124 0 0" xyz="0.0 0.0 -0.03"/>
    <dynamics damping="0.01" friction="0.0"/>
    <limit effort="0.5" velocity="0.05"/>
  </joint>
  <link name="omni_sphere10_right_rear">
    <inertial>
      <origin rpy="0 0 0" xyz="0.0 0.0 0.0"/>
      <mass value="0.05"/>
      <inertia ixx="0.000018" ixy="0" ixz="0" iyy="0.000018" iyz="0" izz="0.000018"/>
    </inertial>
    <visual>
      <origin rpy="0 0 0" xyz="0.0 0.0 0.0"/>
      <geometry>
        <sphere radius="0.03"/>
      </geometry>
      <material name="Grey">
     </material>
    </visual>
    <collision>
      <origin rpy="0 0 0" xyz="0.0 0.0 0.0"/>
      <geometry>
        <sphere radius="0.03"/>
      </geometry>
    </collision>
  </link>
  <gazebo reference="omni_sphere10_right_rear">
    <material>Gazebo/Grey</material>
    <turnGravityOff>false</turnGravityOff>
  </gazebo>
  <joint name="omni_sphere11_joint_left_front" type="continuous">
    <parent link="wheel_left_front"/>
    <child link="omni_sphere11_left_front"/>
    <axis xyz="0 1 0"/>
    <origin rpy="5.236 0 0" xyz="0.0 0.015 -0.026"/>
    <dynamics damping="0.01" friction="0.0"/>
    <limit effort="0.5" velocity="0.05"/>
  </joint>
  <link name="omni_sphere11_left_front">
    <inertial>
      <origin rpy="0 0 0" xyz="0.0 0.0 0.0"/>
      <mass value="0.05"/>
      <inertia ixx="0.000018" ixy="0" ixz="0" iyy="0.000018" iyz="0" izz="0.000018"/>
    </inertial>
    <visual>
      <origin rpy="0 0 0" xyz="0.0 0.0 0.0"/>
      <geometry>
        <sphere radius="0.03"/>
      </geometry>
      <material name="Grey">
     </material>
    </visual>
    <collision>
      <origin rpy="0 0 0" xyz="0.0 0.0 0.0"/>
      <geometry>
        <sphere radius="0.03"/>
      </geometry>
    </collision>
  </link>
  <gazebo reference="omni_sphere11_left_front">
    <material>Gazebo/Grey</material>
    <turnGravityOff>false</turnGravityOff>
  </gazebo>
  <joint name="omni_sphere11_joint_right_front" type="continuous">
    <parent link="wheel_right_front"/>
    <child link="omni_sphere11_right_front"/>
    <axis xyz="0 1 0"/>
    <origin rpy="5.236 0 0" xyz="0.0 0.015 -0.026"/>
    <dynamics damping="0.01" friction="0.0"/>
    <limit effort="0.5" velocity="0.05"/>
  </joint>
  <link name="omni_sphere11_right_front">
    <inertial>
      <origin rpy="0 0 0" xyz="0.0 0.0 0.0"/>
      <mass value="0.05"/>
      <inertia ixx="0.000018" ixy="0" ixz="0" iyy="0.000018" iyz="0" izz="0.000018"/>
    </inertial>
    <visual>
      <origin rpy="0 0 0" xyz="0.0 0.0 0.0"/>
      <geometry>
        <sphere radius="0.03"/>
      </geometry>
      <material name="Grey">
     </material>
    </visual>
    <collision>
      <origin rpy="0 0 0" xyz="0.0 0.0 0.0"/>
      <geometry>
        <sphere radius="0.03"/>
      </geometry>
    </collision>
  </link>
  <gazebo reference="omni_sphere11_right_front">
    <material>Gazebo/Grey</material>
    <turnGravityOff>false</turnGravityOff>
  </gazebo>
  <joint name="omni_sphere11_joint_left_rear" type="continuous">
    <parent link="wheel_left_rear"/>
    <child link="omni_sphere11_left_rear"/>
    <axis xyz="0 1 0"/>
    <origin rpy="5.236 0 0" xyz="0.0 0.015 -0.026"/>
    <dynamics damping="0.01" friction="0.0"/>
    <limit effort="0.5" velocity="0.05"/>
  </joint>
  <link name="omni_sphere11_left_rear">
    <inertial>
      <origin rpy="0 0 0" xyz="0.0 0.0 0.0"/>
      <mass value="0.05"/>
      <inertia ixx="0.000018" ixy="0" ixz="0" iyy="0.000018" iyz="0" izz="0.000018"/>
    </inertial>
    <visual>
      <origin rpy="0 0 0" xyz="0.0 0.0 0.0"/>
      <geometry>
        <sphere radius="0.03"/>
      </geometry>
      <material name="Grey">
     </material>
    </visual>
    <collision>
      <origin rpy="0 0 0" xyz="0.0 0.0 0.0"/>
      <geometry>
        <sphere radius="0.03"/>
      </geometry>
    </collision>
  </link>
  <gazebo reference="omni_sphere11_left_rear">
    <material>Gazebo/Grey</material>
    <turnGravityOff>false</turnGravityOff>
  </gazebo>
  <joint name="omni_sphere11_joint_right_rear" type="continuous">
    <parent link="wheel_right_rear"/>
    <child link="omni_sphere11_right_rear"/>
    <axis xyz="0 1 0"/>
    <origin rpy="5.236 0 0" xyz="0.0 0.015 -0.026"/>
    <dynamics damping="0.01" friction="0.0"/>
    <limit effort="0.5" velocity="0.05"/>
  </joint>
  <link name="omni_sphere11_right_rear">
    <inertial>
      <origin rpy="0 0 0" xyz="0.0 0.0 0.0"/>
      <mass value="0.05"/>
      <inertia ixx="0.000018" ixy="0" ixz="0" iyy="0.000018" iyz="0" izz="0.000018"/>
    </inertial>
    <visual>
      <origin rpy="0 0 0" xyz="0.0 0.0 0.0"/>
      <geometry>
        <sphere radius="0.03"/>
      </geometry>
      <material name="Grey">
     </material>
    </visual>
    <collision>
      <origin rpy="0 0 0" xyz="0.0 0.0 0.0"/>
      <geometry>
        <sphere radius="0.03"/>
      </geometry>
    </collision>
  </link>
  <gazebo reference="omni_sphere11_right_rear">
    <material>Gazebo/Grey</material>
    <turnGravityOff>false</turnGravityOff>
  </gazebo>
  <joint name="omni_sphere12_joint_left_front" type="continuous">
    <parent link="wheel_left_front"/>
    <child link="omni_sphere12_left_front"/>
    <axis xyz="0 1 0"/>
    <origin rpy="5.7596 0 0" xyz="0.0 0.026 -0.015"/>
    <dynamics damping="0.01" friction="0.0"/>
    <limit effort="0.5" velocity="0.05"/>
  </joint>
  <link name="omni_sphere12_left_front">
    <inertial>
      <origin rpy="0 0 0" xyz="0.0 0.0 0.0"/>
      <mass value="0.05"/>
      <inertia ixx="0.000018" ixy="0" ixz="0" iyy="0.000018" iyz="0" izz="0.000018"/>
    </inertial>
    <visual>
      <origin rpy="0 0 0" xyz="0.0 0.0 0.0"/>
      <geometry>
        <sphere radius="0.03"/>
      </geometry>
      <material name="Grey">
     </material>
    </visual>
    <collision>
      <origin rpy="0 0 0" xyz="0.0 0.0 0.0"/>
      <geometry>
        <sphere radius="0.03"/>
      </geometry>
    </collision>
  </link>
  <gazebo reference="omni_sphere12_left_front">
    <material>Gazebo/Grey</material>
    <turnGravityOff>false</turnGravityOff>
  </gazebo>
  <joint name="omni_sphere12_joint_right_front" type="continuous">
    <parent link="wheel_right_front"/>
    <child link="omni_sphere12_right_front"/>
    <axis xyz="0 1 0"/>
    <origin rpy="5.7596 0 0" xyz="0.0 0.026 -0.015"/>
    <dynamics damping="0.01" friction="0.0"/>
    <limit effort="0.5" velocity="0.05"/>
  </joint>
  <link name="omni_sphere12_right_front">
    <inertial>
      <origin rpy="0 0 0" xyz="0.0 0.0 0.0"/>
      <mass value="0.05"/>
      <inertia ixx="0.000018" ixy="0" ixz="0" iyy="0.000018" iyz="0" izz="0.000018"/>
    </inertial>
    <visual>
      <origin rpy="0 0 0" xyz="0.0 0.0 0.0"/>
      <geometry>
        <sphere radius="0.03"/>
      </geometry>
      <material name="Grey">
     </material>
    </visual>
    <collision>
      <origin rpy="0 0 0" xyz="0.0 0.0 0.0"/>
      <geometry>
        <sphere radius="0.03"/>
      </geometry>
    </collision>
  </link>
  <gazebo reference="omni_sphere12_right_front">
    <material>Gazebo/Grey</material>
    <turnGravityOff>false</turnGravityOff>
  </gazebo>
  <joint name="omni_sphere12_joint_left_rear" type="continuous">
    <parent link="wheel_left_rear"/>
    <child link="omni_sphere12_left_rear"/>
    <axis xyz="0 1 0"/>
    <origin rpy="5.7596 0 0" xyz="0.0 0.026 -0.015"/>
    <dynamics damping="0.01" friction="0.0"/>
    <limit effort="0.5" velocity="0.05"/>
  </joint>
  <link name="omni_sphere12_left_rear">
    <inertial>
      <origin rpy="0 0 0" xyz="0.0 0.0 0.0"/>
      <mass value="0.05"/>
      <inertia ixx="0.000018" ixy="0" ixz="0" iyy="0.000018" iyz="0" izz="0.000018"/>
    </inertial>
    <visual>
      <origin rpy="0 0 0" xyz="0.0 0.0 0.0"/>
      <geometry>
        <sphere radius="0.03"/>
      </geometry>
      <material name="Grey">
     </material>
    </visual>
    <collision>
      <origin rpy="0 0 0" xyz="0.0 0.0 0.0"/>
      <geometry>
        <sphere radius="0.03"/>
      </geometry>
    </collision>
  </link>
  <gazebo reference="omni_sphere12_left_rear">
    <material>Gazebo/Grey</material>
    <turnGravityOff>false</turnGravityOff>
  </gazebo>
  <joint name="omni_sphere12_joint_right_rear" type="continuous">
    <parent link="wheel_right_rear"/>
    <child link="omni_sphere12_right_rear"/>
    <axis xyz="0 1 0"/>
    <origin rpy="5.7596 0 0" xyz="0.0 0.026 -0.015"/>
    <dynamics damping="0.01" friction="0.0"/>
    <limit effort="0.5" velocity="0.05"/>
  </joint>
  <link name="omni_sphere12_right_rear">
    <inertial>
      <origin rpy="0 0 0" xyz="0.0 0.0 0.0"/>
      <mass value="0.05"/>
      <inertia ixx="0.000018" ixy="0" ixz="0" iyy="0.000018" iyz="0" izz="0.000018"/>
    </inertial>
    <visual>
      <origin rpy="0 0 0" xyz="0.0 0.0 0.0"/>
      <geometry>
        <sphere radius="0.03"/>
      </geometry>
      <material name="Grey">
     </material>
    </visual>
    <collision>
      <origin rpy="0 0 0" xyz="0.0 0.0 0.0"/>
      <geometry>
        <sphere radius="0.03"/>
      </geometry>
    </collision>
  </link>
  <gazebo reference="omni_sphere12_right_rear">
    <material>Gazebo/Grey</material>
    <turnGravityOff>false</turnGravityOff>
  </gazebo>
  <joint name="wheel_inner_joint_left_front" type="continuous">
    <parent link="base"/>
    <child link="wheel_left_front"/>
    <axis xyz="1 0 0"/>
    <origin rpy="0 0 2.3562" xyz="-0.2 +0.2 0.005"/>
    <dynamics damping="1" friction="0.0"/>
    <limit effort="5.0" velocity="5.0"/>
  </joint>
  <link name="wheel_left_front">
    <inertial>
      <origin rpy="0 0 0" xyz="0.0 0.0 0.0"/>
      <mass value="0.5"/>
      <inertia ixx="0.0006" ixy="0" ixz="0" iyy="0.0006" iyz="0" izz="0.0006"/>
    </inertial>
    <visual>
      <origin rpy="0 1.5708 0" xyz="0.0 0.0 0.0"/>
      <geometry>
        <cylinder length="0.05" radius="0.05"/>
      </geometry>
      <material name="Grey">
     </material>
    </visual>
    <collision>
      <origin rpy="0 1.5708 0" xyz="0.0 0.0 0.0"/>
      <geometry>
        <cylinder length="0.05" radius="0.05"/>
      </geometry>
    </collision>
  </link>
  <gazebo reference="wheel_left_front">
    <material>Gazebo/Grey</material>
    <turnGravityOff>false</turnGravityOff>
  </gazebo>
  <joint name="wheel_inner_joint_right_front" type="continuous">
    <parent link="base"/>
    <child link="wheel_right_front"/>
    <axis xyz="1 0 0"/>
    <origin rpy="0 0 0.7854" xyz="+0.2 +0.2 0.005"/>
    <dynamics damping="1" friction="0.0"/>
    <limit effort="5.0" velocity="5.0"/>
  </joint>
  <link name="wheel_right_front">
    <inertial>
      <origin rpy="0 0 0" xyz="0.0 0.0 0.0"/>
      <mass value="0.5"/>
      <inertia ixx="0.0006" ixy="0" ixz="0" iyy="0.0006" iyz="0" izz="0.0006"/>
    </inertial>
    <visual>
      <origin rpy="0 1.5708 0" xyz="0.0 0.0 0.0"/>
      <geometry>
        <cylinder length="0.05" radius="0.05"/>
      </geometry>
      <material name="Grey">
     </material>
    </visual>
    <collision>
      <origin rpy="0 1.5708 0" xyz="0.0 0.0 0.0"/>
      <geometry>
        <cylinder length="0.05" radius="0.05"/>
      </geometry>
    </collision>
  </link>
  <gazebo reference="wheel_right_front">
    <material>Gazebo/Grey</material>
    <turnGravityOff>false</turnGravityOff>
  </gazebo>
  <joint name="wheel_inner_joint_left_rear" type="continuous">
    <parent link="base"/>
    <child link="wheel_left_rear"/>
    <axis xyz="1 0 0"/>
    <origin rpy="0 0 -2.3562" xyz="-0.2 -0.2 0.005"/>
    <dynamics damping="1" friction="0.0"/>
    <limit effort="5.0" velocity="5.0"/>
  </joint>
  <link name="wheel_left_rear">
    <inertial>
      <origin rpy="0 0 0" xyz="0.0 0.0 0.0"/>
      <mass value="0.5"/>
      <inertia ixx="0.0006" ixy="0" ixz="0" iyy="0.0006" iyz="0" izz="0.0006"/>
    </inertial>
    <visual>
      <origin rpy="0 1.5708 0" xyz="0.0 0.0 0.0"/>
      <geometry>
        <cylinder length="0.05" radius="0.05"/>
      </geometry>
      <material name="Grey">
     </material>
    </visual>
    <collision>
      <origin rpy="0 1.5708 0" xyz="0.0 0.0 0.0"/>
      <geometry>
        <cylinder length="0.05" radius="0.05"/>
      </geometry>
    </collision>
  </link>
  <gazebo reference="wheel_left_rear">
    <material>Gazebo/Grey</material>
    <turnGravityOff>false</turnGravityOff>
  </gazebo>
  <joint name="wheel_inner_joint_right_rear" type="continuous">
    <parent link="base"/>
    <child link="wheel_right_rear"/>
    <axis xyz="1 0 0"/>
    <origin rpy="0 0 -0.7854" xyz="+0.2 -0.2 0.005"/>
    <dynamics damping="1" friction="0.0"/>
    <limit effort="5.0" velocity="5.0"/>
  </joint>
  <link name="wheel_right_rear">
    <inertial>
      <origin rpy="0 0 0" xyz="0.0 0.0 0.0"/>
      <mass value="0.5"/>
      <inertia ixx="0.0006" ixy="0" ixz="0" iyy="0.0006" iyz="0" izz="0.0006"/>
    </inertial>
    <visual>
      <origin rpy="0 1.5708 0" xyz="0.0 0.0 0.0"/>
      <geometry>
        <cylinder length="0.05" radius="0.05"/>
      </geometry>
      <material name="Grey">
     </material>
    </visual>
    <collision>
      <origin rpy="0 1.5708 0" xyz="0.0 0.0 0.0"/>
      <geometry>
        <cylinder length="0.05" radius="0.05"/>
      </geometry>
    </collision>
  </link>
  <gazebo reference="wheel_right_rear">
    <material>Gazebo/Grey</material>
    <turnGravityOff>false</turnGravityOff>
  </gazebo>
  <transmission name="spindle_trans" type="pr2_mechanism_model/SimpleTransmission">
    <actuator name="spindle_motor"/>
    <joint name="spindle_joint"/>
    <mechanicalReduction>1</mechanicalReduction>
    <motorTorqueConstant>1</motorTorqueConstant>
  </transmission>
  <transmission name="shoulder_yaw_trans_left" type="pr2_mechanism_model/SimpleTransmission">
    <actuator name="shoulder_yaw_motor_left"/>
    <joint name="shoulder_yaw_joint_left"/>
    <mechanicalReduction>1</mechanicalReduction>
    <motorTorqueConstant>1</motorTorqueConstant>
  </transmission>
  <transmission name="shoulder_pitch_trans_left" type="pr2_mechanism_model/SimpleTransmission">
    <actuator name="shoulder_pitch_motor_left"/>
    <joint name="shoulder_pitch_joint_left"/>
    <mechanicalReduction>1</mechanicalReduction>
    <motorTorqueConstant>1</motorTorqueConstant>
  </transmission>
  <transmission name="shoulder_roll_trans_left" type="pr2_mechanism_model/SimpleTransmission">
    <actuator name="shoulder_roll_motor_left"/>
    <joint name="shoulder_roll_joint_left"/>
    <mechanicalReduction>1</mechanicalReduction>
    <motorTorqueConstant>1</motorTorqueConstant>
  </transmission>
  <transmission name="elbow_pitch_trans_left" type="pr2_mechanism_model/SimpleTransmission">
    <actuator name="elbow_pitch_motor_left"/>
    <joint name="elbow_pitch_joint_left"/>
    <mechanicalReduction>1</mechanicalReduction>
    <motorTorqueConstant>1</motorTorqueConstant>
  </transmission>
  <transmission name="elbow_roll_trans_left" type="pr2_mechanism_model/SimpleTransmission">
    <actuator name="elbow_roll_motor_left"/>
    <joint name="elbow_roll_joint_left"/>
    <mechanicalReduction>1</mechanicalReduction>
    <motorTorqueConstant>1</motorTorqueConstant>
  </transmission>
  <transmission name="wrist_yaw_trans_left" type="pr2_mechanism_model/SimpleTransmission">
    <actuator name="wrist_yaw_motor_left"/>
    <joint name="wrist_yaw_joint_left"/>
    <mechanicalReduction>1</mechanicalReduction>
    <motorTorqueConstant>1</motorTorqueConstant>
  </transmission>
  <transmission name="wrist_pitch_trans_left" type="pr2_mechanism_model/SimpleTransmission">
    <actuator name="wrist_pitch_motor_left"/>
    <joint name="wrist_pitch_joint_left"/>
    <mechanicalReduction>1</mechanicalReduction>
    <motorTorqueConstant>1</motorTorqueConstant>
  </transmission>
  <transmission name="finger1_trans_left" type="pr2_mechanism_model/SimpleTransmission">
    <actuator name="finger1_motor_left"/>
    <joint name="finger1_joint_left"/>
    <mechanicalReduction>1</mechanicalReduction>
    <motorTorqueConstant>1</motorTorqueConstant>
  </transmission>
  <transmission name="finger2_trans_left" type="pr2_mechanism_model/SimpleTransmission">
    <actuator name="finger2_motor_left"/>
    <joint name="finger2_joint_left"/>
    <mechanicalReduction>1</mechanicalReduction>
    <motorTorqueConstant>1</motorTorqueConstant>
  </transmission>
  <transmission name="shoulder_yaw_trans_right" type="pr2_mechanism_model/SimpleTransmission">
    <actuator name="shoulder_yaw_motor_right"/>
    <joint name="shoulder_yaw_joint_right"/>
    <mechanicalReduction>1</mechanicalReduction>
    <motorTorqueConstant>1</motorTorqueConstant>
  </transmission>
  <transmission name="shoulder_pitch_trans_right" type="pr2_mechanism_model/SimpleTransmission">
    <actuator name="shoulder_pitch_motor_right"/>
    <joint name="shoulder_pitch_joint_right"/>
    <mechanicalReduction>1</mechanicalReduction>
    <motorTorqueConstant>1</motorTorqueConstant>
  </transmission>
  <transmission name="shoulder_roll_trans_right" type="pr2_mechanism_model/SimpleTransmission">
    <actuator name="shoulder_roll_motor_right"/>
    <joint name="shoulder_roll_joint_right"/>
    <mechanicalReduction>1</mechanicalReduction>
    <motorTorqueConstant>1</motorTorqueConstant>
  </transmission>
  <transmission name="elbow_pitch_trans_right" type="pr2_mechanism_model/SimpleTransmission">
    <actuator name="elbow_pitch_motor_right"/>
    <joint name="elbow_pitch_joint_right"/>
    <mechanicalReduction>1</mechanicalReduction>
    <motorTorqueConstant>1</motorTorqueConstant>
  </transmission>
  <transmission name="elbow_roll_trans_right" type="pr2_mechanism_model/SimpleTransmission">
    <actuator name="elbow_roll_motor_right"/>
    <joint name="elbow_roll_joint_right"/>
    <mechanicalReduction>1</mechanicalReduction>
    <motorTorqueConstant>1</motorTorqueConstant>
  </transmission>
  <transmission name="wrist_yaw_trans_right" type="pr2_mechanism_model/SimpleTransmission">
    <actuator name="wrist_yaw_motor_right"/>
    <joint name="wrist_yaw_joint_right"/>
    <mechanicalReduction>1</mechanicalReduction>
    <motorTorqueConstant>1</motorTorqueConstant>
  </transmission>
  <transmission name="wrist_pitch_trans_right" type="pr2_mechanism_model/SimpleTransmission">
    <actuator name="wrist_pitch_motor_right"/>
    <joint name="wrist_pitch_joint_right"/>
    <mechanicalReduction>1</mechanicalReduction>
    <motorTorqueConstant>1</motorTorqueConstant>
  </transmission>
  <transmission name="finger1_trans_right" type="pr2_mechanism_model/SimpleTransmission">
    <actuator name="finger1_motor_right"/>
    <joint name="finger1_joint_right"/>
    <mechanicalReduction>1</mechanicalReduction>
    <motorTorqueConstant>1</motorTorqueConstant>
  </transmission>
  <transmission name="finger2_trans_right" type="pr2_mechanism_model/SimpleTransmission">
    <actuator name="finger2_motor_right"/>
    <joint name="finger2_joint_right"/>
    <mechanicalReduction>1</mechanicalReduction>
    <motorTorqueConstant>1</motorTorqueConstant>
  </transmission>
  <transmission name="wheel_inner_trans_left_front" type="pr2_mechanism_model/SimpleTransmission">
    <actuator name="wheel_inner_motor_left_front"/>
    <joint name="wheel_inner_joint_left_front"/>
    <mechanicalReduction>1</mechanicalReduction>
    <motorTorqueConstant>1</motorTorqueConstant>
  </transmission>
  <transmission name="wheel_inner_trans_right_front" type="pr2_mechanism_model/SimpleTransmission">
    <actuator name="wheel_inner_motor_right_front"/>
    <joint name="wheel_inner_joint_right_front"/>
    <mechanicalReduction>1</mechanicalReduction>
    <motorTorqueConstant>1</motorTorqueConstant>
  </transmission>
  <transmission name="wheel_inner_trans_left_rear" type="pr2_mechanism_model/SimpleTransmission">
    <actuator name="wheel_inner_motor_left_rear"/>
    <joint name="wheel_inner_joint_left_rear"/>
    <mechanicalReduction>1</mechanicalReduction>
    <motorTorqueConstant>1</motorTorqueConstant>
  </transmission>
  <transmission name="wheel_inner_trans_right_rear" type="pr2_mechanism_model/SimpleTransmission">
    <actuator name="wheel_inner_motor_right_rear"/>
    <joint name="wheel_inner_joint_right_rear"/>
    <mechanicalReduction>1</mechanicalReduction>
    <motorTorqueConstant>1</motorTorqueConstant>
  </transmission>
  <transmission name="omniwheel_trans_left_front" type="pr2_mechanism_model/SimpleTransmission">
    <actuator name="omniwheel_motor_left_front"/>
    <joint name="omni_sphere1_joint_left_front"/>
    <mechanicalReduction>1</mechanicalReduction>
    <motorTorqueConstant>1</motorTorqueConstant>
  </transmission>
  <transmission name="omniwheel_trans_right_front" type="pr2_mechanism_model/SimpleTransmission">
    <actuator name="omniwheel_motor_right_front"/>
    <joint name="omni_sphere1_joint_right_front"/>
    <mechanicalReduction>1</mechanicalReduction>
    <motorTorqueConstant>1</motorTorqueConstant>
  </transmission>
  <transmission name="omniwheel_trans_left_rear" type="pr2_mechanism_model/SimpleTransmission">
    <actuator name="omniwheel_motor_left_rear"/>
    <joint name="omni_sphere1_joint_left_rear"/>
    <mechanicalReduction>1</mechanicalReduction>
    <motorTorqueConstant>1</motorTorqueConstant>
  </transmission>
  <transmission name="omniwheel_trans_right_rear" type="pr2_mechanism_model/SimpleTransmission">
    <actuator name="omniwheel_motor_right_rear"/>
    <joint name="omni_sphere1_joint_right_rear"/>
    <mechanicalReduction>1</mechanicalReduction>
    <motorTorqueConstant>1</motorTorqueConstant>
  </transmission>
  <transmission name="omniwheel_trans_left_front" type="pr2_mechanism_model/SimpleTransmission">
    <actuator name="omniwheel_motor_left_front"/>
    <joint name="omni_sphere2_joint_left_front"/>
    <mechanicalReduction>1</mechanicalReduction>
    <motorTorqueConstant>1</motorTorqueConstant>
  </transmission>
  <transmission name="omniwheel_trans_right_front" type="pr2_mechanism_model/SimpleTransmission">
    <actuator name="omniwheel_motor_right_front"/>
    <joint name="omni_sphere2_joint_right_front"/>
    <mechanicalReduction>1</mechanicalReduction>
    <motorTorqueConstant>1</motorTorqueConstant>
  </transmission>
  <transmission name="omniwheel_trans_left_rear" type="pr2_mechanism_model/SimpleTransmission">
    <actuator name="omniwheel_motor_left_rear"/>
    <joint name="omni_sphere2_joint_left_rear"/>
    <mechanicalReduction>1</mechanicalReduction>
    <motorTorqueConstant>1</motorTorqueConstant>
  </transmission>
  <transmission name="omniwheel_trans_right_rear" type="pr2_mechanism_model/SimpleTransmission">
    <actuator name="omniwheel_motor_right_rear"/>
    <joint name="omni_sphere2_joint_right_rear"/>
    <mechanicalReduction>1</mechanicalReduction>
    <motorTorqueConstant>1</motorTorqueConstant>
  </transmission>
  <transmission name="omniwheel_trans_left_front" type="pr2_mechanism_model/SimpleTransmission">
    <actuator name="omniwheel_motor_left_front"/>
    <joint name="omni_sphere3_joint_left_front"/>
    <mechanicalReduction>1</mechanicalReduction>
    <motorTorqueConstant>1</motorTorqueConstant>
  </transmission>
  <transmission name="omniwheel_trans_right_front" type="pr2_mechanism_model/SimpleTransmission">
    <actuator name="omniwheel_motor_right_front"/>
    <joint name="omni_sphere3_joint_right_front"/>
    <mechanicalReduction>1</mechanicalReduction>
    <motorTorqueConstant>1</motorTorqueConstant>
  </transmission>
  <transmission name="omniwheel_trans_left_rear" type="pr2_mechanism_model/SimpleTransmission">
    <actuator name="omniwheel_motor_left_rear"/>
    <joint name="omni_sphere3_joint_left_rear"/>
    <mechanicalReduction>1</mechanicalReduction>
    <motorTorqueConstant>1</motorTorqueConstant>
  </transmission>
  <transmission name="omniwheel_trans_right_rear" type="pr2_mechanism_model/SimpleTransmission">
    <actuator name="omniwheel_motor_right_rear"/>
    <joint name="omni_sphere3_joint_right_rear"/>
    <mechanicalReduction>1</mechanicalReduction>
    <motorTorqueConstant>1</motorTorqueConstant>
  </transmission>
  <transmission name="omniwheel_trans_left_front" type="pr2_mechanism_model/SimpleTransmission">
    <actuator name="omniwheel_motor_left_front"/>
    <joint name="omni_sphere4_joint_left_front"/>
    <mechanicalReduction>1</mechanicalReduction>
    <motorTorqueConstant>1</motorTorqueConstant>
  </transmission>
  <transmission name="omniwheel_trans_right_front" type="pr2_mechanism_model/SimpleTransmission">
    <actuator name="omniwheel_motor_right_front"/>
    <joint name="omni_sphere4_joint_right_front"/>
    <mechanicalReduction>1</mechanicalReduction>
    <motorTorqueConstant>1</motorTorqueConstant>
  </transmission>
  <transmission name="omniwheel_trans_left_rear" type="pr2_mechanism_model/SimpleTransmission">
    <actuator name="omniwheel_motor_left_rear"/>
    <joint name="omni_sphere4_joint_left_rear"/>
    <mechanicalReduction>1</mechanicalReduction>
    <motorTorqueConstant>1</motorTorqueConstant>
  </transmission>
  <transmission name="omniwheel_trans_right_rear" type="pr2_mechanism_model/SimpleTransmission">
    <actuator name="omniwheel_motor_right_rear"/>
    <joint name="omni_sphere4_joint_right_rear"/>
    <mechanicalReduction>1</mechanicalReduction>
    <motorTorqueConstant>1</motorTorqueConstant>
  </transmission>
  <transmission name="omniwheel_trans_left_front" type="pr2_mechanism_model/SimpleTransmission">
    <actuator name="omniwheel_motor_left_front"/>
    <joint name="omni_sphere5_joint_left_front"/>
    <mechanicalReduction>1</mechanicalReduction>
    <motorTorqueConstant>1</motorTorqueConstant>
  </transmission>
  <transmission name="omniwheel_trans_right_front" type="pr2_mechanism_model/SimpleTransmission">
    <actuator name="omniwheel_motor_right_front"/>
    <joint name="omni_sphere5_joint_right_front"/>
    <mechanicalReduction>1</mechanicalReduction>
    <motorTorqueConstant>1</motorTorqueConstant>
  </transmission>
  <transmission name="omniwheel_trans_left_rear" type="pr2_mechanism_model/SimpleTransmission">
    <actuator name="omniwheel_motor_left_rear"/>
    <joint name="omni_sphere5_joint_left_rear"/>
    <mechanicalReduction>1</mechanicalReduction>
    <motorTorqueConstant>1</motorTorqueConstant>
  </transmission>
  <transmission name="omniwheel_trans_right_rear" type="pr2_mechanism_model/SimpleTransmission">
    <actuator name="omniwheel_motor_right_rear"/>
    <joint name="omni_sphere5_joint_right_rear"/>
    <mechanicalReduction>1</mechanicalReduction>
    <motorTorqueConstant>1</motorTorqueConstant>
  </transmission>
  <transmission name="omniwheel_trans_left_front" type="pr2_mechanism_model/SimpleTransmission">
    <actuator name="omniwheel_motor_left_front"/>
    <joint name="omni_sphere6_joint_left_front"/>
    <mechanicalReduction>1</mechanicalReduction>
    <motorTorqueConstant>1</motorTorqueConstant>
  </transmission>
  <transmission name="omniwheel_trans_right_front" type="pr2_mechanism_model/SimpleTransmission">
    <actuator name="omniwheel_motor_right_front"/>
    <joint name="omni_sphere6_joint_right_front"/>
    <mechanicalReduction>1</mechanicalReduction>
    <motorTorqueConstant>1</motorTorqueConstant>
  </transmission>
  <transmission name="omniwheel_trans_left_rear" type="pr2_mechanism_model/SimpleTransmission">
    <actuator name="omniwheel_motor_left_rear"/>
    <joint name="omni_sphere6_joint_left_rear"/>
    <mechanicalReduction>1</mechanicalReduction>
    <motorTorqueConstant>1</motorTorqueConstant>
  </transmission>
  <transmission name="omniwheel_trans_right_rear" type="pr2_mechanism_model/SimpleTransmission">
    <actuator name="omniwheel_motor_right_rear"/>
    <joint name="omni_sphere6_joint_right_rear"/>
    <mechanicalReduction>1</mechanicalReduction>
    <motorTorqueConstant>1</motorTorqueConstant>
  </transmission>
  <transmission name="omniwheel_trans_left_front" type="pr2_mechanism_model/SimpleTransmission">
    <actuator name="omniwheel_motor_left_front"/>
    <joint name="omni_sphere7_joint_left_front"/>
    <mechanicalReduction>1</mechanicalReduction>
    <motorTorqueConstant>1</motorTorqueConstant>
  </transmission>
  <transmission name="omniwheel_trans_right_front" type="pr2_mechanism_model/SimpleTransmission">
    <actuator name="omniwheel_motor_right_front"/>
    <joint name="omni_sphere7_joint_right_front"/>
    <mechanicalReduction>1</mechanicalReduction>
    <motorTorqueConstant>1</motorTorqueConstant>
  </transmission>
  <transmission name="omniwheel_trans_left_rear" type="pr2_mechanism_model/SimpleTransmission">
    <actuator name="omniwheel_motor_left_rear"/>
    <joint name="omni_sphere7_joint_left_rear"/>
    <mechanicalReduction>1</mechanicalReduction>
    <motorTorqueConstant>1</motorTorqueConstant>
  </transmission>
  <transmission name="omniwheel_trans_right_rear" type="pr2_mechanism_model/SimpleTransmission">
    <actuator name="omniwheel_motor_right_rear"/>
    <joint name="omni_sphere7_joint_right_rear"/>
    <mechanicalReduction>1</mechanicalReduction>
    <motorTorqueConstant>1</motorTorqueConstant>
  </transmission>
  <transmission name="omniwheel_trans_left_front" type="pr2_mechanism_model/SimpleTransmission">
    <actuator name="omniwheel_motor_left_front"/>
    <joint name="omni_sphere8_joint_left_front"/>
    <mechanicalReduction>1</mechanicalReduction>
    <motorTorqueConstant>1</motorTorqueConstant>
  </transmission>
  <transmission name="omniwheel_trans_right_front" type="pr2_mechanism_model/SimpleTransmission">
    <actuator name="omniwheel_motor_right_front"/>
    <joint name="omni_sphere8_joint_right_front"/>
    <mechanicalReduction>1</mechanicalReduction>
    <motorTorqueConstant>1</motorTorqueConstant>
  </transmission>
  <transmission name="omniwheel_trans_left_rear" type="pr2_mechanism_model/SimpleTransmission">
    <actuator name="omniwheel_motor_left_rear"/>
    <joint name="omni_sphere8_joint_left_rear"/>
    <mechanicalReduction>1</mechanicalReduction>
    <motorTorqueConstant>1</motorTorqueConstant>
  </transmission>
  <transmission name="omniwheel_trans_right_rear" type="pr2_mechanism_model/SimpleTransmission">
    <actuator name="omniwheel_motor_right_rear"/>
    <joint name="omni_sphere8_joint_right_rear"/>
    <mechanicalReduction>1</mechanicalReduction>
    <motorTorqueConstant>1</motorTorqueConstant>
  </transmission>
  <transmission name="omniwheel_trans_left_front" type="pr2_mechanism_model/SimpleTransmission">
    <actuator name="omniwheel_motor_left_front"/>
    <joint name="omni_sphere9_joint_left_front"/>
    <mechanicalReduction>1</mechanicalReduction>
    <motorTorqueConstant>1</motorTorqueConstant>
  </transmission>
  <transmission name="omniwheel_trans_right_front" type="pr2_mechanism_model/SimpleTransmission">
    <actuator name="omniwheel_motor_right_front"/>
    <joint name="omni_sphere9_joint_right_front"/>
    <mechanicalReduction>1</mechanicalReduction>
    <motorTorqueConstant>1</motorTorqueConstant>
  </transmission>
  <transmission name="omniwheel_trans_left_rear" type="pr2_mechanism_model/SimpleTransmission">
    <actuator name="omniwheel_motor_left_rear"/>
    <joint name="omni_sphere9_joint_left_rear"/>
    <mechanicalReduction>1</mechanicalReduction>
    <motorTorqueConstant>1</motorTorqueConstant>
  </transmission>
  <transmission name="omniwheel_trans_right_rear" type="pr2_mechanism_model/SimpleTransmission">
    <actuator name="omniwheel_motor_right_rear"/>
    <joint name="omni_sphere9_joint_right_rear"/>
    <mechanicalReduction>1</mechanicalReduction>
    <motorTorqueConstant>1</motorTorqueConstant>
  </transmission>
  <transmission name="omniwheel_trans_left_front" type="pr2_mechanism_model/SimpleTransmission">
    <actuator name="omniwheel_motor_left_front"/>
    <joint name="omni_sphere10_joint_left_front"/>
    <mechanicalReduction>1</mechanicalReduction>
    <motorTorqueConstant>1</motorTorqueConstant>
  </transmission>
  <transmission name="omniwheel_trans_right_front" type="pr2_mechanism_model/SimpleTransmission">
    <actuator name="omniwheel_motor_right_front"/>
    <joint name="omni_sphere10_joint_right_front"/>
    <mechanicalReduction>1</mechanicalReduction>
    <motorTorqueConstant>1</motorTorqueConstant>
  </transmission>
  <transmission name="omniwheel_trans_left_rear" type="pr2_mechanism_model/SimpleTransmission">
    <actuator name="omniwheel_motor_left_rear"/>
    <joint name="omni_sphere10_joint_left_rear"/>
    <mechanicalReduction>1</mechanicalReduction>
    <motorTorqueConstant>1</motorTorqueConstant>
  </transmission>
  <transmission name="omniwheel_trans_right_rear" type="pr2_mechanism_model/SimpleTransmission">
    <actuator name="omniwheel_motor_right_rear"/>
    <joint name="omni_sphere10_joint_right_rear"/>
    <mechanicalReduction>1</mechanicalReduction>
    <motorTorqueConstant>1</motorTorqueConstant>
  </transmission>
  <transmission name="omniwheel_trans_left_front" type="pr2_mechanism_model/SimpleTransmission">
    <actuator name="omniwheel_motor_left_front"/>
    <joint name="omni_sphere11_joint_left_front"/>
    <mechanicalReduction>1</mechanicalReduction>
    <motorTorqueConstant>1</motorTorqueConstant>
  </transmission>
  <transmission name="omniwheel_trans_right_front" type="pr2_mechanism_model/SimpleTransmission">
    <actuator name="omniwheel_motor_right_front"/>
    <joint name="omni_sphere11_joint_right_front"/>
    <mechanicalReduction>1</mechanicalReduction>
    <motorTorqueConstant>1</motorTorqueConstant>
  </transmission>
  <transmission name="omniwheel_trans_left_rear" type="pr2_mechanism_model/SimpleTransmission">
    <actuator name="omniwheel_motor_left_rear"/>
    <joint name="omni_sphere11_joint_left_rear"/>
    <mechanicalReduction>1</mechanicalReduction>
    <motorTorqueConstant>1</motorTorqueConstant>
  </transmission>
  <transmission name="omniwheel_trans_right_rear" type="pr2_mechanism_model/SimpleTransmission">
    <actuator name="omniwheel_motor_right_rear"/>
    <joint name="omni_sphere11_joint_right_rear"/>
    <mechanicalReduction>1</mechanicalReduction>
    <motorTorqueConstant>1</motorTorqueConstant>
  </transmission>
  <transmission name="omniwheel_trans_left_front" type="pr2_mechanism_model/SimpleTransmission">
    <actuator name="omniwheel_motor_left_front"/>
    <joint name="omni_sphere12_joint_left_front"/>
    <mechanicalReduction>1</mechanicalReduction>
    <motorTorqueConstant>1</motorTorqueConstant>
  </transmission>
  <transmission name="omniwheel_trans_right_front" type="pr2_mechanism_model/SimpleTransmission">
    <actuator name="omniwheel_motor_right_front"/>
    <joint name="omni_sphere12_joint_right_front"/>
    <mechanicalReduction>1</mechanicalReduction>
    <motorTorqueConstant>1</motorTorqueConstant>
  </transmission>
  <transmission name="omniwheel_trans_left_rear" type="pr2_mechanism_model/SimpleTransmission">
    <actuator name="omniwheel_motor_left_rear"/>
    <joint name="omni_sphere12_joint_left_rear"/>
    <mechanicalReduction>1</mechanicalReduction>
    <motorTorqueConstant>1</motorTorqueConstant>
  </transmission>
  <transmission name="omniwheel_trans_right_rear" type="pr2_mechanism_model/SimpleTransmission">
    <actuator name="omniwheel_motor_right_rear"/>
    <joint name="omni_sphere12_joint_right_rear"/>
    <mechanicalReduction>1</mechanicalReduction>
    <motorTorqueConstant>1</motorTorqueConstant>
  </transmission>
  <transmission name="neck_trans" type="pr2_mechanism_model/SimpleTransmission">
    <actuator name="neck_motor"/>
    <joint name="neck_pan_joint"/>
    <mechanicalReduction>1</mechanicalReduction>
    <motorTorqueConstant>1</motorTorqueConstant>
  </transmission>
  <transmission name="head_trans" type="pr2_mechanism_model/SimpleTransmission">
    <actuator name="head_motor"/>
    <joint name="neck_tilt_joint"/>
    <mechanicalReduction>1</mechanicalReduction>
    <motorTorqueConstant>1</motorTorqueConstant>
  </transmission>
</robot>

